Workbook

Sheet Highlight
B2: Group : | E2: Branding : | H2: Branding : | L2: Branding :
B3: Parameter :
D17: TRANSACTION | K17: SALES VOLUME | R17: FEE BASED INCOME
A18: =Portfolio!N1 -> ALFA GROUP | B18: Bulan | D18: DEBIT ON US | E18: DEBIT OFF US | F18: CREDIT OFF US | G18: QRIS ON US | H18: QRIS OFF US | I18: TOTAL Trx. | K18: DEBIT ON US | L18: DEBIT OFF US | M18: CREDIT OFF US | N18: QRIS ON US | O18: QRIS OFF US | P18: TOTAL Vol. | R18: DEBIT ON US | S18: DEBIT OFF US | T18: CREDIT OFF US | U18: QRIS ON US | V18: QRIS OFF US | W18: TOTAL FBI.
A19: 202401 | B19: 45292 | D19: =SUMIF(Realisasi!$E:$E,Highlight!$X19,Realisasi!F:F) -> 16262 | E19: =SUMIF(Realisasi!$E:$E,Highlight!$X19,Realisasi!G:G) -> 60491 | F19: =SUMIF(Realisasi!$E:$E,Highlight!$X19,Realisasi!H:H) -> 11819 | G19: =SUMIF(Realisasi!$E:$E,Highlight!$X19,Realisasi!I:I) -> 0 | H19: =SUMIF(Realisasi!$E:$E,Highlight!$X19,Realisasi!J:J) -> 1 | I19: =SUM(D19:H19) -> 88573 | K19: =SUMIF(Realisasi!$E:$E,Highlight!$X19,Realisasi!K:K) -> 1711746090 | L19: =SUMIF(Realisasi!$E:$E,Highlight!$X19,Realisasi!L:L) -> 6482977835 | M19: =SUMIF(Realisasi!$E:$E,Highlight!$X19,Realisasi!M:M) -> 1882369072 | N19: =SUMIF(Realisasi!$E:$E,Highlight!$X19,Realisasi!N:N) -> 0 | O19: =SUMIF(Realisasi!$E:$E,Highlight!$X19,Realisasi!O:O) -> 130000 | P19: =SUM(K19:O19) -> 10077222997 | R19: =SUMIF(Realisasi!$E:$E,Highlight!$X19,Realisasi!P:P) -> 2567618 | S19: =SUMIF(Realisasi!$E:$E,Highlight!$X19,Realisasi!Q:Q) -> 56745468 | T19: =SUMIF(Realisasi!$E:$E,Highlight!$X19,Realisasi!R:R) -> 33840127 | U19: =SUMIF(Realisasi!$E:$E,Highlight!$X19,Realisasi!S:S) -> 0 | V19: =SUMIF(Realisasi!$E:$E,Highlight!$X19,Realisasi!T:T) -> 390 | W19: =SUM(R19:V19) -> 93153603 | X19: =CONCATENATE(A$18,A19) -> ALFA GROUP202401
A20: 202402 | B20: 45323 | D20: =SUMIF(Realisasi!$E:$E,Highlight!$X20,Realisasi!F:F) -> 19000 | E20: =SUMIF(Realisasi!$E:$E,Highlight!$X20,Realisasi!G:G) -> 70681 | F20: =SUMIF(Realisasi!$E:$E,Highlight!$X20,Realisasi!H:H) -> 6533 | G20: =SUMIF(Realisasi!$E:$E,Highlight!$X20,Realisasi!I:I) -> 0 | H20: =SUMIF(Realisasi!$E:$E,Highlight!$X20,Realisasi!J:J) -> 0 | I20: =SUM(D20:H20) -> 96214 | K20: =SUMIF(Realisasi!$E:$E,Highlight!$X20,Realisasi!K:K) -> 1880637508 | L20: =SUMIF(Realisasi!$E:$E,Highlight!$X20,Realisasi!L:L) -> 7694614904 | M20: =SUMIF(Realisasi!$E:$E,Highlight!$X20,Realisasi!M:M) -> 1024014060 | N20: =SUMIF(Realisasi!$E:$E,Highlight!$X20,Realisasi!N:N) -> 0 | O20: =SUMIF(Realisasi!$E:$E,Highlight!$X20,Realisasi!O:O) -> 0 | P20: =SUM(K20:O20) -> 10599266472 | R20: =SUMIF(Realisasi!$E:$E,Highlight!$X20,Realisasi!P:P) -> 2820954 | S20: =SUMIF(Realisasi!$E:$E,Highlight!$X20,Realisasi!Q:Q) -> 76622746 | T20: =SUMIF(Realisasi!$E:$E,Highlight!$X20,Realisasi!R:R) -> 18415757 | U20: =SUMIF(Realisasi!$E:$E,Highlight!$X20,Realisasi!S:S) -> 0 | V20: =SUMIF(Realisasi!$E:$E,Highlight!$X20,Realisasi!T:T) -> 0 | W20: =SUM(R20:V20) -> 97859457 | X20: =CONCATENATE(A$18,A20) -> ALFA GROUP202402
A21: 202403 | B21: 45352 | D21: =SUMIF(Realisasi!$E:$E,Highlight!$X21,Realisasi!F:F) -> 22365 | E21: =SUMIF(Realisasi!$E:$E,Highlight!$X21,Realisasi!G:G) -> 88566 | F21: =SUMIF(Realisasi!$E:$E,Highlight!$X21,Realisasi!H:H) -> 7783 | G21: =SUMIF(Realisasi!$E:$E,Highlight!$X21,Realisasi!I:I) -> 0 | H21: =SUMIF(Realisasi!$E:$E,Highlight!$X21,Realisasi!J:J) -> 0 | I21: =SUM(D21:H21) -> 118714 | K21: =SUMIF(Realisasi!$E:$E,Highlight!$X21,Realisasi!K:K) -> 2531039839 | L21: =SUMIF(Realisasi!$E:$E,Highlight!$X21,Realisasi!L:L) -> 10451945225 | M21: =SUMIF(Realisasi!$E:$E,Highlight!$X21,Realisasi!M:M) -> 1330938495 | N21: =SUMIF(Realisasi!$E:$E,Highlight!$X21,Realisasi!N:N) -> 0 | O21: =SUMIF(Realisasi!$E:$E,Highlight!$X21,Realisasi!O:O) -> 0 | P21: =SUM(K21:O21) -> 14313923559 | R21: =SUMIF(Realisasi!$E:$E,Highlight!$X21,Realisasi!P:P) -> 3796556 | S21: =SUMIF(Realisasi!$E:$E,Highlight!$X21,Realisasi!Q:Q) -> 103526651 | T21: =SUMIF(Realisasi!$E:$E,Highlight!$X21,Realisasi!R:R) -> 23941357 | U21: =SUMIF(Realisasi!$E:$E,Highlight!$X21,Realisasi!S:S) -> 0 | V21: =SUMIF(Realisasi!$E:$E,Highlight!$X21,Realisasi!T:T) -> 0 | W21: =SUM(R21:V21) -> 131264564 | X21: =CONCATENATE(A$18,A21) -> ALFA GROUP202403
A22: 202404 | B22: 45383 | D22: =SUMIF(Realisasi!$E:$E,Highlight!$X22,Realisasi!F:F) -> 22096 | E22: =SUMIF(Realisasi!$E:$E,Highlight!$X22,Realisasi!G:G) -> 81243 | F22: =SUMIF(Realisasi!$E:$E,Highlight!$X22,Realisasi!H:H) -> 14358 | G22: =SUMIF(Realisasi!$E:$E,Highlight!$X22,Realisasi!I:I) -> 0 | H22: =SUMIF(Realisasi!$E:$E,Highlight!$X22,Realisasi!J:J) -> 0 | I22: =SUM(D22:H22) -> 117697 | K22: =SUMIF(Realisasi!$E:$E,Highlight!$X22,Realisasi!K:K) -> 2534740240 | L22: =SUMIF(Realisasi!$E:$E,Highlight!$X22,Realisasi!L:L) -> 9284556300 | M22: =SUMIF(Realisasi!$E:$E,Highlight!$X22,Realisasi!M:M) -> 2381667096 | N22: =SUMIF(Realisasi!$E:$E,Highlight!$X22,Realisasi!N:N) -> 0 | O22: =SUMIF(Realisasi!$E:$E,Highlight!$X22,Realisasi!O:O) -> 0 | P22: =SUM(K22:O22) -> 14200963636 | R22: =SUMIF(Realisasi!$E:$E,Highlight!$X22,Realisasi!P:P) -> 3802105 | S22: =SUMIF(Realisasi!$E:$E,Highlight!$X22,Realisasi!Q:Q) -> 82839858 | T22: =SUMIF(Realisasi!$E:$E,Highlight!$X22,Realisasi!R:R) -> 42832709 | U22: =SUMIF(Realisasi!$E:$E,Highlight!$X22,Realisasi!S:S) -> 0 | V22: =SUMIF(Realisasi!$E:$E,Highlight!$X22,Realisasi!T:T) -> 0 | W22: =SUM(R22:V22) -> 129474672 | X22: =CONCATENATE(A$18,A22) -> ALFA GROUP202404
A23: 202405 | B23: 45413 | D23: =SUMIF(Realisasi!$E:$E,Highlight!$X23,Realisasi!F:F) -> 21307 | E23: =SUMIF(Realisasi!$E:$E,Highlight!$X23,Realisasi!G:G) -> 76165 | F23: =SUMIF(Realisasi!$E:$E,Highlight!$X23,Realisasi!H:H) -> 15119 | G23: =SUMIF(Realisasi!$E:$E,Highlight!$X23,Realisasi!I:I) -> 6 | H23: =SUMIF(Realisasi!$E:$E,Highlight!$X23,Realisasi!J:J) -> 16 | I23: =SUM(D23:H23) -> 112613 | K23: =SUMIF(Realisasi!$E:$E,Highlight!$X23,Realisasi!K:K) -> 2235514862 | L23: =SUMIF(Realisasi!$E:$E,Highlight!$X23,Realisasi!L:L) -> 8121972013 | M23: =SUMIF(Realisasi!$E:$E,Highlight!$X23,Realisasi!M:M) -> 2354381619 | N23: =SUMIF(Realisasi!$E:$E,Highlight!$X23,Realisasi!N:N) -> 55000 | O23: =SUMIF(Realisasi!$E:$E,Highlight!$X23,Realisasi!O:O) -> 128500 | P23: =SUM(K23:O23) -> 12712051994 | R23: =SUMIF(Realisasi!$E:$E,Highlight!$X23,Realisasi!P:P) -> 3353268 | S23: =SUMIF(Realisasi!$E:$E,Highlight!$X23,Realisasi!Q:Q) -> 70824575 | T23: =SUMIF(Realisasi!$E:$E,Highlight!$X23,Realisasi!R:R) -> 42338741 | U23: =SUMIF(Realisasi!$E:$E,Highlight!$X23,Realisasi!S:S) -> 165 | V23: =SUMIF(Realisasi!$E:$E,Highlight!$X23,Realisasi!T:T) -> 386 | W23: =SUM(R23:V23) -> 116517135 | X23: =CONCATENATE(A$18,A23) -> ALFA GROUP202405
A24: 202406 | B24: 45444 | D24: =SUMIF(Realisasi!$E:$E,Highlight!$X24,Realisasi!F:F) -> 20813 | E24: =SUMIF(Realisasi!$E:$E,Highlight!$X24,Realisasi!G:G) -> 77560 | F24: =SUMIF(Realisasi!$E:$E,Highlight!$X24,Realisasi!H:H) -> 15232 | G24: =SUMIF(Realisasi!$E:$E,Highlight!$X24,Realisasi!I:I) -> 5 | H24: =SUMIF(Realisasi!$E:$E,Highlight!$X24,Realisasi!J:J) -> 24 | I24: =SUM(D24:H24) -> 113634 | K24: =SUMIF(Realisasi!$E:$E,Highlight!$X24,Realisasi!K:K) -> 2269620239 | L24: =SUMIF(Realisasi!$E:$E,Highlight!$X24,Realisasi!L:L) -> 8459632772 | M24: =SUMIF(Realisasi!$E:$E,Highlight!$X24,Realisasi!M:M) -> 2394991151 | N24: =SUMIF(Realisasi!$E:$E,Highlight!$X24,Realisasi!N:N) -> 33000 | O24: =SUMIF(Realisasi!$E:$E,Highlight!$X24,Realisasi!O:O) -> 172800 | P24: =SUM(K24:O24) -> 13124449962 | R24: =SUMIF(Realisasi!$E:$E,Highlight!$X24,Realisasi!P:P) -> 3404427 | S24: =SUMIF(Realisasi!$E:$E,Highlight!$X24,Realisasi!Q:Q) -> 74617598 | T24: =SUMIF(Realisasi!$E:$E,Highlight!$X24,Realisasi!R:R) -> 43077823 | U24: =SUMIF(Realisasi!$E:$E,Highlight!$X24,Realisasi!S:S) -> 101 | V24: =SUMIF(Realisasi!$E:$E,Highlight!$X24,Realisasi!T:T) -> 566 | W24: =SUM(R24:V24) -> 121100515 | X24: =CONCATENATE(A$18,A24) -> ALFA GROUP202406
A25: 202407 | B25: 45474 | D25: =SUMIF(Realisasi!$E:$E,Highlight!$X25,Realisasi!F:F) -> 22181 | E25: =SUMIF(Realisasi!$E:$E,Highlight!$X25,Realisasi!G:G) -> 78977 | F25: =SUMIF(Realisasi!$E:$E,Highlight!$X25,Realisasi!H:H) -> 16550 | G25: =SUMIF(Realisasi!$E:$E,Highlight!$X25,Realisasi!I:I) -> 3 | H25: =SUMIF(Realisasi!$E:$E,Highlight!$X25,Realisasi!J:J) -> 44 | I25: =SUM(D25:H25) -> 117755 | K25: =SUMIF(Realisasi!$E:$E,Highlight!$X25,Realisasi!K:K) -> 2264212357 | L25: =SUMIF(Realisasi!$E:$E,Highlight!$X25,Realisasi!L:L) -> 8642422442 | M25: =SUMIF(Realisasi!$E:$E,Highlight!$X25,Realisasi!M:M) -> 2588367934 | N25: =SUMIF(Realisasi!$E:$E,Highlight!$X25,Realisasi!N:N) -> 18000 | O25: =SUMIF(Realisasi!$E:$E,Highlight!$X25,Realisasi!O:O) -> 375000 | P25: =SUM(K25:O25) -> 13495395733 | R25: =SUMIF(Realisasi!$E:$E,Highlight!$X25,Realisasi!P:P) -> 3396315 | S25: =SUMIF(Realisasi!$E:$E,Highlight!$X25,Realisasi!Q:Q) -> 76374440 | T25: =SUMIF(Realisasi!$E:$E,Highlight!$X25,Realisasi!R:R) -> 46549719 | U25: =SUMIF(Realisasi!$E:$E,Highlight!$X25,Realisasi!S:S) -> 54 | V25: =SUMIF(Realisasi!$E:$E,Highlight!$X25,Realisasi!T:T) -> 1125 | W25: =SUM(R25:V25) -> 126321653 | X25: =CONCATENATE(A$18,A25) -> ALFA GROUP202407
A26: 202408 | B26: 45505 | D26: =SUMIF(Realisasi!$E:$E,Highlight!$X26,Realisasi!F:F) -> 22859 | E26: =SUMIF(Realisasi!$E:$E,Highlight!$X26,Realisasi!G:G) -> 81603 | F26: =SUMIF(Realisasi!$E:$E,Highlight!$X26,Realisasi!H:H) -> 17696 | G26: =SUMIF(Realisasi!$E:$E,Highlight!$X26,Realisasi!I:I) -> 19 | H26: =SUMIF(Realisasi!$E:$E,Highlight!$X26,Realisasi!J:J) -> 45 | I26: =SUM(D26:H26) -> 122222 | K26: =SUMIF(Realisasi!$E:$E,Highlight!$X26,Realisasi!K:K) -> 2293227863 | L26: =SUMIF(Realisasi!$E:$E,Highlight!$X26,Realisasi!L:L) -> 8788575803 | M26: =SUMIF(Realisasi!$E:$E,Highlight!$X26,Realisasi!M:M) -> 2721134031 | N26: =SUMIF(Realisasi!$E:$E,Highlight!$X26,Realisasi!N:N) -> 156000 | O26: =SUMIF(Realisasi!$E:$E,Highlight!$X26,Realisasi!O:O) -> 672000 | P26: =SUM(K26:O26) -> 13803765697 | R26: =SUMIF(Realisasi!$E:$E,Highlight!$X26,Realisasi!P:P) -> 3439838 | S26: =SUMIF(Realisasi!$E:$E,Highlight!$X26,Realisasi!Q:Q) -> 77086562 | T26: =SUMIF(Realisasi!$E:$E,Highlight!$X26,Realisasi!R:R) -> 48912271 | U26: =SUMIF(Realisasi!$E:$E,Highlight!$X26,Realisasi!S:S) -> 468 | V26: =SUMIF(Realisasi!$E:$E,Highlight!$X26,Realisasi!T:T) -> 2015 | W26: =SUM(R26:V26) -> 129441154 | X26: =CONCATENATE(A$18,A26) -> ALFA GROUP202408
A27: 202409 | B27: 45536 | D27: =SUMIF(Realisasi!$E:$E,Highlight!$X27,Realisasi!F:F) -> 23272 | E27: =SUMIF(Realisasi!$E:$E,Highlight!$X27,Realisasi!G:G) -> 79381 | F27: =SUMIF(Realisasi!$E:$E,Highlight!$X27,Realisasi!H:H) -> 20057 | G27: =SUMIF(Realisasi!$E:$E,Highlight!$X27,Realisasi!I:I) -> 11 | H27: =SUMIF(Realisasi!$E:$E,Highlight!$X27,Realisasi!J:J) -> 40 | I27: =SUM(D27:H27) -> 122761 | K27: =SUMIF(Realisasi!$E:$E,Highlight!$X27,Realisasi!K:K) -> 2326507566 | L27: =SUMIF(Realisasi!$E:$E,Highlight!$X27,Realisasi!L:L) -> 8374753183 | M27: =SUMIF(Realisasi!$E:$E,Highlight!$X27,Realisasi!M:M) -> 3032459304 | N27: =SUMIF(Realisasi!$E:$E,Highlight!$X27,Realisasi!N:N) -> 89000 | O27: =SUMIF(Realisasi!$E:$E,Highlight!$X27,Realisasi!O:O) -> 1909000 | P27: =SUM(K27:O27) -> 13735718053 | R27: =SUMIF(Realisasi!$E:$E,Highlight!$X27,Realisasi!P:P) -> 7426824 | S27: =SUMIF(Realisasi!$E:$E,Highlight!$X27,Realisasi!Q:Q) -> 76437593 | T27: =SUMIF(Realisasi!$E:$E,Highlight!$X27,Realisasi!R:R) -> 54548727 | U27: =SUMIF(Realisasi!$E:$E,Highlight!$X27,Realisasi!S:S) -> 267 | V27: =SUMIF(Realisasi!$E:$E,Highlight!$X27,Realisasi!T:T) -> 5727 | W27: =SUM(R27:V27) -> 138419138 | X27: =CONCATENATE(A$18,A27) -> ALFA GROUP202409
A28: 202410 | B28: 45566 | D28: =SUMIF(Realisasi!$E:$E,Highlight!$X28,Realisasi!F:F) -> 24256 | E28: =SUMIF(Realisasi!$E:$E,Highlight!$X28,Realisasi!G:G) -> 74140 | F28: =SUMIF(Realisasi!$E:$E,Highlight!$X28,Realisasi!H:H) -> 22616 | G28: =SUMIF(Realisasi!$E:$E,Highlight!$X28,Realisasi!I:I) -> 9 | H28: =SUMIF(Realisasi!$E:$E,Highlight!$X28,Realisasi!J:J) -> 90 | I28: =SUM(D28:H28) -> 121111 | K28: =SUMIF(Realisasi!$E:$E,Highlight!$X28,Realisasi!K:K) -> 2345739119 | L28: =SUMIF(Realisasi!$E:$E,Highlight!$X28,Realisasi!L:L) -> 7491031410 | M28: =SUMIF(Realisasi!$E:$E,Highlight!$X28,Realisasi!M:M) -> 3335397519 | N28: =SUMIF(Realisasi!$E:$E,Highlight!$X28,Realisasi!N:N) -> 122200 | O28: =SUMIF(Realisasi!$E:$E,Highlight!$X28,Realisasi!O:O) -> 1336468 | P28: =SUM(K28:O28) -> 13173626716 | R28: =SUMIF(Realisasi!$E:$E,Highlight!$X28,Realisasi!P:P) -> 3518606 | S28: =SUMIF(Realisasi!$E:$E,Highlight!$X28,Realisasi!Q:Q) -> 74909516 | T28: =SUMIF(Realisasi!$E:$E,Highlight!$X28,Realisasi!R:R) -> 59987337 | U28: =SUMIF(Realisasi!$E:$E,Highlight!$X28,Realisasi!S:S) -> 0 | V28: =SUMIF(Realisasi!$E:$E,Highlight!$X28,Realisasi!T:T) -> 1596 | W28: =SUM(R28:V28) -> 138417055 | X28: =CONCATENATE(A$18,A28) -> ALFA GROUP202410
A29: 202411 | B29: 45597 | D29: =SUMIF(Realisasi!$E:$E,Highlight!$X29,Realisasi!F:F) -> 23048 | E29: =SUMIF(Realisasi!$E:$E,Highlight!$X29,Realisasi!G:G) -> 70592 | F29: =SUMIF(Realisasi!$E:$E,Highlight!$X29,Realisasi!H:H) -> 25251 | G29: =SUMIF(Realisasi!$E:$E,Highlight!$X29,Realisasi!I:I) -> 188 | H29: =SUMIF(Realisasi!$E:$E,Highlight!$X29,Realisasi!J:J) -> 212 | I29: =SUM(D29:H29) -> 119291 | K29: =SUMIF(Realisasi!$E:$E,Highlight!$X29,Realisasi!K:K) -> 2264147238 | L29: =SUMIF(Realisasi!$E:$E,Highlight!$X29,Realisasi!L:L) -> 7338323563 | M29: =SUMIF(Realisasi!$E:$E,Highlight!$X29,Realisasi!M:M) -> 3776677559 | N29: =SUMIF(Realisasi!$E:$E,Highlight!$X29,Realisasi!N:N) -> 18336915 | O29: =SUMIF(Realisasi!$E:$E,Highlight!$X29,Realisasi!O:O) -> 3237407 | P29: =SUM(K29:O29) -> 13400722682 | R29: =SUMIF(Realisasi!$E:$E,Highlight!$X29,Realisasi!P:P) -> 3396218 | S29: =SUMIF(Realisasi!$E:$E,Highlight!$X29,Realisasi!Q:Q) -> 73383236 | T29: =SUMIF(Realisasi!$E:$E,Highlight!$X29,Realisasi!R:R) -> 67926250 | U29: =SUMIF(Realisasi!$E:$E,Highlight!$X29,Realisasi!S:S) -> 3021 | V29: =SUMIF(Realisasi!$E:$E,Highlight!$X29,Realisasi!T:T) -> 10164 | W29: =SUM(R29:V29) -> 144718889 | X29: =CONCATENATE(A$18,A29) -> ALFA GROUP202411
A30: 202412 | B30: 45627 | D30: =SUMIF(Realisasi!$E:$E,Highlight!$X30,Realisasi!F:F) -> 23418 | E30: =SUMIF(Realisasi!$E:$E,Highlight!$X30,Realisasi!G:G) -> 71015 | F30: =SUMIF(Realisasi!$E:$E,Highlight!$X30,Realisasi!H:H) -> 22227 | G30: =SUMIF(Realisasi!$E:$E,Highlight!$X30,Realisasi!I:I) -> 26 | H30: =SUMIF(Realisasi!$E:$E,Highlight!$X30,Realisasi!J:J) -> 246 | I30: =SUM(D30:H30) -> 116932 | K30: =SUMIF(Realisasi!$E:$E,Highlight!$X30,Realisasi!K:K) -> 2404627964 | L30: =SUMIF(Realisasi!$E:$E,Highlight!$X30,Realisasi!L:L) -> 7606631818 | M30: =SUMIF(Realisasi!$E:$E,Highlight!$X30,Realisasi!M:M) -> 3352983151 | N30: =SUMIF(Realisasi!$E:$E,Highlight!$X30,Realisasi!N:N) -> 1367800 | O30: =SUMIF(Realisasi!$E:$E,Highlight!$X30,Realisasi!O:O) -> 9104749 | P30: =SUM(K30:O30) -> 13374715482 | R30: =SUMIF(Realisasi!$E:$E,Highlight!$X30,Realisasi!P:P) -> 3606938 | S30: =SUMIF(Realisasi!$E:$E,Highlight!$X30,Realisasi!Q:Q) -> 76066318 | T30: =SUMIF(Realisasi!$E:$E,Highlight!$X30,Realisasi!R:R) -> 60297942 | U30: =SUMIF(Realisasi!$E:$E,Highlight!$X30,Realisasi!S:S) -> 1153 | V30: =SUMIF(Realisasi!$E:$E,Highlight!$X30,Realisasi!T:T) -> 33636 | W30: =SUM(R30:V30) -> 140005987 | X30: =CONCATENATE(A$18,A30) -> ALFA GROUP202412
B31: YTD 2024 | D31: =SUM(D19:D30) -> 260877 | E31: =SUM(E19:E30) -> 910414 | F31: =SUM(F19:F30) -> 195241 | G31: =SUM(G19:G30) -> 267 | H31: =SUM(H19:H30) -> 718 | I31: =SUM(I19:I30) -> 1367517 | K31: =SUM(K19:K30) -> 27061760885 | L31: =SUM(L19:L30) -> 98737437268 | M31: =SUM(M19:M30) -> 30175380991 | N31: =SUM(N19:N30) -> 20177915 | O31: =SUM(O19:O30) -> 17065924 | P31: =SUM(P19:P30) -> 156011822983 | R31: =SUM(R19:R30) -> 44529667 | S31: =SUM(S19:S30) -> 919434561 | T31: =SUM(T19:T30) -> 542668760 | U31: =SUM(U19:U30) -> 5229 | V31: =SUM(V19:V30) -> 55605 | W31: =SUM(W19:W30) -> 1506693822
B32: Average | D32: =AVERAGE(D19:D30) -> 21739.75 | E32: =AVERAGE(E19:E30) -> 75867.833 | F32: =AVERAGE(F19:F30) -> 16270.083 | G32: =AVERAGE(G19:G30) -> 22.25 | H32: =AVERAGE(H19:H30) -> 59.833333 | I32: =AVERAGE(I19:I30) -> 113959.75 | K32: =AVERAGE(K19:K30) -> 2.2551467e+09 | L32: =AVERAGE(L19:L30) -> 8.2281198e+09 | M32: =AVERAGE(M19:M30) -> 2.5146151e+09 | N32: =AVERAGE(N19:N30) -> 1681492.9 | O32: =AVERAGE(O19:O30) -> 1422160.3 | P32: =AVERAGE(P19:P30) -> 1.3000985e+10 | R32: =AVERAGE(R19:R30) -> 3710805.6 | S32: =AVERAGE(S19:S30) -> 76619547 | T32: =AVERAGE(T19:T30) -> 45222397 | U32: =AVERAGE(U19:U30) -> 435.75 | V32: =AVERAGE(V19:V30) -> 4633.75 | W32: =AVERAGE(W19:W30) -> 1.2555782e+08
A33: 202501 | B33: 45658 | D33: =SUMIF(Realisasi!$E:$E,Highlight!$X33,Realisasi!F:F) -> 22997 | E33: =SUMIF(Realisasi!$E:$E,Highlight!$X33,Realisasi!G:G) -> 68550 | F33: =SUMIF(Realisasi!$E:$E,Highlight!$X33,Realisasi!H:H) -> 22190 | G33: =SUMIF(Realisasi!$E:$E,Highlight!$X33,Realisasi!I:I) -> 18 | H33: =SUMIF(Realisasi!$E:$E,Highlight!$X33,Realisasi!J:J) -> 491 | I33: =SUM(D33:H33) -> 114246 | K33: =SUMIF(Realisasi!$E:$E,Highlight!$X33,Realisasi!K:K) -> 2357758031 | L33: =SUMIF(Realisasi!$E:$E,Highlight!$X33,Realisasi!L:L) -> 7386991780 | M33: =SUMIF(Realisasi!$E:$E,Highlight!$X33,Realisasi!M:M) -> 3306140328 | N33: =SUMIF(Realisasi!$E:$E,Highlight!$X33,Realisasi!N:N) -> 732600 | O33: =SUMIF(Realisasi!$E:$E,Highlight!$X33,Realisasi!O:O) -> 24575667 | P33: =SUM(K33:O33) -> 13076198406 | R33: =SUMIF(Realisasi!$E:$E,Highlight!$X33,Realisasi!P:P) -> 3536634 | S33: =SUMIF(Realisasi!$E:$E,Highlight!$X33,Realisasi!Q:Q) -> 73869918 | T33: =SUMIF(Realisasi!$E:$E,Highlight!$X33,Realisasi!R:R) -> 59392003 | U33: =SUMIF(Realisasi!$E:$E,Highlight!$X33,Realisasi!S:S) -> 730 | V33: =SUMIF(Realisasi!$E:$E,Highlight!$X33,Realisasi!T:T) -> 39432 | W33: =SUM(R33:V33) -> 136838717 | X33: =CONCATENATE(A$18,A33) -> ALFA GROUP202501
A34: 202502 | B34: 45689 | D34: =SUMIF(Realisasi!$E:$E,Highlight!$X34,Realisasi!F:F) -> 21799 | E34: =SUMIF(Realisasi!$E:$E,Highlight!$X34,Realisasi!G:G) -> 66448 | F34: =SUMIF(Realisasi!$E:$E,Highlight!$X34,Realisasi!H:H) -> 21938 | G34: =SUMIF(Realisasi!$E:$E,Highlight!$X34,Realisasi!I:I) -> 35 | H34: =SUMIF(Realisasi!$E:$E,Highlight!$X34,Realisasi!J:J) -> 437 | I34: =SUM(D34:H34) -> 110657 | K34: =SUMIF(Realisasi!$E:$E,Highlight!$X34,Realisasi!K:K) -> 2250063826 | L34: =SUMIF(Realisasi!$E:$E,Highlight!$X34,Realisasi!L:L) -> 7242576017 | M34: =SUMIF(Realisasi!$E:$E,Highlight!$X34,Realisasi!M:M) -> 3301500712 | N34: =SUMIF(Realisasi!$E:$E,Highlight!$X34,Realisasi!N:N) -> 780500 | O34: =SUMIF(Realisasi!$E:$E,Highlight!$X34,Realisasi!O:O) -> 19665000 | P34: =SUM(K34:O34) -> 12814586055 | R34: =SUMIF(Realisasi!$E:$E,Highlight!$X34,Realisasi!P:P) -> 3375093 | S34: =SUMIF(Realisasi!$E:$E,Highlight!$X34,Realisasi!Q:Q) -> 72425761 | T34: =SUMIF(Realisasi!$E:$E,Highlight!$X34,Realisasi!R:R) -> 59178495 | U34: =SUMIF(Realisasi!$E:$E,Highlight!$X34,Realisasi!S:S) -> 280 | V34: =SUMIF(Realisasi!$E:$E,Highlight!$X34,Realisasi!T:T) -> 25513 | W34: =SUM(R34:V34) -> 135005142 | X34: =CONCATENATE(A$18,A34) -> ALFA GROUP202502
A35: 202503 | B35: 45717 | D35: =SUMIF(Realisasi!$E:$E,Highlight!$X35,Realisasi!F:F) -> 24754 | E35: =SUMIF(Realisasi!$E:$E,Highlight!$X35,Realisasi!G:G) -> 86537 | F35: =SUMIF(Realisasi!$E:$E,Highlight!$X35,Realisasi!H:H) -> 23087 | G35: =SUMIF(Realisasi!$E:$E,Highlight!$X35,Realisasi!I:I) -> 17 | H35: =SUMIF(Realisasi!$E:$E,Highlight!$X35,Realisasi!J:J) -> 215 | I35: =SUM(D35:H35) -> 134610 | K35: =SUMIF(Realisasi!$E:$E,Highlight!$X35,Realisasi!K:K) -> 2924293659 | L35: =SUMIF(Realisasi!$E:$E,Highlight!$X35,Realisasi!L:L) -> 10334859877 | M35: =SUMIF(Realisasi!$E:$E,Highlight!$X35,Realisasi!M:M) -> 3832544468 | N35: =SUMIF(Realisasi!$E:$E,Highlight!$X35,Realisasi!N:N) -> 724000 | O35: =SUMIF(Realisasi!$E:$E,Highlight!$X35,Realisasi!O:O) -> 16063700 | P35: =SUM(K35:O35) -> 17108485704 | R35: =SUMIF(Realisasi!$E:$E,Highlight!$X35,Realisasi!P:P) -> 4386438 | S35: =SUMIF(Realisasi!$E:$E,Highlight!$X35,Realisasi!Q:Q) -> 103348599 | T35: =SUMIF(Realisasi!$E:$E,Highlight!$X35,Realisasi!R:R) -> 68644486 | U35: =SUMIF(Realisasi!$E:$E,Highlight!$X35,Realisasi!S:S) -> 546 | V35: =SUMIF(Realisasi!$E:$E,Highlight!$X35,Realisasi!T:T) -> 24301 | W35: =SUM(R35:V35) -> 176404370 | X35: =CONCATENATE(A$18,A35) -> ALFA GROUP202503
A36: 202504 | B36: 45748 | D36: =SUMIF(Realisasi!$E:$E,Highlight!$X36,Realisasi!F:F) -> 22089 | E36: =SUMIF(Realisasi!$E:$E,Highlight!$X36,Realisasi!G:G) -> 71432 | F36: =SUMIF(Realisasi!$E:$E,Highlight!$X36,Realisasi!H:H) -> 20963 | G36: =SUMIF(Realisasi!$E:$E,Highlight!$X36,Realisasi!I:I) -> 13 | H36: =SUMIF(Realisasi!$E:$E,Highlight!$X36,Realisasi!J:J) -> 274 | I36: =SUM(D36:H36) -> 114771 | K36: =SUMIF(Realisasi!$E:$E,Highlight!$X36,Realisasi!K:K) -> 2252685289 | L36: =SUMIF(Realisasi!$E:$E,Highlight!$X36,Realisasi!L:L) -> 7503978381 | M36: =SUMIF(Realisasi!$E:$E,Highlight!$X36,Realisasi!M:M) -> 3011472419 | N36: =SUMIF(Realisasi!$E:$E,Highlight!$X36,Realisasi!N:N) -> 869200 | O36: =SUMIF(Realisasi!$E:$E,Highlight!$X36,Realisasi!O:O) -> 14664300 | P36: =SUM(K36:O36) -> 12783669589 | R36: =SUMIF(Realisasi!$E:$E,Highlight!$X36,Realisasi!P:P) -> 3379024 | S36: =SUMIF(Realisasi!$E:$E,Highlight!$X36,Realisasi!Q:Q) -> 75039784 | T36: =SUMIF(Realisasi!$E:$E,Highlight!$X36,Realisasi!R:R) -> 53939547 | U36: =SUMIF(Realisasi!$E:$E,Highlight!$X36,Realisasi!S:S) -> 2498 | V36: =SUMIF(Realisasi!$E:$E,Highlight!$X36,Realisasi!T:T) -> 13911 | W36: =SUM(R36:V36) -> 132374764 | X36: =CONCATENATE(A$18,A36) -> ALFA GROUP202504
A37: 202505 | B37: 45778 | D37: =SUMIF(Realisasi!$E:$E,Highlight!$X37,Realisasi!F:F) -> 19905 | E37: =SUMIF(Realisasi!$E:$E,Highlight!$X37,Realisasi!G:G) -> 64277 | F37: =SUMIF(Realisasi!$E:$E,Highlight!$X37,Realisasi!H:H) -> 20517 | G37: =SUMIF(Realisasi!$E:$E,Highlight!$X37,Realisasi!I:I) -> 26 | H37: =SUMIF(Realisasi!$E:$E,Highlight!$X37,Realisasi!J:J) -> 358 | I37: =SUM(D37:H37) -> 105083 | K37: =SUMIF(Realisasi!$E:$E,Highlight!$X37,Realisasi!K:K) -> 1997239662 | L37: =SUMIF(Realisasi!$E:$E,Highlight!$X37,Realisasi!L:L) -> 6569143301 | M37: =SUMIF(Realisasi!$E:$E,Highlight!$X37,Realisasi!M:M) -> 2938618660 | N37: =SUMIF(Realisasi!$E:$E,Highlight!$X37,Realisasi!N:N) -> 932700 | O37: =SUMIF(Realisasi!$E:$E,Highlight!$X37,Realisasi!O:O) -> 17996501 | P37: =SUM(K37:O37) -> 11523930824 | R37: =SUMIF(Realisasi!$E:$E,Highlight!$X37,Realisasi!P:P) -> 2995856 | S37: =SUMIF(Realisasi!$E:$E,Highlight!$X37,Realisasi!Q:Q) -> 65691433 | T37: =SUMIF(Realisasi!$E:$E,Highlight!$X37,Realisasi!R:R) -> 52641548 | U37: =SUMIF(Realisasi!$E:$E,Highlight!$X37,Realisasi!S:S) -> 64 | V37: =SUMIF(Realisasi!$E:$E,Highlight!$X37,Realisasi!T:T) -> 17949 | W37: =SUM(R37:V37) -> 121346850 | X37: =CONCATENATE(A$18,A37) -> ALFA GROUP202505
A38: 202506 | B38: 45809 | D38: =SUMIF(Realisasi!$E:$E,Highlight!$X38,Realisasi!F:F) -> 22294 | E38: =SUMIF(Realisasi!$E:$E,Highlight!$X38,Realisasi!G:G) -> 80610 | F38: =SUMIF(Realisasi!$E:$E,Highlight!$X38,Realisasi!H:H) -> 23291 | G38: =SUMIF(Realisasi!$E:$E,Highlight!$X38,Realisasi!I:I) -> 26 | H38: =SUMIF(Realisasi!$E:$E,Highlight!$X38,Realisasi!J:J) -> 374 | I38: =SUM(D38:H38) -> 126595 | K38: =SUMIF(Realisasi!$E:$E,Highlight!$X38,Realisasi!K:K) -> 2282723076 | L38: =SUMIF(Realisasi!$E:$E,Highlight!$X38,Realisasi!L:L) -> 8577464438 | M38: =SUMIF(Realisasi!$E:$E,Highlight!$X38,Realisasi!M:M) -> 3320134443 | N38: =SUMIF(Realisasi!$E:$E,Highlight!$X38,Realisasi!N:N) -> 2015058 | O38: =SUMIF(Realisasi!$E:$E,Highlight!$X38,Realisasi!O:O) -> 22631385 | P38: =SUM(K38:O38) -> 14204968400 | R38: =SUMIF(Realisasi!$E:$E,Highlight!$X38,Realisasi!P:P) -> 3424081 | S38: =SUMIF(Realisasi!$E:$E,Highlight!$X38,Realisasi!Q:Q) -> 85774645 | T38: =SUMIF(Realisasi!$E:$E,Highlight!$X38,Realisasi!R:R) -> 59451642 | U38: =SUMIF(Realisasi!$E:$E,Highlight!$X38,Realisasi!S:S) -> 7276 | V38: =SUMIF(Realisasi!$E:$E,Highlight!$X38,Realisasi!T:T) -> 20939 | W38: =SUM(R38:V38) -> 148678583 | X38: =CONCATENATE(A$18,A38) -> ALFA GROUP202506
A39: 202507 | B39: 45839 | D39: =SUMIF(Realisasi!$E:$E,Highlight!$X39,Realisasi!F:F) -> 22936 | E39: =SUMIF(Realisasi!$E:$E,Highlight!$X39,Realisasi!G:G) -> 81425 | F39: =SUMIF(Realisasi!$E:$E,Highlight!$X39,Realisasi!H:H) -> 24766 | G39: =SUMIF(Realisasi!$E:$E,Highlight!$X39,Realisasi!I:I) -> 29 | H39: =SUMIF(Realisasi!$E:$E,Highlight!$X39,Realisasi!J:J) -> 485 | I39: =SUM(D39:H39) -> 129641 | K39: =SUMIF(Realisasi!$E:$E,Highlight!$X39,Realisasi!K:K) -> 2299339424 | L39: =SUMIF(Realisasi!$E:$E,Highlight!$X39,Realisasi!L:L) -> 8561522595 | M39: =SUMIF(Realisasi!$E:$E,Highlight!$X39,Realisasi!M:M) -> 3478146755 | N39: =SUMIF(Realisasi!$E:$E,Highlight!$X39,Realisasi!N:N) -> 944400 | O39: =SUMIF(Realisasi!$E:$E,Highlight!$X39,Realisasi!O:O) -> 33227000 | P39: =SUM(K39:O39) -> 14373180174 | R39: =SUMIF(Realisasi!$E:$E,Highlight!$X39,Realisasi!P:P) -> 3449006 | S39: =SUMIF(Realisasi!$E:$E,Highlight!$X39,Realisasi!Q:Q) -> 85615226 | T39: =SUMIF(Realisasi!$E:$E,Highlight!$X39,Realisasi!R:R) -> 62262212 | U39: =SUMIF(Realisasi!$E:$E,Highlight!$X39,Realisasi!S:S) -> 1197 | V39: =SUMIF(Realisasi!$E:$E,Highlight!$X39,Realisasi!T:T) -> 21537 | W39: =SUM(R39:V39) -> 151349178 | X39: =CONCATENATE(A$18,A39) -> ALFA GROUP202507
A40: 202508 | B40: 45870 | D40: =SUMIF(Realisasi!$E:$E,Highlight!$X40,Realisasi!F:F) -> 21499 | E40: =SUMIF(Realisasi!$E:$E,Highlight!$X40,Realisasi!G:G) -> 74837 | F40: =SUMIF(Realisasi!$E:$E,Highlight!$X40,Realisasi!H:H) -> 23504 | G40: =SUMIF(Realisasi!$E:$E,Highlight!$X40,Realisasi!I:I) -> 42 | H40: =SUMIF(Realisasi!$E:$E,Highlight!$X40,Realisasi!J:J) -> 539 | I40: =SUM(D40:H40) -> 120421 | K40: =SUMIF(Realisasi!$E:$E,Highlight!$X40,Realisasi!K:K) -> 2144898935 | L40: =SUMIF(Realisasi!$E:$E,Highlight!$X40,Realisasi!L:L) -> 7745484296 | M40: =SUMIF(Realisasi!$E:$E,Highlight!$X40,Realisasi!M:M) -> 3312317338 | N40: =SUMIF(Realisasi!$E:$E,Highlight!$X40,Realisasi!N:N) -> 3990100 | O40: =SUMIF(Realisasi!$E:$E,Highlight!$X40,Realisasi!O:O) -> 35205700 | P40: =SUM(K40:O40) -> 13241896369 | R40: =SUMIF(Realisasi!$E:$E,Highlight!$X40,Realisasi!P:P) -> 3217346 | S40: =SUMIF(Realisasi!$E:$E,Highlight!$X40,Realisasi!Q:Q) -> 77454843 | T40: =SUMIF(Realisasi!$E:$E,Highlight!$X40,Realisasi!R:R) -> 59272708 | U40: =SUMIF(Realisasi!$E:$E,Highlight!$X40,Realisasi!S:S) -> 9912 | V40: =SUMIF(Realisasi!$E:$E,Highlight!$X40,Realisasi!T:T) -> 21394 | W40: =SUM(R40:V40) -> 139976203 | X40: =CONCATENATE(A$18,A40) -> ALFA GROUP202508
A41: 202509 | B41: 45901 | D41: =SUMIF(Realisasi!$E:$E,Highlight!$X41,Realisasi!F:F) -> 21875 | E41: =SUMIF(Realisasi!$E:$E,Highlight!$X41,Realisasi!G:G) -> 76470 | F41: =SUMIF(Realisasi!$E:$E,Highlight!$X41,Realisasi!H:H) -> 22946 | G41: =SUMIF(Realisasi!$E:$E,Highlight!$X41,Realisasi!I:I) -> 30 | H41: =SUMIF(Realisasi!$E:$E,Highlight!$X41,Realisasi!J:J) -> 505 | I41: =SUM(D41:H41) -> 121826 | K41: =SUMIF(Realisasi!$E:$E,Highlight!$X41,Realisasi!K:K) -> 2154455892 | L41: =SUMIF(Realisasi!$E:$E,Highlight!$X41,Realisasi!L:L) -> 7776514545 | M41: =SUMIF(Realisasi!$E:$E,Highlight!$X41,Realisasi!M:M) -> 3198109908 | N41: =SUMIF(Realisasi!$E:$E,Highlight!$X41,Realisasi!N:N) -> 830400 | O41: =SUMIF(Realisasi!$E:$E,Highlight!$X41,Realisasi!O:O) -> 32626110 | P41: =SUM(K41:O41) -> 13162536855 | R41: =SUMIF(Realisasi!$E:$E,Highlight!$X41,Realisasi!P:P) -> 3231681 | S41: =SUMIF(Realisasi!$E:$E,Highlight!$X41,Realisasi!Q:Q) -> 77765146 | T41: =SUMIF(Realisasi!$E:$E,Highlight!$X41,Realisasi!R:R) -> 57205672 | U41: =SUMIF(Realisasi!$E:$E,Highlight!$X41,Realisasi!S:S) -> 2292 | V41: =SUMIF(Realisasi!$E:$E,Highlight!$X41,Realisasi!T:T) -> 22489 | W41: =SUM(R41:V41) -> 138227280 | X41: =CONCATENATE(A$18,A41) -> ALFA GROUP202509
A42: 202510 | B42: 45931 | D42: =SUMIF(Realisasi!$E:$E,Highlight!$X42,Realisasi!F:F) -> 22030 | E42: =SUMIF(Realisasi!$E:$E,Highlight!$X42,Realisasi!G:G) -> 79746 | F42: =SUMIF(Realisasi!$E:$E,Highlight!$X42,Realisasi!H:H) -> 23378 | G42: =SUMIF(Realisasi!$E:$E,Highlight!$X42,Realisasi!I:I) -> 49 | H42: =SUMIF(Realisasi!$E:$E,Highlight!$X42,Realisasi!J:J) -> 722 | I42: =SUM(D42:H42) -> 125925 | K42: =SUMIF(Realisasi!$E:$E,Highlight!$X42,Realisasi!K:K) -> 2173642012 | L42: =SUMIF(Realisasi!$E:$E,Highlight!$X42,Realisasi!L:L) -> 8144251602 | M42: =SUMIF(Realisasi!$E:$E,Highlight!$X42,Realisasi!M:M) -> 3275789835 | N42: =SUMIF(Realisasi!$E:$E,Highlight!$X42,Realisasi!N:N) -> 2966859 | O42: =SUMIF(Realisasi!$E:$E,Highlight!$X42,Realisasi!O:O) -> 40795900 | P42: =SUM(K42:O42) -> 13637446208 | R42: =SUMIF(Realisasi!$E:$E,Highlight!$X42,Realisasi!P:P) -> 3260461 | S42: =SUMIF(Realisasi!$E:$E,Highlight!$X42,Realisasi!Q:Q) -> 81442516 | T42: =SUMIF(Realisasi!$E:$E,Highlight!$X42,Realisasi!R:R) -> 58536381 | U42: =SUMIF(Realisasi!$E:$E,Highlight!$X42,Realisasi!S:S) -> 13890 | V42: =SUMIF(Realisasi!$E:$E,Highlight!$X42,Realisasi!T:T) -> 39277 | W42: =SUM(R42:V42) -> 143292525 | X42: =CONCATENATE(A$18,A42) -> ALFA GROUP202510
A43: 202511 | B43: 45962 | D43: =SUMIF(Realisasi!$E:$E,Highlight!$X43,Realisasi!F:F) -> 19369 | E43: =SUMIF(Realisasi!$E:$E,Highlight!$X43,Realisasi!G:G) -> 76855 | F43: =SUMIF(Realisasi!$E:$E,Highlight!$X43,Realisasi!H:H) -> 22321 | G43: =SUMIF(Realisasi!$E:$E,Highlight!$X43,Realisasi!I:I) -> 32 | H43: =SUMIF(Realisasi!$E:$E,Highlight!$X43,Realisasi!J:J) -> 615 | I43: =SUM(D43:H43) -> 119192 | K43: =SUMIF(Realisasi!$E:$E,Highlight!$X43,Realisasi!K:K) -> 1986113055 | L43: =SUMIF(Realisasi!$E:$E,Highlight!$X43,Realisasi!L:L) -> 8084066586 | M43: =SUMIF(Realisasi!$E:$E,Highlight!$X43,Realisasi!M:M) -> 3284936912 | N43: =SUMIF(Realisasi!$E:$E,Highlight!$X43,Realisasi!N:N) -> 1962395 | O43: =SUMIF(Realisasi!$E:$E,Highlight!$X43,Realisasi!O:O) -> 38440500 | P43: =SUM(K43:O43) -> 13395519448 | R43: =SUMIF(Realisasi!$E:$E,Highlight!$X43,Realisasi!P:P) -> 2979167 | S43: =SUMIF(Realisasi!$E:$E,Highlight!$X43,Realisasi!Q:Q) -> 80840666 | T43: =SUMIF(Realisasi!$E:$E,Highlight!$X43,Realisasi!R:R) -> 58666547 | U43: =SUMIF(Realisasi!$E:$E,Highlight!$X43,Realisasi!S:S) -> 4368 | V43: =SUMIF(Realisasi!$E:$E,Highlight!$X43,Realisasi!T:T) -> 23500 | W43: =SUM(R43:V43) -> 142514248 | X43: =CONCATENATE(A$18,A43) -> ALFA GROUP202511
A44: 202512 | B44: 45992 | D44: =SUMIF(Realisasi!$E:$E,Highlight!$X44,Realisasi!F:F) -> 18786 | E44: =SUMIF(Realisasi!$E:$E,Highlight!$X44,Realisasi!G:G) -> 75474 | F44: =SUMIF(Realisasi!$E:$E,Highlight!$X44,Realisasi!H:H) -> 17527 | G44: =SUMIF(Realisasi!$E:$E,Highlight!$X44,Realisasi!I:I) -> 41 | H44: =SUMIF(Realisasi!$E:$E,Highlight!$X44,Realisasi!J:J) -> 601 | I44: =SUM(D44:H44) -> 112429 | K44: =SUMIF(Realisasi!$E:$E,Highlight!$X44,Realisasi!K:K) -> 1958285299 | L44: =SUMIF(Realisasi!$E:$E,Highlight!$X44,Realisasi!L:L) -> 8060809271 | M44: =SUMIF(Realisasi!$E:$E,Highlight!$X44,Realisasi!M:M) -> 2770406138 | N44: =SUMIF(Realisasi!$E:$E,Highlight!$X44,Realisasi!N:N) -> 2499281 | O44: =SUMIF(Realisasi!$E:$E,Highlight!$X44,Realisasi!O:O) -> 40996094 | P44: =SUM(K44:O44) -> 12832996083 | R44: =SUMIF(Realisasi!$E:$E,Highlight!$X44,Realisasi!P:P) -> 2937426 | S44: =SUMIF(Realisasi!$E:$E,Highlight!$X44,Realisasi!Q:Q) -> 80503906 | T44: =SUMIF(Realisasi!$E:$E,Highlight!$X44,Realisasi!R:R) -> 49477828 | U44: =SUMIF(Realisasi!$E:$E,Highlight!$X44,Realisasi!S:S) -> 10380 | V44: =SUMIF(Realisasi!$E:$E,Highlight!$X44,Realisasi!T:T) -> 36386 | W44: =SUM(R44:V44) -> 132965926 | X44: =CONCATENATE(A$18,A44) -> ALFA GROUP202512
B45: YTD 2025 | D45: =SUM(D33:D44) -> 260333 | E45: =SUM(E33:E44) -> 902661 | F45: =SUM(F33:F44) -> 266428 | G45: =SUM(G33:G44) -> 358 | H45: =SUM(H33:H44) -> 5616 | I45: =SUM(I33:I44) -> 1435396 | K45: =SUM(K33:K44) -> 26781498160 | L45: =SUM(L33:L44) -> 95987662689 | M45: =SUM(M33:M44) -> 39030117916 | N45: =SUM(N33:N44) -> 19247493 | O45: =SUM(O33:O44) -> 336887857 | P45: =SUM(P33:P44) -> 162155414115 | R45: =SUM(R33:R44) -> 40172213 | S45: =SUM(S33:S44) -> 959772443 | T45: =SUM(T33:T44) -> 698669069 | U45: =SUM(U33:U44) -> 53433 | V45: =SUM(V33:V44) -> 306628 | W45: =SUM(W33:W44) -> 1698973786
B46: Average | D46: =AVERAGE(D33:D44) -> 21694.417 | E46: =AVERAGE(E33:E44) -> 75221.75 | F46: =AVERAGE(F33:F44) -> 22202.333 | G46: =AVERAGE(G33:G44) -> 29.833333 | H46: =AVERAGE(H33:H44) -> 468 | I46: =AVERAGE(I33:I44) -> 119616.33 | K46: =AVERAGE(K33:K44) -> 2.2317915e+09 | L46: =AVERAGE(L33:L44) -> 7.9989719e+09 | M46: =AVERAGE(M33:M44) -> 3.2525098e+09 | N46: =AVERAGE(N33:N44) -> 1603957.8 | O46: =AVERAGE(O33:O44) -> 28073988 | P46: =AVERAGE(P33:P44) -> 1.3512951e+10 | R46: =AVERAGE(R33:R44) -> 3347684.4 | S46: =AVERAGE(S33:S44) -> 79981037 | T46: =AVERAGE(T33:T44) -> 58222422 | U46: =AVERAGE(U33:U44) -> 4452.75 | V46: =AVERAGE(V33:V44) -> 25552.333 | W46: =AVERAGE(W33:W44) -> 1.4158115e+08
A47: 202601 | B47: 46023 | D47: =SUMIF(Realisasi!$E:$E,Highlight!$X47,Realisasi!F:F) -> 136015 | E47: =SUMIF(Realisasi!$E:$E,Highlight!$X47,Realisasi!G:G) -> 145384 | F47: =SUMIF(Realisasi!$E:$E,Highlight!$X47,Realisasi!H:H) -> 25813 | G47: =SUMIF(Realisasi!$E:$E,Highlight!$X47,Realisasi!I:I) -> 14 | H47: =SUMIF(Realisasi!$E:$E,Highlight!$X47,Realisasi!J:J) -> 466 | I47: =SUM(D47:H47) -> 307692 | K47: =SUMIF(Realisasi!$E:$E,Highlight!$X47,Realisasi!K:K) -> 14149202932 | L47: =SUMIF(Realisasi!$E:$E,Highlight!$X47,Realisasi!L:L) -> 15416112510 | M47: =SUMIF(Realisasi!$E:$E,Highlight!$X47,Realisasi!M:M) -> 4630609680 | N47: =SUMIF(Realisasi!$E:$E,Highlight!$X47,Realisasi!N:N) -> 259800 | O47: =SUMIF(Realisasi!$E:$E,Highlight!$X47,Realisasi!O:O) -> 16537200 | P47: =SUM(K47:O47) -> 34212722122 | R47: =SUMIF(Realisasi!$E:$E,Highlight!$X47,Realisasi!P:P) -> 21223785 | S47: =SUMIF(Realisasi!$E:$E,Highlight!$X47,Realisasi!Q:Q) -> 153893548 | T47: =SUMIF(Realisasi!$E:$E,Highlight!$X47,Realisasi!R:R) -> 82212391 | U47: =SUMIF(Realisasi!$E:$E,Highlight!$X47,Realisasi!S:S) -> 124 | V47: =SUMIF(Realisasi!$E:$E,Highlight!$X47,Realisasi!T:T) -> 13472 | W47: =SUM(R47:V47) -> 257343320 | X47: =CONCATENATE(A$18,A47) -> ALFA GROUP202601
A48: 202602 | B48: 46054 | D48: =SUMIF(Realisasi!$E:$E,Highlight!$X48,Realisasi!F:F) -> 251488 | E48: =SUMIF(Realisasi!$E:$E,Highlight!$X48,Realisasi!G:G) -> 297658 | F48: =SUMIF(Realisasi!$E:$E,Highlight!$X48,Realisasi!H:H) -> 69052 | G48: =SUMIF(Realisasi!$E:$E,Highlight!$X48,Realisasi!I:I) -> 86 | H48: =SUMIF(Realisasi!$E:$E,Highlight!$X48,Realisasi!J:J) -> 1248 | I48: =SUM(D48:H48) -> 619532 | K48: =SUMIF(Realisasi!$E:$E,Highlight!$X48,Realisasi!K:K) -> 28433656676 | L48: =SUMIF(Realisasi!$E:$E,Highlight!$X48,Realisasi!L:L) -> 33400427620 | M48: =SUMIF(Realisasi!$E:$E,Highlight!$X48,Realisasi!M:M) -> 10246175136 | N48: =SUMIF(Realisasi!$E:$E,Highlight!$X48,Realisasi!N:N) -> 3140400 | O48: =SUMIF(Realisasi!$E:$E,Highlight!$X48,Realisasi!O:O) -> 57018580 | P48: =SUM(K48:O48) -> 72140418412 | R48: =SUMIF(Realisasi!$E:$E,Highlight!$X48,Realisasi!P:P) -> 42650452 | S48: =SUMIF(Realisasi!$E:$E,Highlight!$X48,Realisasi!Q:Q) -> 332889065 | T48: =SUMIF(Realisasi!$E:$E,Highlight!$X48,Realisasi!R:R) -> 182104947 | U48: =SUMIF(Realisasi!$E:$E,Highlight!$X48,Realisasi!S:S) -> 3262 | V48: =SUMIF(Realisasi!$E:$E,Highlight!$X48,Realisasi!T:T) -> 66054 | W48: =SUM(R48:V48) -> 557713780 | X48: =CONCATENATE(A$18,A48) -> ALFA GROUP202602
A49: 202603 | B49: 46082 | D49: =SUMIF(Realisasi!$E:$E,Highlight!$X49,Realisasi!F:F) -> 0 | E49: =SUMIF(Realisasi!$E:$E,Highlight!$X49,Realisasi!G:G) -> 41405 | F49: =SUMIF(Realisasi!$E:$E,Highlight!$X49,Realisasi!H:H) -> 3505 | G49: =SUMIF(Realisasi!$E:$E,Highlight!$X49,Realisasi!I:I) -> 19 | H49: =SUMIF(Realisasi!$E:$E,Highlight!$X49,Realisasi!J:J) -> 356 | I49: =SUM(D49:H49) -> 45285 | K49: =SUMIF(Realisasi!$E:$E,Highlight!$X49,Realisasi!K:K) -> 0 | L49: =SUMIF(Realisasi!$E:$E,Highlight!$X49,Realisasi!L:L) -> 5141479795 | M49: =SUMIF(Realisasi!$E:$E,Highlight!$X49,Realisasi!M:M) -> 580373019 | N49: =SUMIF(Realisasi!$E:$E,Highlight!$X49,Realisasi!N:N) -> 1721900 | O49: =SUMIF(Realisasi!$E:$E,Highlight!$X49,Realisasi!O:O) -> 23423201 | P49: =SUM(K49:O49) -> 5746997915 | R49: =SUMIF(Realisasi!$E:$E,Highlight!$X49,Realisasi!P:P) -> 0 | S49: =SUMIF(Realisasi!$E:$E,Highlight!$X49,Realisasi!Q:Q) -> 51317247 | T49: =SUMIF(Realisasi!$E:$E,Highlight!$X49,Realisasi!R:R) -> 10346704 | U49: =SUMIF(Realisasi!$E:$E,Highlight!$X49,Realisasi!S:S) -> 3994 | V49: =SUMIF(Realisasi!$E:$E,Highlight!$X49,Realisasi!T:T) -> 10666 | W49: =SUM(R49:V49) -> 61678611 | X49: =CONCATENATE(A$18,A49) -> ALFA GROUP202603
A50: 202604 | B50: 46113 | D50: =SUMIF(Realisasi!$E:$E,Highlight!$X50,Realisasi!F:F) -> 0 | E50: =SUMIF(Realisasi!$E:$E,Highlight!$X50,Realisasi!G:G) -> 0 | F50: =SUMIF(Realisasi!$E:$E,Highlight!$X50,Realisasi!H:H) -> 0 | G50: =SUMIF(Realisasi!$E:$E,Highlight!$X50,Realisasi!I:I) -> 0 | H50: =SUMIF(Realisasi!$E:$E,Highlight!$X50,Realisasi!J:J) -> 0 | I50: =SUM(D50:H50) -> 0 | K50: =SUMIF(Realisasi!$E:$E,Highlight!$X50,Realisasi!K:K) -> 0 | L50: =SUMIF(Realisasi!$E:$E,Highlight!$X50,Realisasi!L:L) -> 0 | M50: =SUMIF(Realisasi!$E:$E,Highlight!$X50,Realisasi!M:M) -> 0 | N50: =SUMIF(Realisasi!$E:$E,Highlight!$X50,Realisasi!N:N) -> 0 | O50: =SUMIF(Realisasi!$E:$E,Highlight!$X50,Realisasi!O:O) -> 0 | P50: =SUM(K50:O50) -> 0 | R50: =SUMIF(Realisasi!$E:$E,Highlight!$X50,Realisasi!P:P) -> 0 | S50: =SUMIF(Realisasi!$E:$E,Highlight!$X50,Realisasi!Q:Q) -> 0 | T50: =SUMIF(Realisasi!$E:$E,Highlight!$X50,Realisasi!R:R) -> 0 | U50: =SUMIF(Realisasi!$E:$E,Highlight!$X50,Realisasi!S:S) -> 0 | V50: =SUMIF(Realisasi!$E:$E,Highlight!$X50,Realisasi!T:T) -> 0 | W50: =SUM(R50:V50) -> 0 | X50: =CONCATENATE(A$18,A50) -> ALFA GROUP202604
A51: 202605 | B51: 46143 | D51: =SUMIF(Realisasi!$E:$E,Highlight!$X51,Realisasi!F:F) -> 0 | E51: =SUMIF(Realisasi!$E:$E,Highlight!$X51,Realisasi!G:G) -> 0 | F51: =SUMIF(Realisasi!$E:$E,Highlight!$X51,Realisasi!H:H) -> 0 | G51: =SUMIF(Realisasi!$E:$E,Highlight!$X51,Realisasi!I:I) -> 0 | H51: =SUMIF(Realisasi!$E:$E,Highlight!$X51,Realisasi!J:J) -> 0 | I51: =SUM(D51:H51) -> 0 | K51: =SUMIF(Realisasi!$E:$E,Highlight!$X51,Realisasi!K:K) -> 0 | L51: =SUMIF(Realisasi!$E:$E,Highlight!$X51,Realisasi!L:L) -> 0 | M51: =SUMIF(Realisasi!$E:$E,Highlight!$X51,Realisasi!M:M) -> 0 | N51: =SUMIF(Realisasi!$E:$E,Highlight!$X51,Realisasi!N:N) -> 0 | O51: =SUMIF(Realisasi!$E:$E,Highlight!$X51,Realisasi!O:O) -> 0 | P51: =SUM(K51:O51) -> 0 | R51: =SUMIF(Realisasi!$E:$E,Highlight!$X51,Realisasi!P:P) -> 0 | S51: =SUMIF(Realisasi!$E:$E,Highlight!$X51,Realisasi!Q:Q) -> 0 | T51: =SUMIF(Realisasi!$E:$E,Highlight!$X51,Realisasi!R:R) -> 0 | U51: =SUMIF(Realisasi!$E:$E,Highlight!$X51,Realisasi!S:S) -> 0 | V51: =SUMIF(Realisasi!$E:$E,Highlight!$X51,Realisasi!T:T) -> 0 | W51: =SUM(R51:V51) -> 0 | X51: =CONCATENATE(A$18,A51) -> ALFA GROUP202605
A52: 202606 | B52: 46174 | D52: =SUMIF(Realisasi!$E:$E,Highlight!$X52,Realisasi!F:F) -> 0 | E52: =SUMIF(Realisasi!$E:$E,Highlight!$X52,Realisasi!G:G) -> 0 | F52: =SUMIF(Realisasi!$E:$E,Highlight!$X52,Realisasi!H:H) -> 0 | G52: =SUMIF(Realisasi!$E:$E,Highlight!$X52,Realisasi!I:I) -> 0 | H52: =SUMIF(Realisasi!$E:$E,Highlight!$X52,Realisasi!J:J) -> 0 | I52: =SUM(D52:H52) -> 0 | K52: =SUMIF(Realisasi!$E:$E,Highlight!$X52,Realisasi!K:K) -> 0 | L52: =SUMIF(Realisasi!$E:$E,Highlight!$X52,Realisasi!L:L) -> 0 | M52: =SUMIF(Realisasi!$E:$E,Highlight!$X52,Realisasi!M:M) -> 0 | N52: =SUMIF(Realisasi!$E:$E,Highlight!$X52,Realisasi!N:N) -> 0 | O52: =SUMIF(Realisasi!$E:$E,Highlight!$X52,Realisasi!O:O) -> 0 | P52: =SUM(K52:O52) -> 0 | R52: =SUMIF(Realisasi!$E:$E,Highlight!$X52,Realisasi!P:P) -> 0 | S52: =SUMIF(Realisasi!$E:$E,Highlight!$X52,Realisasi!Q:Q) -> 0 | T52: =SUMIF(Realisasi!$E:$E,Highlight!$X52,Realisasi!R:R) -> 0 | U52: =SUMIF(Realisasi!$E:$E,Highlight!$X52,Realisasi!S:S) -> 0 | V52: =SUMIF(Realisasi!$E:$E,Highlight!$X52,Realisasi!T:T) -> 0 | W52: =SUM(R52:V52) -> 0 | X52: =CONCATENATE(A$18,A52) -> ALFA GROUP202606
A53: 202607 | B53: 46204 | D53: =SUMIF(Realisasi!$E:$E,Highlight!$X53,Realisasi!F:F) -> 0 | E53: =SUMIF(Realisasi!$E:$E,Highlight!$X53,Realisasi!G:G) -> 0 | F53: =SUMIF(Realisasi!$E:$E,Highlight!$X53,Realisasi!H:H) -> 0 | G53: =SUMIF(Realisasi!$E:$E,Highlight!$X53,Realisasi!I:I) -> 0 | H53: =SUMIF(Realisasi!$E:$E,Highlight!$X53,Realisasi!J:J) -> 0 | I53: =SUM(D53:H53) -> 0 | K53: =SUMIF(Realisasi!$E:$E,Highlight!$X53,Realisasi!K:K) -> 0 | L53: =SUMIF(Realisasi!$E:$E,Highlight!$X53,Realisasi!L:L) -> 0 | M53: =SUMIF(Realisasi!$E:$E,Highlight!$X53,Realisasi!M:M) -> 0 | N53: =SUMIF(Realisasi!$E:$E,Highlight!$X53,Realisasi!N:N) -> 0 | O53: =SUMIF(Realisasi!$E:$E,Highlight!$X53,Realisasi!O:O) -> 0 | P53: =SUM(K53:O53) -> 0 | R53: =SUMIF(Realisasi!$E:$E,Highlight!$X53,Realisasi!P:P) -> 0 | S53: =SUMIF(Realisasi!$E:$E,Highlight!$X53,Realisasi!Q:Q) -> 0 | T53: =SUMIF(Realisasi!$E:$E,Highlight!$X53,Realisasi!R:R) -> 0 | U53: =SUMIF(Realisasi!$E:$E,Highlight!$X53,Realisasi!S:S) -> 0 | V53: =SUMIF(Realisasi!$E:$E,Highlight!$X53,Realisasi!T:T) -> 0 | W53: =SUM(R53:V53) -> 0 | X53: =CONCATENATE(A$18,A53) -> ALFA GROUP202607
A54: 202608 | B54: 46235 | D54: =SUMIF(Realisasi!$E:$E,Highlight!$X54,Realisasi!F:F) -> 0 | E54: =SUMIF(Realisasi!$E:$E,Highlight!$X54,Realisasi!G:G) -> 0 | F54: =SUMIF(Realisasi!$E:$E,Highlight!$X54,Realisasi!H:H) -> 0 | G54: =SUMIF(Realisasi!$E:$E,Highlight!$X54,Realisasi!I:I) -> 0 | H54: =SUMIF(Realisasi!$E:$E,Highlight!$X54,Realisasi!J:J) -> 0 | I54: =SUM(D54:H54) -> 0 | K54: =SUMIF(Realisasi!$E:$E,Highlight!$X54,Realisasi!K:K) -> 0 | L54: =SUMIF(Realisasi!$E:$E,Highlight!$X54,Realisasi!L:L) -> 0 | M54: =SUMIF(Realisasi!$E:$E,Highlight!$X54,Realisasi!M:M) -> 0 | N54: =SUMIF(Realisasi!$E:$E,Highlight!$X54,Realisasi!N:N) -> 0 | O54: =SUMIF(Realisasi!$E:$E,Highlight!$X54,Realisasi!O:O) -> 0 | P54: =SUM(K54:O54) -> 0 | R54: =SUMIF(Realisasi!$E:$E,Highlight!$X54,Realisasi!P:P) -> 0 | S54: =SUMIF(Realisasi!$E:$E,Highlight!$X54,Realisasi!Q:Q) -> 0 | T54: =SUMIF(Realisasi!$E:$E,Highlight!$X54,Realisasi!R:R) -> 0 | U54: =SUMIF(Realisasi!$E:$E,Highlight!$X54,Realisasi!S:S) -> 0 | V54: =SUMIF(Realisasi!$E:$E,Highlight!$X54,Realisasi!T:T) -> 0 | W54: =SUM(R54:V54) -> 0 | X54: =CONCATENATE(A$18,A54) -> ALFA GROUP202608
...

Sheet Portfolio
A1: ALFA GROUP | B1: 1 | C1: =CONCATENATE(A1,B1) -> ALFA GROUP1 | D1: ALFAMART | E1: 1 | F1: ALFA GROUP | G1: 1 | H1: =VLOOKUP(G1,E:F,2,0) -> ALFA GROUP | I1: 0 | J1: =_xlfn.CONCAT(H1,I1) -> ALFA GROUP0 | K1: 1 | L1: =H1 -> ALFA GROUP | M1: 1 | N1: =VLOOKUP(M1,K:L,2,0) -> ALFA GROUP | O1: 1 | P1: TRANSACTION | Q1: 1 | S1: 1 | T1: =VLOOKUP(S1,O1:Q3,3,0) -> 1 | U1: =CONCATENATE(VLOOKUP(S1,O1:P3,2,0)," - ",N1," ",T2) -> TRANSACTION - ALFA GROUP 0
A2: ALFA GROUP | B2: =IF(A2=A1,B1+1,1) -> 2 | C2: =CONCATENATE(A2,B2) -> ALFA GROUP2 | D2: ALFAMIDI | E2: =E1+1 -> 2 | F2: ANCOL | H2: =H1 -> ALFA GROUP | I2: 1 | J2: =_xlfn.CONCAT(H2,I2) -> ALFA GROUP1 | K2: =K1+1 -> 2 | L2: =IFERROR(VLOOKUP(J2,C:D,2,0),"") -> ALFAMART | O2: 2 | P2: SALES VOLUME | Q2: 1000 | R2: (Idr Ribu) | T2: =VLOOKUP(S1,O1:R3,4,0) -> 0
A3: ALFA GROUP | B3: =IF(A3=A2,B2+1,1) -> 3 | C3: =CONCATENATE(A3,B3) -> ALFA GROUP3 | D3: DAN+DAN | E3: =E2+1 -> 3 | F3: BANBAN TEA | H3: =H2 -> ALFA GROUP | I3: =I2+1 -> 2 | J3: =_xlfn.CONCAT(H3,I3) -> ALFA GROUP2 | K3: =K2+1 -> 3 | L3: =IFERROR(VLOOKUP(J3,C:D,2,0),"") -> ALFAMIDI | O3: 3 | P3: FEE BASED INCOME | Q3: 1
A4: ANCOL | B4: =IF(A4=A3,B3+1,1) -> 1 | C4: =CONCATENATE(A4,B4) -> ANCOL1 | D4: ANCOL | E4: =E3+1 -> 4 | F4: BEARD PAPA | H4: =H3 -> ALFA GROUP | I4: =I3+1 -> 3 | J4: =_xlfn.CONCAT(H4,I4) -> ALFA GROUP3 | K4: =K3+1 -> 4 | L4: =IFERROR(VLOOKUP(J4,C:D,2,0),"") -> DAN+DAN
A5: BANBAN TEA | B5: =IF(A5=A4,B4+1,1) -> 1 | C5: =CONCATENATE(A5,B5) -> BANBAN TEA1 | D5: BANBAN TEA | E5: =E4+1 -> 5 | F5: CHAMP RESTO | H5: =H4 -> ALFA GROUP | I5: =I4+1 -> 4 | J5: =_xlfn.CONCAT(H5,I5) -> ALFA GROUP4 | K5: =K4+1 -> 5 | L5: =IFERROR(VLOOKUP(J5,C:D,2,0),"")
A6: BEARD PAPA | B6: =IF(A6=A5,B5+1,1) -> 1 | C6: =CONCATENATE(A6,B6) -> BEARD PAPA1 | D6: BEARD PAPA | E6: =E5+1 -> 6 | F6: DAMRI | H6: =H5 -> ALFA GROUP | I6: =I5+1 -> 5 | J6: =_xlfn.CONCAT(H6,I6) -> ALFA GROUP5 | K6: =K5+1 -> 6 | L6: =IFERROR(VLOOKUP(J6,C:D,2,0),"")
A7: CHAMP RESTO | B7: =IF(A7=A6,B6+1,1) -> 1 | C7: =CONCATENATE(A7,B7) -> CHAMP RESTO1 | D7: BAMIKO | E7: =E6+1 -> 7 | F7: DELTA WIBAWA BERSAMA | H7: =H6 -> ALFA GROUP | I7: =I6+1 -> 6 | J7: =_xlfn.CONCAT(H7,I7) -> ALFA GROUP6 | K7: =K6+1 -> 7 | L7: =IFERROR(VLOOKUP(J7,C:D,2,0),"")
A8: CHAMP RESTO | B8: =IF(A8=A7,B7+1,1) -> 2 | C8: =CONCATENATE(A8,B8) -> CHAMP RESTO2 | D8: CHOPSTIX | E8: =E7+1 -> 8 | F8: DWIDAYA | H8: =H7 -> ALFA GROUP | I8: =I7+1 -> 7 | J8: =_xlfn.CONCAT(H8,I8) -> ALFA GROUP7 | K8: =K7+1 -> 8 | L8: =IFERROR(VLOOKUP(J8,C:D,2,0),"")
A9: CHAMP RESTO | B9: =IF(A9=A8,B8+1,1) -> 3 | C9: =CONCATENATE(A9,B9) -> CHAMP RESTO3 | D9: CROCO | E9: =E8+1 -> 9 | F9: EKA HOSPITAL | H9: =H8 -> ALFA GROUP | I9: =I8+1 -> 8 | J9: =_xlfn.CONCAT(H9,I9) -> ALFA GROUP8 | K9: =K8+1 -> 9 | L9: =IFERROR(VLOOKUP(J9,C:D,2,0),"")
A10: CHAMP RESTO | B10: =IF(A10=A9,B9+1,1) -> 4 | C10: =CONCATENATE(A10,B10) -> CHAMP RESTO4 | D10: DEWATA | E10: =E9+1 -> 10 | F10: ES TELLER 77 | H10: =H9 -> ALFA GROUP | I10: =I9+1 -> 9 | J10: =_xlfn.CONCAT(H10,I10) -> ALFA GROUP9 | K10: =K9+1 -> 10 | L10: =IFERROR(VLOOKUP(J10,C:D,2,0),"")
A11: CHAMP RESTO | B11: =IF(A11=A10,B10+1,1) -> 5 | C11: =CONCATENATE(A11,B11) -> CHAMP RESTO5 | D11: GOKANA | E11: =E10+1 -> 11 | F11: GRAMEDIA | H11: =H10 -> ALFA GROUP | I11: =I10+1 -> 10 | J11: =_xlfn.CONCAT(H11,I11) -> ALFA GROUP10 | K11: =K10+1 -> 11 | L11: =IFERROR(VLOOKUP(J11,C:D,2,0),"")
A12: CHAMP RESTO | B12: =IF(A12=A11,B11+1,1) -> 6 | C12: =CONCATENATE(A12,B12) -> CHAMP RESTO6 | D12: GRILL MAN | E12: =E11+1 -> 12 | F12: HAUS | H12: =H11 -> ALFA GROUP | I12: =I11+1 -> 11 | J12: =_xlfn.CONCAT(H12,I12) -> ALFA GROUP11 | K12: =K11+1 -> 12 | L12: =IFERROR(VLOOKUP(J12,C:D,2,0),"")
A13: CHAMP RESTO | B13: =IF(A13=A12,B12+1,1) -> 7 | C13: =CONCATENATE(A13,B13) -> CHAMP RESTO7 | D13: KOPILATINUM | E13: =E12+1 -> 13 | F13: HEAVENLY WANG | H13: =H12 -> ALFA GROUP | I13: =I12+1 -> 12 | J13: =_xlfn.CONCAT(H13,I13) -> ALFA GROUP12 | K13: =K12+1 -> 13 | L13: =IFERROR(VLOOKUP(J13,C:D,2,0),"")
A14: CHAMP RESTO | B14: =IF(A14=A13,B13+1,1) -> 8 | C14: =CONCATENATE(A14,B14) -> CHAMP RESTO8 | D14: MONSIEUR SPOON | E14: =E13+1 -> 14 | F14: HERO GROUP | H14: =H13 -> ALFA GROUP | I14: =I13+1 -> 13 | J14: =_xlfn.CONCAT(H14,I14) -> ALFA GROUP13 | K14: =K13+1 -> 14 | L14: =IFERROR(VLOOKUP(J14,C:D,2,0),"")
A15: CHAMP RESTO | B15: =IF(A15=A14,B14+1,1) -> 9 | C15: =CONCATENATE(A15,B15) -> CHAMP RESTO9 | D15: PLATINUM | E15: =E14+1 -> 15 | F15: HOKBEN | H15: =H14 -> ALFA GROUP | I15: =I14+1 -> 14 | J15: =_xlfn.CONCAT(H15,I15) -> ALFA GROUP14 | K15: =K14+1 -> 15 | L15: =IFERROR(VLOOKUP(J15,C:D,2,0),"")
... A44: KAWAN LAMA | B44: =IF(A44=A43,B43+1,1) -> 11 | C44: =CONCATENATE(A44,B44) -> KAWAN LAMA11 | D44: KELS | E44: =E43+1 -> 44 | F44: ZENBU | H44: =H43 -> ALFA GROUP | I44: =I43+1 -> 43 | J44: =_xlfn.CONCAT(H44,I44) -> ALFA GROUP43 | K44: =K43+1 -> 44 | L44: =IFERROR(VLOOKUP(J44,C:D,2,0),"")
A45: KAWAN LAMA | B45: =IF(A45=A44,B44+1,1) -> 12 | C45: =CONCATENATE(A45,B45) -> KAWAN LAMA12 | D45: PENDOPO | H45: =H44 -> ALFA GROUP | I45: =I44+1 -> 44 | J45: =_xlfn.CONCAT(H45,I45) -> ALFA GROUP44 | K45: =K44+1 -> 45 | L45: =IFERROR(VLOOKUP(J45,C:D,2,0),"")
A46: KAWAN LAMA | B46: =IF(A46=A45,B45+1,1) -> 13 | C46: =CONCATENATE(A46,B46) -> KAWAN LAMA13 | D46: SELMA | H46: =H45 -> ALFA GROUP | I46: =I45+1 -> 45 | J46: =_xlfn.CONCAT(H46,I46) -> ALFA GROUP45 | K46: =K45+1 -> 46 | L46: =IFERROR(VLOOKUP(J46,C:D,2,0),"")
A47: KAWAN LAMA | B47: =IF(A47=A46,B46+1,1) -> 14 | C47: =CONCATENATE(A47,B47) -> KAWAN LAMA14 | D47: SUSEN | H47: =H46 -> ALFA GROUP | I47: =I46+1 -> 46 | J47: =_xlfn.CONCAT(H47,I47) -> ALFA GROUP46 | K47: =K46+1 -> 47 | L47: =IFERROR(VLOOKUP(J47,C:D,2,0),"")
A48: KAWAN LAMA | B48: =IF(A48=A47,B47+1,1) -> 15 | C48: =CONCATENATE(A48,B48) -> KAWAN LAMA15 | D48: THYS | H48: =H47 -> ALFA GROUP | I48: =I47+1 -> 47 | J48: =_xlfn.CONCAT(H48,I48) -> ALFA GROUP47 | K48: =K47+1 -> 48 | L48: =IFERROR(VLOOKUP(J48,C:D,2,0),"")
A49: KAWAN LAMA | B49: =IF(A49=A48,B48+1,1) -> 16 | C49: =CONCATENATE(A49,B49) -> KAWAN LAMA16 | D49: TOYS KINGDOM | H49: =H48 -> ALFA GROUP | I49: =I48+1 -> 48 | J49: =_xlfn.CONCAT(H49,I49) -> ALFA GROUP48 | K49: =K48+1 -> 49 | L49: =IFERROR(VLOOKUP(J49,C:D,2,0),"")
A50: KCIC | B50: =IF(A50=A49,B49+1,1) -> 1 | C50: =CONCATENATE(A50,B50) -> KCIC1 | D50: KERETA CEPAT INDONESIA CHINA | H50: =H49 -> ALFA GROUP | I50: =I49+1 -> 49 | J50: =_xlfn.CONCAT(H50,I50) -> ALFA GROUP49 | K50: =K49+1 -> 50 | L50: =IFERROR(VLOOKUP(J50,C:D,2,0),"")
A51: KIMIA FARMA | B51: =IF(A51=A50,B50+1,1) -> 1 | C51: =CONCATENATE(A51,B51) -> KIMIA FARMA1 | D51: APOTEK KIMIA FARMA | H51: =H50 -> ALFA GROUP | I51: =I50+1 -> 50 | J51: =_xlfn.CONCAT(H51,I51) -> ALFA GROUP50 | K51: =K50+1 -> 51 | L51: =IFERROR(VLOOKUP(J51,C:D,2,0),"")
A52: LOTTE GROUP | B52: =IF(A52=A51,B51+1,1) -> 1 | C52: =CONCATENATE(A52,B52) -> LOTTE GROUP1 | D52: LOTTE GROSIR | H52: =H51 -> ALFA GROUP | I52: =I51+1 -> 51 | J52: =_xlfn.CONCAT(H52,I52) -> ALFA GROUP51 | K52: =K51+1 -> 52 | L52: =IFERROR(VLOOKUP(J52,C:D,2,0),"")
A53: LOTTE GROUP | B53: =IF(A53=A52,B52+1,1) -> 2 | C53: =CONCATENATE(A53,B53) -> LOTTE GROUP2 | D53: LOTTE MART | H53: =H52 -> ALFA GROUP | I53: =I52+1 -> 52 | J53: =_xlfn.CONCAT(H53,I53) -> ALFA GROUP52 | K53: =K52+1 -> 53 | L53: =IFERROR(VLOOKUP(J53,C:D,2,0),"")
A54: MAMA ROZ | B54: =IF(A54=A53,B53+1,1) -> 1 | C54: =CONCATENATE(A54,B54) -> MAMA ROZ1 | D54: MAMA ROZ | H54: =H53 -> ALFA GROUP | I54: =I53+1 -> 53 | J54: =_xlfn.CONCAT(H54,I54) -> ALFA GROUP53 | K54: =K53+1 -> 54 | L54: =IFERROR(VLOOKUP(J54,C:D,2,0),"")
A55: MAP GROUP | B55: =IF(A55=A54,B54+1,1) -> 1 | C55: =CONCATENATE(A55,B55) -> MAP GROUP1 | D55: 2XU | H55: =H54 -> ALFA GROUP | I55: =I54+1 -> 54 | J55: =_xlfn.CONCAT(H55,I55) -> ALFA GROUP54 | K55: =K54+1 -> 55 | L55: =IFERROR(VLOOKUP(J55,C:D,2,0),"")
A56: MAP GROUP | B56: =IF(A56=A55,B55+1,1) -> 2 | C56: =CONCATENATE(A56,B56) -> MAP GROUP2 | D56: ADIDAS | H56: =H55 -> ALFA GROUP | I56: =I55+1 -> 55 | J56: =_xlfn.CONCAT(H56,I56) -> ALFA GROUP55 | K56: =K55+1 -> 56 | L56: =IFERROR(VLOOKUP(J56,C:D,2,0),"")
... A61: MAP GROUP | B61: =IF(A61=A60,B60+1,1) -> 7 | C61: =CONCATENATE(A61,B61) -> MAP GROUP7 | D61: ATHLETE FOOT | H61: =H60 -> ALFA GROUP | I61: =I60+1 -> 60 | J61: =_xlfn.CONCAT(H61,I61) -> ALFA GROUP60 | K61: =K60+1 -> 61 | L61: =IFERROR(VLOOKUP(J61,C:D,2,0),"")
A62: MAP GROUP | B62: =IF(A62=A61,B61+1,1) -> 8 | C62: =CONCATENATE(A62,B62) -> MAP GROUP8 | D62: BABY STATION
A63: MAP GROUP | B63: =IF(A63=A62,B62+1,1) -> 9 | C63: =CONCATENATE(A63,B63) -> MAP GROUP9 | D63: BCBG
A64: MAP GROUP | B64: =IF(A64=A63,B63+1,1) -> 10 | C64: =CONCATENATE(A64,B64) -> MAP GROUP10 | D64: BIRKENSTOCK
A65: MAP GROUP | B65: =IF(A65=A64,B64+1,1) -> 11 | C65: =CONCATENATE(A65,B65) -> MAP GROUP11 | D65: CALVIN KLEIN
A66: MAP GROUP | B66: =IF(A66=A65,B65+1,1) -> 12 | C66: =CONCATENATE(A66,B66) -> MAP GROUP12 | D66: CLARKS
A67: MAP GROUP | B67: =IF(A67=A66,B66+1,1) -> 13 | C67: =CONCATENATE(A67,B67) -> MAP GROUP13 | D67: CONVERSE
A68: MAP GROUP | B68: =IF(A68=A67,B67+1,1) -> 14 | C68: =CONCATENATE(A68,B68) -> MAP GROUP14 | D68: CROCS
A69: MAP GROUP | B69: =IF(A69=A68,B68+1,1) -> 15 | C69: =CONCATENATE(A69,B69) -> MAP GROUP15 | D69: DIGIMAP
A70: MAP GROUP | B70: =IF(A70=A69,B69+1,1) -> 16 | C70: =CONCATENATE(A70,B70) -> MAP GROUP16 | D70: DIGIPLUS
A71: MAP GROUP | B71: =IF(A71=A70,B70+1,1) -> 17 | C71: =CONCATENATE(A71,B71) -> MAP GROUP17 | D71: DR MARTENS
A72: MAP GROUP | B72: =IF(A72=A71,B71+1,1) -> 18 | C72: =CONCATENATE(A72,B72) -> MAP GROUP18 | D72: FITFLOP
...

Sheet Sheet4
B2: Top 10 Merchant | C2: 45658 | D2: FY-25 | E2: 46023 | F2: Growth
F3: % | G3: Δ Delta
B4: MAP GROUP | C4: 113701561 | D4: 211099634852 | E4: 43103381103 | F4: =E4/C4-1 -> 378.09225 | G4: 42989679542
B5: KAWAN LAMA | C5: 3244703067 | D5: 38898630141 | E5: 11270015986 | F5: =E5/C5-1 -> 2.4733582 | G5: 8025312919
B6: ANCOL | C6: 5981200 | D6: 13151058840 | E6: 6677986906 | F6: =E6/C6-1 -> 1115.4962 | G6: 6672005706 | J6: Historical
B7: INDOMARET | C7: 12752570497 | D7: 150669116830 | E7: 18822659759 | F7: =E7/C7-1 -> 0.47598947 | G7: 6070089262 | J7: MTD | K7: YTD | L7: YTD
B8: ALFA GROUP | C8: 13076198406 | D8: 162155414115 | E8: 17114430511 | F8: =E8/C8-1 -> 0.3088231 | G8: 4038232105 | J8: =[1]Parameter!J4 -> 0 | K8: =J8 -> 0 | L8: 45627
B9: LOTTE GROUP | C9: 5922000 | D9: 3361841770 | E9: 2962380698 | F9: =E9/C9-1 -> 499.23315 | G9: 2956458698
B10: MITRA10 | C10: 1013916445 | D10: 12538438120 | E10: 3807233949 | F10: =E10/C10-1 -> 2.754978 | G10: 2793317504
B11: DWIDAYA | C11: 97993006 | D11: 5284101260 | E11: 1667471081 | F11: =E11/C11-1 -> 16.016225 | G11: 1569478075
B12: PERTAMINA RETAIL | C12: 184255851 | D12: 1002287788 | E12: 1364382292 | F12: =E12/C12-1 -> 6.4048248 | G12: 1180126441
B13: KCIC | C13: 1756925000 | D13: 27322724008 | E13: 1746345000 | F13: =E13/C13-1 -> -0.0060218848 | G13: -10580000
B15: Bottom 10 Merchant | C15: 45658 | D15: FY-25 | E15: 46023 | F15: Growth
F16: % | G16: Δ Delta
B17: OPTIK MELAWAI | C17: 4619945199 | D17: 8081418711 | E17: 336854000 | F17: =E17/C17-1 -> -0.92708701 | G17: -4283091199
B18: HAUS | C18: 2410806978 | D18: 8887740957 | E18: 6183000 | F18: =E18/C18-1 -> -0.9974353 | G18: -2404623978
B19: YOSHINOYA | C19: 2170435300 | D19: 162885884420 | E19: 738229005 | F19: =E19/C19-1 -> -0.65987053 | G19: -1432206295
B20: SARINAH | C20: 812665629 | D20: 7858189536 | E20: 96872196 | F20: =E20/C20-1 -> -0.88079698 | G20: -715793433
B21: YOGURT REPUBLIC | C21: 399582063 | D21: 4856996073 | E21: 128108800 | F21: =E21/C21-1 -> -0.67939302 | G21: -271473263
B22: PLATINUM CINEPLEX | C22: 263415000 | D22: 2427049250 | E22: 2000000 | F22: =E22/C22-1 -> -0.99240742 | G22: -261415000
B23: SOUR SALLY | C23: 196027608 | D23: 945709040 | E23: 14184990 | F23: =E23/C23-1 -> -0.92763779 | G23: -181842618
B24: HOKKAIDO BAKED CHEESE | C24: 115737747 | D24: 2228970911 | E24: 16327984 | F24: =E24/C24-1 -> -0.85892257 | G24: -99409763
B25: STEVEN GROUP | C25: 100397002 | D25: 924829882 | E25: 49474443 | F25: =E25/C25-1 -> -0.50721195 | G25: -50922559
B26: SURYA BUMI RETAILINDO | C26: 31210300 | D26: 64378300 | E26: 0 | F26: =E26/C26-1 -> -1 | G26: -31210300
B29: Top TRX - Kenaikan Terbesar | C29: Jan-25 | D29: FY-25 | E29: Jan-26 | F29: Growth
F30: % | G30: Δ Delta
B31: MAP GROUP | C31: 836 | D31: 230006 | E31: 53930 | F31: =E31/C31-1 -> 63.509569 | G31: 53094
B32: INDOMARET | C32: 123472 | D32: 1445227 | E32: 170234 | F32: =E32/C32-1 -> 0.37872554 | G32: 46762
B33: ALFA GROUP | C33: 114246 | D33: 1435396 | E33: 153844 | F33: =E33/C33-1 -> 0.34660294 | G33: 39598
B34: ANCOL | C34: 49 | D34: 31385 | E34: 6630 | F34: =E34/C34-1 -> 134.30612 | G34: 6581
B35: PERTAMINA RETAIL | C35: 797 | D35: 6468 | E35: 7327 | F35: =E35/C35-1 -> 8.1932246 | G35: 6530
B36: KAWAN LAMA | C36: 2555 | D36: 54628 | E36: 7076 | F36: =E36/C36-1 -> 1.7694716 | G36: 4521
B37: LOTTE GROUP | C37: 18 | D37: 6098 | E37: 4218 | F37: =E37/C37-1 -> 233.33333 | G37: 4200
B38: SOLARIA | C38: 1839 | D38: 26110 | E38: 4459 | F38: =E38/C38-1 -> 1.4246873 | G38: 2620
B39: MITRA10 | C39: 533 | D39: 5801 | E39: 1745 | F39: =E39/C39-1 -> 2.2739212 | G39: 1212
B40: HOP HOP | C40: 517 | D40: 137370 | E40: 1210 | F40: =E40/C40-1 -> 1.3404255 | G40: 693
B43: Bottom TRX - Penurunan Terbesar | C43: Jan-25 | D43: FY-25 | E43: Jan-26 | F43: Growth
F44: % | G44: Δ Delta
B45: HAUS | C45: 59404 | D45: 210783 | E45: 89 | F45: =E45/C45-1 -> -0.99850178 | G45: -59315
B46: YOSHINOYA | C46: 13806 | D46: 8769872 | E46: 2217 | F46: =E46/C46-1 -> -0.83941764 | G46: -11589
...

Sheet Sheet1
A3: MERCHANT_GROUP | B3: MERCHANT_ANCHOR
A4: ALFA GROUP | B4: ALFAMART
A5: ALFA GROUP | B5: ALFAMIDI
A6: ALFA GROUP | B6: DAN+DAN
A7: ANCOL | B7: ANCOL
A8: BANBAN TEA | B8: BANBAN TEA
A9: BEARD PAPA | B9: BEARD PAPA
A10: CHAMP RESTO | B10: BAMIKO
A11: CHAMP RESTO | B11: CHOPSTIX
A12: CHAMP RESTO | B12: CROCO
A13: CHAMP RESTO | B13: DEWATA
A14: CHAMP RESTO | B14: GOKANA
... A150: (blank) | B150: (blank)
A151: Grand Total

Sheet Realisasi
A1: MERCHANT_GROUP | B1: MERCHANT_ANCHOR | C1: TRX_MONTH | D1: YEAR | E1: KEY | F1: TRX_DEBIT_ONUS | G1: TRX_DEBIT_OFFUS | H1: TRX_CREDIT_OFFUS | I1: TRX_QRIS_ONUS | J1: TRX_QRIS_OFFUS | K1: SV_DEBIT_ONUS | L1: SV_DEBIT_OFFUS | M1: SV_CREDIT_OFFUS | N1: SV_QRIS_ONUS | O1: SV_QRIS_OFFUS | P1: FBI_DEBIT_ONUS | Q1: FBI_DEBIT_OFFUS | R1: FBI_CREDIT_OFFUS | S1: FBI_QRIS_ONUS | T1: FBI_QRIS_OFFUS
A2: ALFA GROUP | B2: ALFAMART | C2: 202401 | D2: =MID(C2,1,4) -> 2024 | E2: =IF(Portfolio!$M$1=1,CONCATENATE(A2,C2),CONCATENATE(B2,C2)) -> ALFA GROUP202401 | F2: 15991 | G2: 59542 | H2: 11685 | I2: 0 | J2: 1 | K2: 1665490406 | L2: 6336019727 | M2: 1852964987 | N2: 0 | O2: 130000 | P2: 2498234 | Q2: 55387878 | R2: 33312779 | S2: 0 | T2: 390
A3: ALFA GROUP | B3: ALFAMIDI | C3: 202401 | D3: =MID(C3,1,4) -> 2024 | E3: =IF(Portfolio!$M$1=1,CONCATENATE(A3,C3),CONCATENATE(B3,C3)) -> ALFA GROUP202401 | F3: 11 | G3: 59 | H3: 16 | I3: 0 | J3: 0 | K3: 1886347 | L3: 9226450 | M3: 3169885 | N3: 0 | O3: 0 | P3: 2830 | Q3: 82511 | R3: 57058 | S3: 0 | T3: 0
A4: ALFA GROUP | B4: DAN+DAN | C4: 202401 | D4: =MID(C4,1,4) -> 2024 | E4: =IF(Portfolio!$M$1=1,CONCATENATE(A4,C4),CONCATENATE(B4,C4)) -> ALFA GROUP202401 | F4: 260 | G4: 890 | H4: 118 | I4: 0 | J4: 0 | K4: 44369337 | L4: 137731658 | M4: 26234200 | N4: 0 | O4: 0 | P4: 66554 | Q4: 1275079 | R4: 470290 | S4: 0 | T4: 0
A5: ANCOL | B5: ANCOL | C5: 202401 | D5: =MID(C5,1,4) -> 2024 | E5: =IF(Portfolio!$M$1=1,CONCATENATE(A5,C5),CONCATENATE(B5,C5)) -> ANCOL202401 | F5: 2 | G5: 5 | H5: 0 | I5: 0 | J5: 0 | K5: 1881000 | L5: 1966100 | M5: 0 | N5: 0 | O5: 0 | P5: 2822 | Q5: 19661 | R5: 0 | S5: 0 | T5: 0
A6: CHAMP RESTO | B6: CROCO | C6: 202401 | D6: =MID(C6,1,4) -> 2024 | E6: =IF(Portfolio!$M$1=1,CONCATENATE(A6,C6),CONCATENATE(B6,C6)) -> CHAMP RESTO202401 | F6: 0 | G6: 1 | H6: 0 | I6: 0 | J6: 0 | K6: 0 | L6: 315727 | M6: 0 | N6: 0 | O6: 0 | P6: 0 | Q6: 3157 | R6: 0 | S6: 0 | T6: 0
A7: CHAMP RESTO | B7: DEWATA | C7: 202401 | D7: =MID(C7,1,4) -> 2024 | E7: =IF(Portfolio!$M$1=1,CONCATENATE(A7,C7),CONCATENATE(B7,C7)) -> CHAMP RESTO202401 | F7: 1 | G7: 79 | H7: 14 | I7: 1 | J7: 1 | K7: 60225 | L7: 18196685 | M7: 2543600 | N7: 23000 | O7: 180000 | P7: 90 | Q7: 170355 | R7: 50872 | S7: 161 | T7: 1260
A8: CHAMP RESTO | B8: GOKANA | C8: 202401 | D8: =MID(C8,1,4) -> 2024 | E8: =IF(Portfolio!$M$1=1,CONCATENATE(A8,C8),CONCATENATE(B8,C8)) -> CHAMP RESTO202401 | F8: 14 | G8: 167 | H8: 0 | I8: 0 | J8: 0 | K8: 2569997 | L8: 29616842 | M8: 0 | N8: 0 | O8: 0 | P8: 3855 | Q8: 296168 | R8: 0 | S8: 0 | T8: 0
A9: CHAMP RESTO | B9: MONSIEUR SPOON | C9: 202401 | D9: =MID(C9,1,4) -> 2024 | E9: =IF(Portfolio!$M$1=1,CONCATENATE(A9,C9),CONCATENATE(B9,C9)) -> CHAMP RESTO202401 | F9: 0 | G9: 4 | H9: 0 | I9: 0 | J9: 0 | K9: 0 | L9: 1717677 | M9: 0 | N9: 0 | O9: 0 | P9: 0 | Q9: 17177 | R9: 0 | S9: 0 | T9: 0
A10: CHAMP RESTO | B10: PLATINUM | C10: 202401 | D10: =MID(C10,1,4) -> 2024 | E10: =IF(Portfolio!$M$1=1,CONCATENATE(A10,C10),CONCATENATE(B10,C10)) -> CHAMP RESTO202401 | F10: 6 | G10: 3 | H10: 0 | I10: 0 | J10: 0 | K10: 3637000 | L10: 1834497 | M10: 0 | N10: 0 | O10: 0 | P10: 5456 | Q10: 18345 | R10: 0 | S10: 0 | T10: 0
A11: CHAMP RESTO | B11: RAACHA | C11: 202401 | D11: =MID(C11,1,4) -> 2024 | E11: =IF(Portfolio!$M$1=1,CONCATENATE(A11,C11),CONCATENATE(B11,C11)) -> CHAMP RESTO202401 | F11: 3 | G11: 4 | H11: 0 | I11: 0 | J11: 0 | K11: 1052000 | L11: 1004008 | M11: 0 | N11: 0 | O11: 0 | P11: 1578 | Q11: 10040 | R11: 0 | S11: 0 | T11: 0
A12: ES TELLER 77 | B12: ES TELLER 77 | C12: 202401 | D12: =MID(C12,1,4) -> 2024 | E12: =IF(Portfolio!$M$1=1,CONCATENATE(A12,C12),CONCATENATE(B12,C12)) -> ES TELLER 77202401 | F12: 89 | G12: 146 | H12: 1 | I12: 0 | J12: 0 | K12: 10858000 | L12: 19020700 | M12: 152000 | N12: 0 | O12: 0 | P12: 16287 | Q12: 190207 | R12: 2736 | S12: 0 | T12: 0
