Workbook

Sheet PerPM
I4: 1 | J4: =I4+1 -> 2 | K4: =J4+1 -> 3 | L4: =K4+1 -> 4 | M4: =L4+1 -> 5 | N4: =M4+1 -> 6 | O4: =N4+1 -> 7 | P4: =O4+1 -> 8 | Q4: =P4+1 -> 9 | ... BI4: =BH4+1 -> 53
B5: SEGMEN | C5: KET | D5: % | F5: Periode | G5: FY | H5: YTD | I5: Week-01 | J5: Week-02 | K5: Week-03 | L5: Week-04 | M5: Week-05 | N5: Week-06 | O5: Week-07 | P5: Week-08 | Q5: Week-09 | R5: Week-10 | S5: Week-11 | T5: Week-12 | U5: Week-13 | V5: Week-14 | W5: Week-15 | X5: Week-16 | Y5: Week-17 | Z5: Week-18 | AA5: Week-19 | AB5: Week-20 | AC5: Week-21 | AD5: Week-22 | AE5: Week-23 | AF5: Week-24 | AG5: Week-25 | AH5: Week-26 | AI5: Week-27 | AJ5: Week-28 | AK5: Week-29 | AL5: Week-30 | AM5: Week-31 | AN5: Week-32 | AO5: Week-33 | AP5: Week-34 | AQ5: Week-35 | AR5: Week-36 | AS5: Week-37 | AT5: Week-38 | AU5: Week-39 | AV5: Week-40 | AW5: Week-41 | AX5: Week-42 | AY5: Week-43 | AZ5: Week-44 | BA5: Week-45 | BB5: Week-46 | BC5: Week-47 | BD5: Week-48 | BE5: Week-49 | BF5: Week-50 | BG5: Week-51 | BH5: Week-52 | BI5: Week-53
I6: 46028 | J6: =I6+7 -> 46035 | K6: =J6+7 -> 46042 | L6: =K6+7 -> 46049 | M6: =L6+7 -> 46056 | N6: =M6+7 -> 46063 | O6: =N6+7 -> 46070 | P6: =O6+7 -> 46077 | Q6: =P6+7 -> 46084 | ... BH6: =BG6+7 -> 46385 | BI6: =BH6+1 -> 46386
B7: ANCHOR | C7: Ach (%) | D7: =H8/H7 -> 6425.2462 | E7: =IF(D7>300%,300%,D7) -> 3 | F7: Target | G7: =G14+G18+G22 -> 1594897 | H7: =H14+H18+H22 -> 111782.16 | I7: =IFERROR(I14+I18+I22,"") -> 12565.57 | J7: =IFERROR(J14+J18+J22,"") -> 11161.751 | K7: =IFERROR(K14+K18+K22,"") -> 10817.907 | L7: =IFERROR(L14+L18+L22,"") -> 13151.848 | M7: =IFERROR(M14+M18+M22,"") -> 12482.394 | N7: =IFERROR(N14+N18+N22,"") -> 11512.271 | O7: =IFERROR(O14+O18+O22,"") -> 11017.893 | P7: =IFERROR(P14+P18+P22,"") -> 13030.258 | ... BI7: =IFERROR(BI14+BI18+BI22,"")
B8: =B7 -> ANCHOR | C8: YoY (%) | D8: =H8/H9-1 -> 5034.2567 | E8: =IF(D8>300%,300%,D8) -> 3 | F8: 2026 | G8: =G15+G19+G23 -> 7.1838571e+08 | H8: =H15+H19+H23 -> 7.182279e+08 | I8: =IFERROR(I15+I19+I23,"") -> 806.89733 | J8: =IFERROR(J15+J19+J23,"") -> 565.13659 | K8: =IFERROR(K15+K19+K23,"") -> 398.58689 | L8: =IFERROR(L15+L19+L23,"") -> 656.23401 | M8: =IFERROR(M15+M19+M23,"") -> 834.78412 | N8: =IFERROR(N15+N19+N23,"") -> 836.75157 | O8: =IFERROR(O15+O19+O23,"") -> 678.54053 | P8: =IFERROR(P15+P19+P23,"") -> 759.0356 | ... BI8: =IFERROR(BI15+BI19+BI23,"")
C9: YoY (%) | D9: =H9/H10-1 -> -0.25869721 | E9: =IF(D9>300%,300%,D9) -> -0.25869721 | F9: 2025 | G9: =G16+G20+G24 -> 871113.49 | H9: =H16+H20+H24 -> 142639.78 | I9: =IFERROR(I16+I20+I24,"") -> 10868.838 | J9: =IFERROR(J16+J20+J24,"") -> 9449.8979 | K9: =IFERROR(K16+K20+K24,"") -> 9389.5657 | L9: =IFERROR(L16+L20+L24,"") -> 11328.81 | M9: =IFERROR(M16+M20+M24,"") -> 10509.281 | N9: =IFERROR(N16+N20+N24,"") -> 9594.0448 | O9: =IFERROR(O16+O20+O24,"") -> 9485.8721 | P9: =IFERROR(P16+P20+P24,"") -> 13105.251 | ... BI9: =IFERROR(BI16+BI20+BI24,"")
B10: =B7 -> ANCHOR | F10: =F9-1 -> 2024 | G10: =G17+G21+G25 -> 745707.97 | H10: =H17+H21+H25 -> 192417.7 | I10: =IFERROR(I17+I21+I25,"") -> 16620.323 | J10: =IFERROR(J17+J21+J25,"") -> 15966.218 | K10: =IFERROR(K17+K21+K25,"") -> 15658.988 | L10: =IFERROR(L17+L21+L25,"") -> 16730.294 | M10: =IFERROR(M17+M21+M25,"") -> 17605.817 | N10: =IFERROR(N17+N21+N25,"") -> 19334.424 | O10: =IFERROR(O17+O21+O25,"") -> 14109.222 | P10: =IFERROR(P17+P21+P25,"") -> 14732.828 | ... BI10: =IFERROR(BI17+BI21+BI25,"")
B12: PM | C12: KET | D12: % | F12: Periode | G12: FY | H12: YTD | I12: =I5 -> Week-01 | J12: =J5 -> Week-02 | K12: =K5 -> Week-03 | L12: =L5 -> Week-04 | M12: =M5 -> Week-05 | N12: =N5 -> Week-06 | O12: =O5 -> Week-07 | P12: =P5 -> Week-08 | ... BI12: =BI5 -> Week-53
I13: 46028 | J13: =I13+7 -> 46035 | K13: =J13+7 -> 46042 | L13: =K13+7 -> 46049 | M13: =L13+7 -> 46056 | N13: =M13+7 -> 46063 | O13: =N13+7 -> 46070 | P13: =O13+7 -> 46077 | Q13: =P13+7 -> 46084 | ... BH13: =BG13+7 -> 46385 | BI13: =BH13+1 -> 46386
A14: =CONCATENATE(B14,PARAMETER!T$2) -> ADISTIVOL | B14: =PARAMETER!H2 -> ADISTI | C14: Ach (%) | D14: =H15/H14 -> 8216.7503 | E14: =IF(D14>300%,300%,D14) -> 3 | F14: =F7 -> Target | G14: =SUMIF('2026 T'!$E:$E,PerPM!$A14,'2026 T'!G:G)/PARAMETER!$T$3 -> 776510 | H14: =SUMIF('2026 T'!$E:$E,PerPM!$A14,'2026 T'!H:H)/PARAMETER!$T$3 -> 44517.257 | I14: =IF(I$4<=PARAMETER!$X$2,SUMIF('2026 T'!$E:$E,PerPM!$A14,'2026 T'!I:I)/PARAMETER!$T$3,"") -> 5155.1766 | J14: =IF(J$4<=PARAMETER!$X$2,SUMIF('2026 T'!$E:$E,PerPM!$A14,'2026 T'!J:J)/PARAMETER!$T$3,"") -> 4471.8912 | K14: =IF(K$4<=PARAMETER!$X$2,SUMIF('2026 T'!$E:$E,PerPM!$A14,'2026 T'!K:K)/PARAMETER!$T$3,"") -> 4426.3866 | L14: =IF(L$4<=PARAMETER!$X$2,SUMIF('2026 T'!$E:$E,PerPM!$A14,'2026 T'!L:L)/PARAMETER!$T$3,"") -> 5514.4079 | M14: =IF(M$4<=PARAMETER!$X$2,SUMIF('2026 T'!$E:$E,PerPM!$A14,'2026 T'!M:M)/PARAMETER!$T$3,"") -> 4968.4099 | N14: =IF(N$4<=PARAMETER!$X$2,SUMIF('2026 T'!$E:$E,PerPM!$A14,'2026 T'!N:N)/PARAMETER!$T$3,"") -> 4811.1881 | O14: =IF(O$4<=PARAMETER!$X$2,SUMIF('2026 T'!$E:$E,PerPM!$A14,'2026 T'!O:O)/PARAMETER!$T$3,"") -> 4791.6511 | P14: =IF(P$4<=PARAMETER!$X$2,SUMIF('2026 T'!$E:$E,PerPM!$A14,'2026 T'!P:P)/PARAMETER!$T$3,"") -> 4897.334 | Q14: =IF(Q$4<=PARAMETER!$X$2,SUMIF('2026 T'!$E:$E,PerPM!$A14,'2026 T'!Q:Q)/PARAMETER!$T$3,"") -> 5480.8115 | R14: =IF(R$4<=PARAMETER!$X$2,SUMIF('2026 T'!$E:$E,PerPM!$A14,'2026 T'!R:R)/PARAMETER!$T$3,"") -> 5042.8209 | S14: =IF(S$4<=PARAMETER!$X$2,SUMIF('2026 T'!$E:$E,PerPM!$A14,'2026 T'!S:S)/PARAMETER!$T$3,"") -> 5797.8882 | T14: =IF(T$4<=PARAMETER!$X$2,SUMIF('2026 T'!$E:$E,PerPM!$A14,'2026 T'!T:T)/PARAMETER!$T$3,"") -> 6255.1224 | U14: =IF(U$4<=PARAMETER!$X$2,SUMIF('2026 T'!$E:$E,PerPM!$A14,'2026 T'!U:U)/PARAMETER!$T$3,"") | V14: =IF(V$4<=PARAMETER!$X$2,SUMIF('2026 T'!$E:$E,PerPM!$A14,'2026 T'!V:V)/PARAMETER!$T$3,"") | W14: =IF(W$4<=PARAMETER!$X$2,SUMIF('2026 T'!$E:$E,PerPM!$A14,'2026 T'!W:W)/PARAMETER!$T$3,"") | X14: =IF(X$4<=PARAMETER!$X$2,SUMIF('2026 T'!$E:$E,PerPM!$A14,'2026 T'!X:X)/PARAMETER!$T$3,"") | Y14: =IF(Y$4<=PARAMETER!$X$2,SUMIF('2026 T'!$E:$E,PerPM!$A14,'2026 T'!Y:Y)/PARAMETER!$T$3,"") | Z14: =IF(Z$4<=PARAMETER!$X$2,SUMIF('2026 T'!$E:$E,PerPM!$A14,'2026 T'!Z:Z)/PARAMETER!$T$3,"") | AA14: =IF(AA$4<=PARAMETER!$X$2,SUMIF('2026 T'!$E:$E,PerPM!$A14,'2026 T'!AA:AA)/PARAMETER!$T$3,"") | AB14: =IF(AB$4<=PARAMETER!$X$2,SUMIF('2026 T'!$E:$E,PerPM!$A14,'2026 T'!AB:AB)/PARAMETER!$T$3,"") | AC14: =IF(AC$4<=PARAMETER!$X$2,SUMIF('2026 T'!$E:$E,PerPM!$A14,'2026 T'!AC:AC)/PARAMETER!$T$3,"") | AD14: =IF(AD$4<=PARAMETER!$X$2,SUMIF('2026 T'!$E:$E,PerPM!$A14,'2026 T'!AD:AD)/PARAMETER!$T$3,"") | AE14: =IF(AE$4<=PARAMETER!$X$2,SUMIF('2026 T'!$E:$E,PerPM!$A14,'2026 T'!AE:AE)/PARAMETER!$T$3,"") | AF14: =IF(AF$4<=PARAMETER!$X$2,SUMIF('2026 T'!$E:$E,PerPM!$A14,'2026 T'!AF:AF)/PARAMETER!$T$3,"") | AG14: =IF(AG$4<=PARAMETER!$X$2,SUMIF('2026 T'!$E:$E,PerPM!$A14,'2026 T'!AG:AG)/PARAMETER!$T$3,"") | AH14: =IF(AH$4<=PARAMETER!$X$2,SUMIF('2026 T'!$E:$E,PerPM!$A14,'2026 T'!AH:AH)/PARAMETER!$T$3,"") | AI14: =IF(AI$4<=PARAMETER!$X$2,SUMIF('2026 T'!$E:$E,PerPM!$A14,'2026 T'!AI:AI)/PARAMETER!$T$3,"") | AJ14: =IF(AJ$4<=PARAMETER!$X$2,SUMIF('2026 T'!$E:$E,PerPM!$A14,'2026 T'!AJ:AJ)/PARAMETER!$T$3,"") | AK14: =IF(AK$4<=PARAMETER!$X$2,SUMIF('2026 T'!$E:$E,PerPM!$A14,'2026 T'!AK:AK)/PARAMETER!$T$3,"") | AL14: =IF(AL$4<=PARAMETER!$X$2,SUMIF('2026 T'!$E:$E,PerPM!$A14,'2026 T'!AL:AL)/PARAMETER!$T$3,"") | AM14: =IF(AM$4<=PARAMETER!$X$2,SUMIF('2026 T'!$E:$E,PerPM!$A14,'2026 T'!AM:AM)/PARAMETER!$T$3,"") | AN14: =IF(AN$4<=PARAMETER!$X$2,SUMIF('2026 T'!$E:$E,PerPM!$A14,'2026 T'!AN:AN)/PARAMETER!$T$3,"") | AO14: =IF(AO$4<=PARAMETER!$X$2,SUMIF('2026 T'!$E:$E,PerPM!$A14,'2026 T'!AO:AO)/PARAMETER!$T$3,"") | AP14: =IF(AP$4<=PARAMETER!$X$2,SUMIF('2026 T'!$E:$E,PerPM!$A14,'2026 T'!AP:AP)/PARAMETER!$T$3,"") | AQ14: =IF(AQ$4<=PARAMETER!$X$2,SUMIF('2026 T'!$E:$E,PerPM!$A14,'2026 T'!AQ:AQ)/PARAMETER!$T$3,"") | AR14: =IF(AR$4<=PARAMETER!$X$2,SUMIF('2026 T'!$E:$E,PerPM!$A14,'2026 T'!AR:AR)/PARAMETER!$T$3,"") | AS14: =IF(AS$4<=PARAMETER!$X$2,SUMIF('2026 T'!$E:$E,PerPM!$A14,'2026 T'!AS:AS)/PARAMETER!$T$3,"") | AT14: =IF(AT$4<=PARAMETER!$X$2,SUMIF('2026 T'!$E:$E,PerPM!$A14,'2026 T'!AT:AT)/PARAMETER!$T$3,"") | AU14: =IF(AU$4<=PARAMETER!$X$2,SUMIF('2026 T'!$E:$E,PerPM!$A14,'2026 T'!AU:AU)/PARAMETER!$T$3,"") | AV14: =IF(AV$4<=PARAMETER!$X$2,SUMIF('2026 T'!$E:$E,PerPM!$A14,'2026 T'!AV:AV)/PARAMETER!$T$3,"") | AW14: =IF(AW$4<=PARAMETER!$X$2,SUMIF('2026 T'!$E:$E,PerPM!$A14,'2026 T'!AW:AW)/PARAMETER!$T$3,"") | AX14: =IF(AX$4<=PARAMETER!$X$2,SUMIF('2026 T'!$E:$E,PerPM!$A14,'2026 T'!AX:AX)/PARAMETER!$T$3,"") | AY14: =IF(AY$4<=PARAMETER!$X$2,SUMIF('2026 T'!$E:$E,PerPM!$A14,'2026 T'!AY:AY)/PARAMETER!$T$3,"") | AZ14: =IF(AZ$4<=PARAMETER!$X$2,SUMIF('2026 T'!$E:$E,PerPM!$A14,'2026 T'!AZ:AZ)/PARAMETER!$T$3,"") | BA14: =IF(BA$4<=PARAMETER!$X$2,SUMIF('2026 T'!$E:$E,PerPM!$A14,'2026 T'!BA:BA)/PARAMETER!$T$3,"") | BB14: =IF(BB$4<=PARAMETER!$X$2,SUMIF('2026 T'!$E:$E,PerPM!$A14,'2026 T'!BB:BB)/PARAMETER!$T$3,"") | BC14: =IF(BC$4<=PARAMETER!$X$2,SUMIF('2026 T'!$E:$E,PerPM!$A14,'2026 T'!BC:BC)/PARAMETER!$T$3,"") | BD14: =IF(BD$4<=PARAMETER!$X$2,SUMIF('2026 T'!$E:$E,PerPM!$A14,'2026 T'!BD:BD)/PARAMETER!$T$3,"") | BE14: =IF(BE$4<=PARAMETER!$X$2,SUMIF('2026 T'!$E:$E,PerPM!$A14,'2026 T'!BE:BE)/PARAMETER!$T$3,"") | BF14: =IF(BF$4<=PARAMETER!$X$2,SUMIF('2026 T'!$E:$E,PerPM!$A14,'2026 T'!BF:BF)/PARAMETER!$T$3,"") | BG14: =IF(BG$4<=PARAMETER!$X$2,SUMIF('2026 T'!$E:$E,PerPM!$A14,'2026 T'!BG:BG)/PARAMETER!$T$3,"") | BH14: =IF(BH$4<=PARAMETER!$X$2,SUMIF('2026 T'!$E:$E,PerPM!$A14,'2026 T'!BH:BH)/PARAMETER!$T$3,"") | BI14: =IF(BI$4<=PARAMETER!$X$2,SUMIF('2026 T'!$E:$E,PerPM!$A14,'2026 T'!BI:BI)/PARAMETER!$T$3,"")
A15: =CONCATENATE(B15,PARAMETER!T$2) -> ADISTIVOL | B15: =B14 -> ADISTI | C15: YoY (%) | D15: =H15/H16-1 -> 7084.6036 | E15: =IF(D15>300%,300%,D15) -> 3 | F15: =F8 -> 2026 | G15: =IF(G$4<=PARAMETER!$X$2,SUMIF('2026'!$E:$E,PerPM!$A14,'2026'!G:G)/PARAMETER!$T$3,"") -> 3.6584414e+08 | H15: =IF(H$4<=PARAMETER!$X$2,SUMIF('2026'!$E:$E,PerPM!$A14,'2026'!H:H)/PARAMETER!$T$3,"") -> 3.6578718e+08 | I15: =IF(I$4<=PARAMETER!$X$2,SUMIF('2026'!$E:$E,PerPM!$A14,'2026'!I:I)/PARAMETER!$T$3,"") -> 156.04983 | J15: =IF(J$4<=PARAMETER!$X$2,SUMIF('2026'!$E:$E,PerPM!$A14,'2026'!J:J)/PARAMETER!$T$3,"") -> 0 | K15: =IF(K$4<=PARAMETER!$X$2,SUMIF('2026'!$E:$E,PerPM!$A14,'2026'!K:K)/PARAMETER!$T$3,"") -> 0 | L15: =IF(L$4<=PARAMETER!$X$2,SUMIF('2026'!$E:$E,PerPM!$A14,'2026'!L:L)/PARAMETER!$T$3,"") -> 0 | M15: =IF(M$4<=PARAMETER!$X$2,SUMIF('2026'!$E:$E,PerPM!$A14,'2026'!M:M)/PARAMETER!$T$3,"") -> 167.56352 | N15: =IF(N$4<=PARAMETER!$X$2,SUMIF('2026'!$E:$E,PerPM!$A14,'2026'!N:N)/PARAMETER!$T$3,"") -> 147.79262 | O15: =IF(O$4<=PARAMETER!$X$2,SUMIF('2026'!$E:$E,PerPM!$A14,'2026'!O:O)/PARAMETER!$T$3,"") -> 0 | P15: =IF(P$4<=PARAMETER!$X$2,SUMIF('2026'!$E:$E,PerPM!$A14,'2026'!P:P)/PARAMETER!$T$3,"") -> 128.04754 | Q15: =IF(Q$4<=PARAMETER!$X$2,SUMIF('2026'!$E:$E,PerPM!$A14,'2026'!Q:Q)/PARAMETER!$T$3,"") -> 2.5654408e+08 | R15: =IF(R$4<=PARAMETER!$X$2,SUMIF('2026'!$E:$E,PerPM!$A14,'2026'!R:R)/PARAMETER!$T$3,"") -> 57398984 | S15: =IF(S$4<=PARAMETER!$X$2,SUMIF('2026'!$E:$E,PerPM!$A14,'2026'!S:S)/PARAMETER!$T$3,"") -> 51843370 | T15: =IF(T$4<=PARAMETER!$X$2,SUMIF('2026'!$E:$E,PerPM!$A14,'2026'!T:T)/PARAMETER!$T$3,"") -> 149.79984 | U15: =IF(U$4<=PARAMETER!$X$2,SUMIF('2026'!$E:$E,PerPM!$A14,'2026'!U:U)/PARAMETER!$T$3,"") | V15: =IF(V$4<=PARAMETER!$X$2,SUMIF('2026'!$E:$E,PerPM!$A14,'2026'!V:V)/PARAMETER!$T$3,"") | W15: =IF(W$4<=PARAMETER!$X$2,SUMIF('2026'!$E:$E,PerPM!$A14,'2026'!W:W)/PARAMETER!$T$3,"") | X15: =IF(X$4<=PARAMETER!$X$2,SUMIF('2026'!$E:$E,PerPM!$A14,'2026'!X:X)/PARAMETER!$T$3,"") | Y15: =IF(Y$4<=PARAMETER!$X$2,SUMIF('2026'!$E:$E,PerPM!$A14,'2026'!Y:Y)/PARAMETER!$T$3,"") | Z15: =IF(Z$4<=PARAMETER!$X$2,SUMIF('2026'!$E:$E,PerPM!$A14,'2026'!Z:Z)/PARAMETER!$T$3,"") | AA15: =IF(AA$4<=PARAMETER!$X$2,SUMIF('2026'!$E:$E,PerPM!$A14,'2026'!AA:AA)/PARAMETER!$T$3,"") | AB15: =IF(AB$4<=PARAMETER!$X$2,SUMIF('2026'!$E:$E,PerPM!$A14,'2026'!AB:AB)/PARAMETER!$T$3,"") | AC15: =IF(AC$4<=PARAMETER!$X$2,SUMIF('2026'!$E:$E,PerPM!$A14,'2026'!AC:AC)/PARAMETER!$T$3,"") | AD15: =IF(AD$4<=PARAMETER!$X$2,SUMIF('2026'!$E:$E,PerPM!$A14,'2026'!AD:AD)/PARAMETER!$T$3,"") | AE15: =IF(AE$4<=PARAMETER!$X$2,SUMIF('2026'!$E:$E,PerPM!$A14,'2026'!AE:AE)/PARAMETER!$T$3,"") | AF15: =IF(AF$4<=PARAMETER!$X$2,SUMIF('2026'!$E:$E,PerPM!$A14,'2026'!AF:AF)/PARAMETER!$T$3,"") | AG15: =IF(AG$4<=PARAMETER!$X$2,SUMIF('2026'!$E:$E,PerPM!$A14,'2026'!AG:AG)/PARAMETER!$T$3,"") | AH15: =IF(AH$4<=PARAMETER!$X$2,SUMIF('2026'!$E:$E,PerPM!$A14,'2026'!AH:AH)/PARAMETER!$T$3,"") | AI15: =IF(AI$4<=PARAMETER!$X$2,SUMIF('2026'!$E:$E,PerPM!$A14,'2026'!AI:AI)/PARAMETER!$T$3,"") | AJ15: =IF(AJ$4<=PARAMETER!$X$2,SUMIF('2026'!$E:$E,PerPM!$A14,'2026'!AJ:AJ)/PARAMETER!$T$3,"") | AK15: =IF(AK$4<=PARAMETER!$X$2,SUMIF('2026'!$E:$E,PerPM!$A14,'2026'!AK:AK)/PARAMETER!$T$3,"") | AL15: =IF(AL$4<=PARAMETER!$X$2,SUMIF('2026'!$E:$E,PerPM!$A14,'2026'!AL:AL)/PARAMETER!$T$3,"") | AM15: =IF(AM$4<=PARAMETER!$X$2,SUMIF('2026'!$E:$E,PerPM!$A14,'2026'!AM:AM)/PARAMETER!$T$3,"") | AN15: =IF(AN$4<=PARAMETER!$X$2,SUMIF('2026'!$E:$E,PerPM!$A14,'2026'!AN:AN)/PARAMETER!$T$3,"") | AO15: =IF(AO$4<=PARAMETER!$X$2,SUMIF('2026'!$E:$E,PerPM!$A14,'2026'!AO:AO)/PARAMETER!$T$3,"") | AP15: =IF(AP$4<=PARAMETER!$X$2,SUMIF('2026'!$E:$E,PerPM!$A14,'2026'!AP:AP)/PARAMETER!$T$3,"") | AQ15: =IF(AQ$4<=PARAMETER!$X$2,SUMIF('2026'!$E:$E,PerPM!$A14,'2026'!AQ:AQ)/PARAMETER!$T$3,"") | AR15: =IF(AR$4<=PARAMETER!$X$2,SUMIF('2026'!$E:$E,PerPM!$A14,'2026'!AR:AR)/PARAMETER!$T$3,"") | AS15: =IF(AS$4<=PARAMETER!$X$2,SUMIF('2026'!$E:$E,PerPM!$A14,'2026'!AS:AS)/PARAMETER!$T$3,"") | AT15: =IF(AT$4<=PARAMETER!$X$2,SUMIF('2026'!$E:$E,PerPM!$A14,'2026'!AT:AT)/PARAMETER!$T$3,"") | AU15: =IF(AU$4<=PARAMETER!$X$2,SUMIF('2026'!$E:$E,PerPM!$A14,'2026'!AU:AU)/PARAMETER!$T$3,"") | AV15: =IF(AV$4<=PARAMETER!$X$2,SUMIF('2026'!$E:$E,PerPM!$A14,'2026'!AV:AV)/PARAMETER!$T$3,"") | AW15: =IF(AW$4<=PARAMETER!$X$2,SUMIF('2026'!$E:$E,PerPM!$A14,'2026'!AW:AW)/PARAMETER!$T$3,"") | AX15: =IF(AX$4<=PARAMETER!$X$2,SUMIF('2026'!$E:$E,PerPM!$A14,'2026'!AX:AX)/PARAMETER!$T$3,"") | AY15: =IF(AY$4<=PARAMETER!$X$2,SUMIF('2026'!$E:$E,PerPM!$A14,'2026'!AY:AY)/PARAMETER!$T$3,"") | AZ15: =IF(AZ$4<=PARAMETER!$X$2,SUMIF('2026'!$E:$E,PerPM!$A14,'2026'!AZ:AZ)/PARAMETER!$T$3,"") | BA15: =IF(BA$4<=PARAMETER!$X$2,SUMIF('2026'!$E:$E,PerPM!$A14,'2026'!BA:BA)/PARAMETER!$T$3,"") | BB15: =IF(BB$4<=PARAMETER!$X$2,SUMIF('2026'!$E:$E,PerPM!$A14,'2026'!BB:BB)/PARAMETER!$T$3,"") | BC15: =IF(BC$4<=PARAMETER!$X$2,SUMIF('2026'!$E:$E,PerPM!$A14,'2026'!BC:BC)/PARAMETER!$T$3,"") | BD15: =IF(BD$4<=PARAMETER!$X$2,SUMIF('2026'!$E:$E,PerPM!$A14,'2026'!BD:BD)/PARAMETER!$T$3,"") | BE15: =IF(BE$4<=PARAMETER!$X$2,SUMIF('2026'!$E:$E,PerPM!$A14,'2026'!BE:BE)/PARAMETER!$T$3,"") | BF15: =IF(BF$4<=PARAMETER!$X$2,SUMIF('2026'!$E:$E,PerPM!$A14,'2026'!BF:BF)/PARAMETER!$T$3,"") | BG15: =IF(BG$4<=PARAMETER!$X$2,SUMIF('2026'!$E:$E,PerPM!$A14,'2026'!BG:BG)/PARAMETER!$T$3,"") | BH15: =IF(BH$4<=PARAMETER!$X$2,SUMIF('2026'!$E:$E,PerPM!$A14,'2026'!BH:BH)/PARAMETER!$T$3,"") | BI15: =IF(BI$4<=PARAMETER!$X$2,SUMIF('2026'!$E:$E,PerPM!$A14,'2026'!BI:BI)/PARAMETER!$T$3,"")
A16: =CONCATENATE(B16,PARAMETER!T$2) -> ADISTIVOL | B16: =B15 -> ADISTI | C16: YoY (%) | D16: =H16/H17-1 -> 0.050684665 | E16: =IF(D16>300%,300%,D16) -> 0.050684665 | F16: =F9 -> 2025 | G16: =IF(G$4<=PARAMETER!$X$2,SUMIF('2025'!$E:$E,PerPM!$A15,'2025'!G:G)/PARAMETER!$T$3,"") -> 425356.2 | H16: =IF(H$4<=PARAMETER!$X$2,SUMIF('2025'!$E:$E,PerPM!$A15,'2025'!H:H)/PARAMETER!$T$3,"") -> 51623.998 | I16: =IF(I$4<=PARAMETER!$X$2,SUMIF('2025'!$E:$E,PerPM!$A15,'2025'!I:I)/PARAMETER!$T$3,"") -> 4339.5899 | J16: =IF(J$4<=PARAMETER!$X$2,SUMIF('2025'!$E:$E,PerPM!$A15,'2025'!J:J)/PARAMETER!$T$3,"") -> 3721.4221 | K16: =IF(K$4<=PARAMETER!$X$2,SUMIF('2025'!$E:$E,PerPM!$A15,'2025'!K:K)/PARAMETER!$T$3,"") -> 3708.9509 | L16: =IF(L$4<=PARAMETER!$X$2,SUMIF('2025'!$E:$E,PerPM!$A15,'2025'!L:L)/PARAMETER!$T$3,"") -> 4593.2381 | M16: =IF(M$4<=PARAMETER!$X$2,SUMIF('2025'!$E:$E,PerPM!$A15,'2025'!M:M)/PARAMETER!$T$3,"") -> 4159.0775 | N16: =IF(N$4<=PARAMETER!$X$2,SUMIF('2025'!$E:$E,PerPM!$A15,'2025'!N:N)/PARAMETER!$T$3,"") -> 3970.6468 | O16: =IF(O$4<=PARAMETER!$X$2,SUMIF('2025'!$E:$E,PerPM!$A15,'2025'!O:O)/PARAMETER!$T$3,"") -> 4025.1105 | P16: =IF(P$4<=PARAMETER!$X$2,SUMIF('2025'!$E:$E,PerPM!$A15,'2025'!P:P)/PARAMETER!$T$3,"") -> 4137.5195 | Q16: =IF(Q$4<=PARAMETER!$X$2,SUMIF('2025'!$E:$E,PerPM!$A15,'2025'!Q:Q)/PARAMETER!$T$3,"") -> 4681.143 | R16: =IF(R$4<=PARAMETER!$X$2,SUMIF('2025'!$E:$E,PerPM!$A15,'2025'!R:R)/PARAMETER!$T$3,"") -> 4218.9789 | S16: =IF(S$4<=PARAMETER!$X$2,SUMIF('2025'!$E:$E,PerPM!$A15,'2025'!S:S)/PARAMETER!$T$3,"") -> 4818.8779 | T16: =IF(T$4<=PARAMETER!$X$2,SUMIF('2025'!$E:$E,PerPM!$A15,'2025'!T:T)/PARAMETER!$T$3,"") -> 5249.4428 | U16: =IF(U$4<=PARAMETER!$X$2,SUMIF('2025'!$E:$E,PerPM!$A15,'2025'!U:U)/PARAMETER!$T$3,"") | V16: =IF(V$4<=PARAMETER!$X$2,SUMIF('2025'!$E:$E,PerPM!$A15,'2025'!V:V)/PARAMETER!$T$3,"") | W16: =IF(W$4<=PARAMETER!$X$2,SUMIF('2025'!$E:$E,PerPM!$A15,'2025'!W:W)/PARAMETER!$T$3,"") | X16: =IF(X$4<=PARAMETER!$X$2,SUMIF('2025'!$E:$E,PerPM!$A15,'2025'!X:X)/PARAMETER!$T$3,"") | Y16: =IF(Y$4<=PARAMETER!$X$2,SUMIF('2025'!$E:$E,PerPM!$A15,'2025'!Y:Y)/PARAMETER!$T$3,"") | Z16: =IF(Z$4<=PARAMETER!$X$2,SUMIF('2025'!$E:$E,PerPM!$A15,'2025'!Z:Z)/PARAMETER!$T$3,"") | AA16: =IF(AA$4<=PARAMETER!$X$2,SUMIF('2025'!$E:$E,PerPM!$A15,'2025'!AA:AA)/PARAMETER!$T$3,"") | AB16: =IF(AB$4<=PARAMETER!$X$2,SUMIF('2025'!$E:$E,PerPM!$A15,'2025'!AB:AB)/PARAMETER!$T$3,"") | AC16: =IF(AC$4<=PARAMETER!$X$2,SUMIF('2025'!$E:$E,PerPM!$A15,'2025'!AC:AC)/PARAMETER!$T$3,"") | AD16: =IF(AD$4<=PARAMETER!$X$2,SUMIF('2025'!$E:$E,PerPM!$A15,'2025'!AD:AD)/PARAMETER!$T$3,"") | AE16: =IF(AE$4<=PARAMETER!$X$2,SUMIF('2025'!$E:$E,PerPM!$A15,'2025'!AE:AE)/PARAMETER!$T$3,"") | AF16: =IF(AF$4<=PARAMETER!$X$2,SUMIF('2025'!$E:$E,PerPM!$A15,'2025'!AF:AF)/PARAMETER!$T$3,"") | AG16: =IF(AG$4<=PARAMETER!$X$2,SUMIF('2025'!$E:$E,PerPM!$A15,'2025'!AG:AG)/PARAMETER!$T$3,"") | AH16: =IF(AH$4<=PARAMETER!$X$2,SUMIF('2025'!$E:$E,PerPM!$A15,'2025'!AH:AH)/PARAMETER!$T$3,"") | AI16: =IF(AI$4<=PARAMETER!$X$2,SUMIF('2025'!$E:$E,PerPM!$A15,'2025'!AI:AI)/PARAMETER!$T$3,"") | AJ16: =IF(AJ$4<=PARAMETER!$X$2,SUMIF('2025'!$E:$E,PerPM!$A15,'2025'!AJ:AJ)/PARAMETER!$T$3,"") | AK16: =IF(AK$4<=PARAMETER!$X$2,SUMIF('2025'!$E:$E,PerPM!$A15,'2025'!AK:AK)/PARAMETER!$T$3,"") | AL16: =IF(AL$4<=PARAMETER!$X$2,SUMIF('2025'!$E:$E,PerPM!$A15,'2025'!AL:AL)/PARAMETER!$T$3,"") | AM16: =IF(AM$4<=PARAMETER!$X$2,SUMIF('2025'!$E:$E,PerPM!$A15,'2025'!AM:AM)/PARAMETER!$T$3,"") | AN16: =IF(AN$4<=PARAMETER!$X$2,SUMIF('2025'!$E:$E,PerPM!$A15,'2025'!AN:AN)/PARAMETER!$T$3,"") | AO16: =IF(AO$4<=PARAMETER!$X$2,SUMIF('2025'!$E:$E,PerPM!$A15,'2025'!AO:AO)/PARAMETER!$T$3,"") | AP16: =IF(AP$4<=PARAMETER!$X$2,SUMIF('2025'!$E:$E,PerPM!$A15,'2025'!AP:AP)/PARAMETER!$T$3,"") | AQ16: =IF(AQ$4<=PARAMETER!$X$2,SUMIF('2025'!$E:$E,PerPM!$A15,'2025'!AQ:AQ)/PARAMETER!$T$3,"") | AR16: =IF(AR$4<=PARAMETER!$X$2,SUMIF('2025'!$E:$E,PerPM!$A15,'2025'!AR:AR)/PARAMETER!$T$3,"") | AS16: =IF(AS$4<=PARAMETER!$X$2,SUMIF('2025'!$E:$E,PerPM!$A15,'2025'!AS:AS)/PARAMETER!$T$3,"") | AT16: =IF(AT$4<=PARAMETER!$X$2,SUMIF('2025'!$E:$E,PerPM!$A15,'2025'!AT:AT)/PARAMETER!$T$3,"") | AU16: =IF(AU$4<=PARAMETER!$X$2,SUMIF('2025'!$E:$E,PerPM!$A15,'2025'!AU:AU)/PARAMETER!$T$3,"") | AV16: =IF(AV$4<=PARAMETER!$X$2,SUMIF('2025'!$E:$E,PerPM!$A15,'2025'!AV:AV)/PARAMETER!$T$3,"") | AW16: =IF(AW$4<=PARAMETER!$X$2,SUMIF('2025'!$E:$E,PerPM!$A15,'2025'!AW:AW)/PARAMETER!$T$3,"") | AX16: =IF(AX$4<=PARAMETER!$X$2,SUMIF('2025'!$E:$E,PerPM!$A15,'2025'!AX:AX)/PARAMETER!$T$3,"") | AY16: =IF(AY$4<=PARAMETER!$X$2,SUMIF('2025'!$E:$E,PerPM!$A15,'2025'!AY:AY)/PARAMETER!$T$3,"") | AZ16: =IF(AZ$4<=PARAMETER!$X$2,SUMIF('2025'!$E:$E,PerPM!$A15,'2025'!AZ:AZ)/PARAMETER!$T$3,"") | BA16: =IF(BA$4<=PARAMETER!$X$2,SUMIF('2025'!$E:$E,PerPM!$A15,'2025'!BA:BA)/PARAMETER!$T$3,"") | BB16: =IF(BB$4<=PARAMETER!$X$2,SUMIF('2025'!$E:$E,PerPM!$A15,'2025'!BB:BB)/PARAMETER!$T$3,"") | BC16: =IF(BC$4<=PARAMETER!$X$2,SUMIF('2025'!$E:$E,PerPM!$A15,'2025'!BC:BC)/PARAMETER!$T$3,"") | BD16: =IF(BD$4<=PARAMETER!$X$2,SUMIF('2025'!$E:$E,PerPM!$A15,'2025'!BD:BD)/PARAMETER!$T$3,"") | BE16: =IF(BE$4<=PARAMETER!$X$2,SUMIF('2025'!$E:$E,PerPM!$A15,'2025'!BE:BE)/PARAMETER!$T$3,"") | BF16: =IF(BF$4<=PARAMETER!$X$2,SUMIF('2025'!$E:$E,PerPM!$A15,'2025'!BF:BF)/PARAMETER!$T$3,"") | BG16: =IF(BG$4<=PARAMETER!$X$2,SUMIF('2025'!$E:$E,PerPM!$A15,'2025'!BG:BG)/PARAMETER!$T$3,"") | BH16: =IF(BH$4<=PARAMETER!$X$2,SUMIF('2025'!$E:$E,PerPM!$A15,'2025'!BH:BH)/PARAMETER!$T$3,"") | BI16: =IF(BI$4<=PARAMETER!$X$2,SUMIF('2025'!$E:$E,PerPM!$A15,'2025'!BI:BI)/PARAMETER!$T$3,"")
A17: =CONCATENATE(B17,PARAMETER!T$2) -> ADISTIVOL | B17: =B15 -> ADISTI | F17: =F10 -> 2024 | G17: =IF(G$4<=PARAMETER!$X$2,SUMIF('2024'!$E:$E,PerPM!$A14,'2024'!G:G)/PARAMETER!$T$3,"") -> 220838.95 | H17: =IF(H$4<=PARAMETER!$X$2,SUMIF('2024'!$E:$E,PerPM!$A14,'2024'!H:H)/PARAMETER!$T$3,"") -> 49133.674 | I17: =IF(I$4<=PARAMETER!$X$2,SUMIF('2024'!$E:$E,PerPM!$A14,'2024'!I:I)/PARAMETER!$T$3,"") -> 3774.5459 | J17: =IF(J$4<=PARAMETER!$X$2,SUMIF('2024'!$E:$E,PerPM!$A14,'2024'!J:J)/PARAMETER!$T$3,"") -> 3695.4699 | K17: =IF(K$4<=PARAMETER!$X$2,SUMIF('2024'!$E:$E,PerPM!$A14,'2024'!K:K)/PARAMETER!$T$3,"") -> 3293.9511 | L17: =IF(L$4<=PARAMETER!$X$2,SUMIF('2024'!$E:$E,PerPM!$A14,'2024'!L:L)/PARAMETER!$T$3,"") -> 3730.9688 | M17: =IF(M$4<=PARAMETER!$X$2,SUMIF('2024'!$E:$E,PerPM!$A14,'2024'!M:M)/PARAMETER!$T$3,"") -> 3750.0534 | N17: =IF(N$4<=PARAMETER!$X$2,SUMIF('2024'!$E:$E,PerPM!$A14,'2024'!N:N)/PARAMETER!$T$3,"") -> 6342.4502 | O17: =IF(O$4<=PARAMETER!$X$2,SUMIF('2024'!$E:$E,PerPM!$A14,'2024'!O:O)/PARAMETER!$T$3,"") -> 3818.9531 | P17: =IF(P$4<=PARAMETER!$X$2,SUMIF('2024'!$E:$E,PerPM!$A14,'2024'!P:P)/PARAMETER!$T$3,"") -> 3893.1397 | Q17: =IF(Q$4<=PARAMETER!$X$2,SUMIF('2024'!$E:$E,PerPM!$A14,'2024'!Q:Q)/PARAMETER!$T$3,"") -> 4204.3022 | R17: =IF(R$4<=PARAMETER!$X$2,SUMIF('2024'!$E:$E,PerPM!$A14,'2024'!R:R)/PARAMETER!$T$3,"") -> 4357.7652 | S17: =IF(S$4<=PARAMETER!$X$2,SUMIF('2024'!$E:$E,PerPM!$A14,'2024'!S:S)/PARAMETER!$T$3,"") -> 4062.9411 | T17: =IF(T$4<=PARAMETER!$X$2,SUMIF('2024'!$E:$E,PerPM!$A14,'2024'!T:T)/PARAMETER!$T$3,"") -> 4209.1334 | U17: =IF(U$4<=PARAMETER!$X$2,SUMIF('2024'!$E:$E,PerPM!$A14,'2024'!U:U)/PARAMETER!$T$3,"") | V17: =IF(V$4<=PARAMETER!$X$2,SUMIF('2024'!$E:$E,PerPM!$A14,'2024'!V:V)/PARAMETER!$T$3,"") | W17: =IF(W$4<=PARAMETER!$X$2,SUMIF('2024'!$E:$E,PerPM!$A14,'2024'!W:W)/PARAMETER!$T$3,"") | X17: =IF(X$4<=PARAMETER!$X$2,SUMIF('2024'!$E:$E,PerPM!$A14,'2024'!X:X)/PARAMETER!$T$3,"") | Y17: =IF(Y$4<=PARAMETER!$X$2,SUMIF('2024'!$E:$E,PerPM!$A14,'2024'!Y:Y)/PARAMETER!$T$3,"") | Z17: =IF(Z$4<=PARAMETER!$X$2,SUMIF('2024'!$E:$E,PerPM!$A14,'2024'!Z:Z)/PARAMETER!$T$3,"") | AA17: =IF(AA$4<=PARAMETER!$X$2,SUMIF('2024'!$E:$E,PerPM!$A14,'2024'!AA:AA)/PARAMETER!$T$3,"") | AB17: =IF(AB$4<=PARAMETER!$X$2,SUMIF('2024'!$E:$E,PerPM!$A14,'2024'!AB:AB)/PARAMETER!$T$3,"") | AC17: =IF(AC$4<=PARAMETER!$X$2,SUMIF('2024'!$E:$E,PerPM!$A14,'2024'!AC:AC)/PARAMETER!$T$3,"") | AD17: =IF(AD$4<=PARAMETER!$X$2,SUMIF('2024'!$E:$E,PerPM!$A14,'2024'!AD:AD)/PARAMETER!$T$3,"") | AE17: =IF(AE$4<=PARAMETER!$X$2,SUMIF('2024'!$E:$E,PerPM!$A14,'2024'!AE:AE)/PARAMETER!$T$3,"") | AF17: =IF(AF$4<=PARAMETER!$X$2,SUMIF('2024'!$E:$E,PerPM!$A14,'2024'!AF:AF)/PARAMETER!$T$3,"") | AG17: =IF(AG$4<=PARAMETER!$X$2,SUMIF('2024'!$E:$E,PerPM!$A14,'2024'!AG:AG)/PARAMETER!$T$3,"") | AH17: =IF(AH$4<=PARAMETER!$X$2,SUMIF('2024'!$E:$E,PerPM!$A14,'2024'!AH:AH)/PARAMETER!$T$3,"") | AI17: =IF(AI$4<=PARAMETER!$X$2,SUMIF('2024'!$E:$E,PerPM!$A14,'2024'!AI:AI)/PARAMETER!$T$3,"") | AJ17: =IF(AJ$4<=PARAMETER!$X$2,SUMIF('2024'!$E:$E,PerPM!$A14,'2024'!AJ:AJ)/PARAMETER!$T$3,"") | AK17: =IF(AK$4<=PARAMETER!$X$2,SUMIF('2024'!$E:$E,PerPM!$A14,'2024'!AK:AK)/PARAMETER!$T$3,"") | AL17: =IF(AL$4<=PARAMETER!$X$2,SUMIF('2024'!$E:$E,PerPM!$A14,'2024'!AL:AL)/PARAMETER!$T$3,"") | AM17: =IF(AM$4<=PARAMETER!$X$2,SUMIF('2024'!$E:$E,PerPM!$A14,'2024'!AM:AM)/PARAMETER!$T$3,"") | AN17: =IF(AN$4<=PARAMETER!$X$2,SUMIF('2024'!$E:$E,PerPM!$A14,'2024'!AN:AN)/PARAMETER!$T$3,"") | AO17: =IF(AO$4<=PARAMETER!$X$2,SUMIF('2024'!$E:$E,PerPM!$A14,'2024'!AO:AO)/PARAMETER!$T$3,"") | AP17: =IF(AP$4<=PARAMETER!$X$2,SUMIF('2024'!$E:$E,PerPM!$A14,'2024'!AP:AP)/PARAMETER!$T$3,"") | AQ17: =IF(AQ$4<=PARAMETER!$X$2,SUMIF('2024'!$E:$E,PerPM!$A14,'2024'!AQ:AQ)/PARAMETER!$T$3,"") | AR17: =IF(AR$4<=PARAMETER!$X$2,SUMIF('2024'!$E:$E,PerPM!$A14,'2024'!AR:AR)/PARAMETER!$T$3,"") | AS17: =IF(AS$4<=PARAMETER!$X$2,SUMIF('2024'!$E:$E,PerPM!$A14,'2024'!AS:AS)/PARAMETER!$T$3,"") | AT17: =IF(AT$4<=PARAMETER!$X$2,SUMIF('2024'!$E:$E,PerPM!$A14,'2024'!AT:AT)/PARAMETER!$T$3,"") | AU17: =IF(AU$4<=PARAMETER!$X$2,SUMIF('2024'!$E:$E,PerPM!$A14,'2024'!AU:AU)/PARAMETER!$T$3,"") | AV17: =IF(AV$4<=PARAMETER!$X$2,SUMIF('2024'!$E:$E,PerPM!$A14,'2024'!AV:AV)/PARAMETER!$T$3,"") | AW17: =IF(AW$4<=PARAMETER!$X$2,SUMIF('2024'!$E:$E,PerPM!$A14,'2024'!AW:AW)/PARAMETER!$T$3,"") | AX17: =IF(AX$4<=PARAMETER!$X$2,SUMIF('2024'!$E:$E,PerPM!$A14,'2024'!AX:AX)/PARAMETER!$T$3,"") | AY17: =IF(AY$4<=PARAMETER!$X$2,SUMIF('2024'!$E:$E,PerPM!$A14,'2024'!AY:AY)/PARAMETER!$T$3,"") | AZ17: =IF(AZ$4<=PARAMETER!$X$2,SUMIF('2024'!$E:$E,PerPM!$A14,'2024'!AZ:AZ)/PARAMETER!$T$3,"") | BA17: =IF(BA$4<=PARAMETER!$X$2,SUMIF('2024'!$E:$E,PerPM!$A14,'2024'!BA:BA)/PARAMETER!$T$3,"") | BB17: =IF(BB$4<=PARAMETER!$X$2,SUMIF('2024'!$E:$E,PerPM!$A14,'2024'!BB:BB)/PARAMETER!$T$3,"") | BC17: =IF(BC$4<=PARAMETER!$X$2,SUMIF('2024'!$E:$E,PerPM!$A14,'2024'!BC:BC)/PARAMETER!$T$3,"") | BD17: =IF(BD$4<=PARAMETER!$X$2,SUMIF('2024'!$E:$E,PerPM!$A14,'2024'!BD:BD)/PARAMETER!$T$3,"") | BE17: =IF(BE$4<=PARAMETER!$X$2,SUMIF('2024'!$E:$E,PerPM!$A14,'2024'!BE:BE)/PARAMETER!$T$3,"") | BF17: =IF(BF$4<=PARAMETER!$X$2,SUMIF('2024'!$E:$E,PerPM!$A14,'2024'!BF:BF)/PARAMETER!$T$3,"") | BG17: =IF(BG$4<=PARAMETER!$X$2,SUMIF('2024'!$E:$E,PerPM!$A14,'2024'!BG:BG)/PARAMETER!$T$3,"") | BH17: =IF(BH$4<=PARAMETER!$X$2,SUMIF('2024'!$E:$E,PerPM!$A14,'2024'!BH:BH)/PARAMETER!$T$3,"") | BI17: =IF(BI$4<=PARAMETER!$X$2,SUMIF('2024'!$E:$E,PerPM!$A14,'2024'!BI:BI)/PARAMETER!$T$3,"")
A18: =CONCATENATE(B18,PARAMETER!T$2) -> NINAVOL | B18: =PARAMETER!H3 -> NINA | C18: Ach (%) | D18: =H19/H18 -> 7272.4946 | E18: =IF(D18>300%,300%,D18) -> 3 | F18: =F14 -> Target | G18: =SUMIF('2026 T'!$E:$E,PerPM!$A18,'2026 T'!G:G)/PARAMETER!$T$3 -> 330877 | H18: =SUMIF('2026 T'!$E:$E,PerPM!$A18,'2026 T'!H:H)/PARAMETER!$T$3 -> 46685.301 | I18: =IF(I$4<=PARAMETER!$X$2,SUMIF('2026 T'!$E:$E,PerPM!$A18,'2026 T'!I:I)/PARAMETER!$T$3,"") -> 4913.3036 | J18: =IF(J$4<=PARAMETER!$X$2,SUMIF('2026 T'!$E:$E,PerPM!$A18,'2026 T'!J:J)/PARAMETER!$T$3,"") -> 4220.1846 | K18: =IF(K$4<=PARAMETER!$X$2,SUMIF('2026 T'!$E:$E,PerPM!$A18,'2026 T'!K:K)/PARAMETER!$T$3,"") -> 4214.8734 | L18: =IF(L$4<=PARAMETER!$X$2,SUMIF('2026 T'!$E:$E,PerPM!$A18,'2026 T'!L:L)/PARAMETER!$T$3,"") -> 4961.7104 | M18: =IF(M$4<=PARAMETER!$X$2,SUMIF('2026 T'!$E:$E,PerPM!$A18,'2026 T'!M:M)/PARAMETER!$T$3,"") -> 4961.0907 | N18: =IF(N$4<=PARAMETER!$X$2,SUMIF('2026 T'!$E:$E,PerPM!$A18,'2026 T'!N:N)/PARAMETER!$T$3,"") -> 4554.5263 | O18: =IF(O$4<=PARAMETER!$X$2,SUMIF('2026 T'!$E:$E,PerPM!$A18,'2026 T'!O:O)/PARAMETER!$T$3,"") -> 4375.1254 | P18: =IF(P$4<=PARAMETER!$X$2,SUMIF('2026 T'!$E:$E,PerPM!$A18,'2026 T'!P:P)/PARAMETER!$T$3,"") -> 6622.7353 | Q18: =IF(Q$4<=PARAMETER!$X$2,SUMIF('2026 T'!$E:$E,PerPM!$A18,'2026 T'!Q:Q)/PARAMETER!$T$3,"") -> 7861.7516 | R18: =IF(R$4<=PARAMETER!$X$2,SUMIF('2026 T'!$E:$E,PerPM!$A18,'2026 T'!R:R)/PARAMETER!$T$3,"") -> 6845.5563 | S18: =IF(S$4<=PARAMETER!$X$2,SUMIF('2026 T'!$E:$E,PerPM!$A18,'2026 T'!S:S)/PARAMETER!$T$3,"") -> 7583.3899 | T18: =IF(T$4<=PARAMETER!$X$2,SUMIF('2026 T'!$E:$E,PerPM!$A18,'2026 T'!T:T)/PARAMETER!$T$3,"") -> 9175.1057 | U18: =IF(U$4<=PARAMETER!$X$2,SUMIF('2026 T'!$E:$E,PerPM!$A18,'2026 T'!U:U)/PARAMETER!$T$3,"") | V18: =IF(V$4<=PARAMETER!$X$2,SUMIF('2026 T'!$E:$E,PerPM!$A18,'2026 T'!V:V)/PARAMETER!$T$3,"") | W18: =IF(W$4<=PARAMETER!$X$2,SUMIF('2026 T'!$E:$E,PerPM!$A18,'2026 T'!W:W)/PARAMETER!$T$3,"") | X18: =IF(X$4<=PARAMETER!$X$2,SUMIF('2026 T'!$E:$E,PerPM!$A18,'2026 T'!X:X)/PARAMETER!$T$3,"") | Y18: =IF(Y$4<=PARAMETER!$X$2,SUMIF('2026 T'!$E:$E,PerPM!$A18,'2026 T'!Y:Y)/PARAMETER!$T$3,"") | Z18: =IF(Z$4<=PARAMETER!$X$2,SUMIF('2026 T'!$E:$E,PerPM!$A18,'2026 T'!Z:Z)/PARAMETER!$T$3,"") | AA18: =IF(AA$4<=PARAMETER!$X$2,SUMIF('2026 T'!$E:$E,PerPM!$A18,'2026 T'!AA:AA)/PARAMETER!$T$3,"") | AB18: =IF(AB$4<=PARAMETER!$X$2,SUMIF('2026 T'!$E:$E,PerPM!$A18,'2026 T'!AB:AB)/PARAMETER!$T$3,"") | AC18: =IF(AC$4<=PARAMETER!$X$2,SUMIF('2026 T'!$E:$E,PerPM!$A18,'2026 T'!AC:AC)/PARAMETER!$T$3,"") | AD18: =IF(AD$4<=PARAMETER!$X$2,SUMIF('2026 T'!$E:$E,PerPM!$A18,'2026 T'!AD:AD)/PARAMETER!$T$3,"") | AE18: =IF(AE$4<=PARAMETER!$X$2,SUMIF('2026 T'!$E:$E,PerPM!$A18,'2026 T'!AE:AE)/PARAMETER!$T$3,"") | AF18: =IF(AF$4<=PARAMETER!$X$2,SUMIF('2026 T'!$E:$E,PerPM!$A18,'2026 T'!AF:AF)/PARAMETER!$T$3,"") | AG18: =IF(AG$4<=PARAMETER!$X$2,SUMIF('2026 T'!$E:$E,PerPM!$A18,'2026 T'!AG:AG)/PARAMETER!$T$3,"") | AH18: =IF(AH$4<=PARAMETER!$X$2,SUMIF('2026 T'!$E:$E,PerPM!$A18,'2026 T'!AH:AH)/PARAMETER!$T$3,"") | AI18: =IF(AI$4<=PARAMETER!$X$2,SUMIF('2026 T'!$E:$E,PerPM!$A18,'2026 T'!AI:AI)/PARAMETER!$T$3,"") | AJ18: =IF(AJ$4<=PARAMETER!$X$2,SUMIF('2026 T'!$E:$E,PerPM!$A18,'2026 T'!AJ:AJ)/PARAMETER!$T$3,"") | AK18: =IF(AK$4<=PARAMETER!$X$2,SUMIF('2026 T'!$E:$E,PerPM!$A18,'2026 T'!AK:AK)/PARAMETER!$T$3,"") | AL18: =IF(AL$4<=PARAMETER!$X$2,SUMIF('2026 T'!$E:$E,PerPM!$A18,'2026 T'!AL:AL)/PARAMETER!$T$3,"") | AM18: =IF(AM$4<=PARAMETER!$X$2,SUMIF('2026 T'!$E:$E,PerPM!$A18,'2026 T'!AM:AM)/PARAMETER!$T$3,"") | AN18: =IF(AN$4<=PARAMETER!$X$2,SUMIF('2026 T'!$E:$E,PerPM!$A18,'2026 T'!AN:AN)/PARAMETER!$T$3,"") | AO18: =IF(AO$4<=PARAMETER!$X$2,SUMIF('2026 T'!$E:$E,PerPM!$A18,'2026 T'!AO:AO)/PARAMETER!$T$3,"") | AP18: =IF(AP$4<=PARAMETER!$X$2,SUMIF('2026 T'!$E:$E,PerPM!$A18,'2026 T'!AP:AP)/PARAMETER!$T$3,"") | AQ18: =IF(AQ$4<=PARAMETER!$X$2,SUMIF('2026 T'!$E:$E,PerPM!$A18,'2026 T'!AQ:AQ)/PARAMETER!$T$3,"") | AR18: =IF(AR$4<=PARAMETER!$X$2,SUMIF('2026 T'!$E:$E,PerPM!$A18,'2026 T'!AR:AR)/PARAMETER!$T$3,"") | AS18: =IF(AS$4<=PARAMETER!$X$2,SUMIF('2026 T'!$E:$E,PerPM!$A18,'2026 T'!AS:AS)/PARAMETER!$T$3,"") | AT18: =IF(AT$4<=PARAMETER!$X$2,SUMIF('2026 T'!$E:$E,PerPM!$A18,'2026 T'!AT:AT)/PARAMETER!$T$3,"") | AU18: =IF(AU$4<=PARAMETER!$X$2,SUMIF('2026 T'!$E:$E,PerPM!$A18,'2026 T'!AU:AU)/PARAMETER!$T$3,"") | AV18: =IF(AV$4<=PARAMETER!$X$2,SUMIF('2026 T'!$E:$E,PerPM!$A18,'2026 T'!AV:AV)/PARAMETER!$T$3,"") | AW18: =IF(AW$4<=PARAMETER!$X$2,SUMIF('2026 T'!$E:$E,PerPM!$A18,'2026 T'!AW:AW)/PARAMETER!$T$3,"") | AX18: =IF(AX$4<=PARAMETER!$X$2,SUMIF('2026 T'!$E:$E,PerPM!$A18,'2026 T'!AX:AX)/PARAMETER!$T$3,"") | AY18: =IF(AY$4<=PARAMETER!$X$2,SUMIF('2026 T'!$E:$E,PerPM!$A18,'2026 T'!AY:AY)/PARAMETER!$T$3,"") | AZ18: =IF(AZ$4<=PARAMETER!$X$2,SUMIF('2026 T'!$E:$E,PerPM!$A18,'2026 T'!AZ:AZ)/PARAMETER!$T$3,"") | BA18: =IF(BA$4<=PARAMETER!$X$2,SUMIF('2026 T'!$E:$E,PerPM!$A18,'2026 T'!BA:BA)/PARAMETER!$T$3,"") | BB18: =IF(BB$4<=PARAMETER!$X$2,SUMIF('2026 T'!$E:$E,PerPM!$A18,'2026 T'!BB:BB)/PARAMETER!$T$3,"") | BC18: =IF(BC$4<=PARAMETER!$X$2,SUMIF('2026 T'!$E:$E,PerPM!$A18,'2026 T'!BC:BC)/PARAMETER!$T$3,"") | BD18: =IF(BD$4<=PARAMETER!$X$2,SUMIF('2026 T'!$E:$E,PerPM!$A18,'2026 T'!BD:BD)/PARAMETER!$T$3,"") | BE18: =IF(BE$4<=PARAMETER!$X$2,SUMIF('2026 T'!$E:$E,PerPM!$A18,'2026 T'!BE:BE)/PARAMETER!$T$3,"") | BF18: =IF(BF$4<=PARAMETER!$X$2,SUMIF('2026 T'!$E:$E,PerPM!$A18,'2026 T'!BF:BF)/PARAMETER!$T$3,"") | BG18: =IF(BG$4<=PARAMETER!$X$2,SUMIF('2026 T'!$E:$E,PerPM!$A18,'2026 T'!BG:BG)/PARAMETER!$T$3,"") | BH18: =IF(BH$4<=PARAMETER!$X$2,SUMIF('2026 T'!$E:$E,PerPM!$A18,'2026 T'!BH:BH)/PARAMETER!$T$3,"") | BI18: =IF(BI$4<=PARAMETER!$X$2,SUMIF('2026 T'!$E:$E,PerPM!$A18,'2026 T'!BI:BI)/PARAMETER!$T$3,"")
A19: =CONCATENATE(B19,PARAMETER!T$2) -> NINAVOL | B19: =B18 -> NINA | C19: YoY (%) | D19: =H19/H20-1 -> 4627.3853 | E19: =IF(D19>300%,300%,D19) -> 3 | F19: =F15 -> 2026 | G19: =IF(G$4<=PARAMETER!$X$2,SUMIF('2026'!$E:$E,PerPM!$A18,'2026'!G:G)/PARAMETER!$T$3,"") -> 3.3958032e+08 | H19: =IF(H$4<=PARAMETER!$X$2,SUMIF('2026'!$E:$E,PerPM!$A18,'2026'!H:H)/PARAMETER!$T$3,"") -> 3.395186e+08 | I19: =IF(I$4<=PARAMETER!$X$2,SUMIF('2026'!$E:$E,PerPM!$A18,'2026'!I:I)/PARAMETER!$T$3,"") -> 183.58227 | J19: =IF(J$4<=PARAMETER!$X$2,SUMIF('2026'!$E:$E,PerPM!$A18,'2026'!J:J)/PARAMETER!$T$3,"") -> 177.94041 | K19: =IF(K$4<=PARAMETER!$X$2,SUMIF('2026'!$E:$E,PerPM!$A18,'2026'!K:K)/PARAMETER!$T$3,"") -> 0 | L19: =IF(L$4<=PARAMETER!$X$2,SUMIF('2026'!$E:$E,PerPM!$A18,'2026'!L:L)/PARAMETER!$T$3,"") -> 208.35063 | M19: =IF(M$4<=PARAMETER!$X$2,SUMIF('2026'!$E:$E,PerPM!$A18,'2026'!M:M)/PARAMETER!$T$3,"") -> 165.62353 | N19: =IF(N$4<=PARAMETER!$X$2,SUMIF('2026'!$E:$E,PerPM!$A18,'2026'!N:N)/PARAMETER!$T$3,"") -> 200.19594 | O19: =IF(O$4<=PARAMETER!$X$2,SUMIF('2026'!$E:$E,PerPM!$A18,'2026'!O:O)/PARAMETER!$T$3,"") -> 170.30831 | P19: =IF(P$4<=PARAMETER!$X$2,SUMIF('2026'!$E:$E,PerPM!$A18,'2026'!P:P)/PARAMETER!$T$3,"") -> 206.23438 | Q19: =IF(Q$4<=PARAMETER!$X$2,SUMIF('2026'!$E:$E,PerPM!$A18,'2026'!Q:Q)/PARAMETER!$T$3,"") -> 2.0591655e+08 | R19: =IF(R$4<=PARAMETER!$X$2,SUMIF('2026'!$E:$E,PerPM!$A18,'2026'!R:R)/PARAMETER!$T$3,"") -> 72530809 | S19: =IF(S$4<=PARAMETER!$X$2,SUMIF('2026'!$E:$E,PerPM!$A18,'2026'!S:S)/PARAMETER!$T$3,"") -> 61069725 | T19: =IF(T$4<=PARAMETER!$X$2,SUMIF('2026'!$E:$E,PerPM!$A18,'2026'!T:T)/PARAMETER!$T$3,"") -> 201.29233 | U19: =IF(U$4<=PARAMETER!$X$2,SUMIF('2026'!$E:$E,PerPM!$A18,'2026'!U:U)/PARAMETER!$T$3,"") | V19: =IF(V$4<=PARAMETER!$X$2,SUMIF('2026'!$E:$E,PerPM!$A18,'2026'!V:V)/PARAMETER!$T$3,"") | W19: =IF(W$4<=PARAMETER!$X$2,SUMIF('2026'!$E:$E,PerPM!$A18,'2026'!W:W)/PARAMETER!$T$3,"") | X19: =IF(X$4<=PARAMETER!$X$2,SUMIF('2026'!$E:$E,PerPM!$A18,'2026'!X:X)/PARAMETER!$T$3,"") | Y19: =IF(Y$4<=PARAMETER!$X$2,SUMIF('2026'!$E:$E,PerPM!$A18,'2026'!Y:Y)/PARAMETER!$T$3,"") | Z19: =IF(Z$4<=PARAMETER!$X$2,SUMIF('2026'!$E:$E,PerPM!$A18,'2026'!Z:Z)/PARAMETER!$T$3,"") | AA19: =IF(AA$4<=PARAMETER!$X$2,SUMIF('2026'!$E:$E,PerPM!$A18,'2026'!AA:AA)/PARAMETER!$T$3,"") | AB19: =IF(AB$4<=PARAMETER!$X$2,SUMIF('2026'!$E:$E,PerPM!$A18,'2026'!AB:AB)/PARAMETER!$T$3,"") | AC19: =IF(AC$4<=PARAMETER!$X$2,SUMIF('2026'!$E:$E,PerPM!$A18,'2026'!AC:AC)/PARAMETER!$T$3,"") | AD19: =IF(AD$4<=PARAMETER!$X$2,SUMIF('2026'!$E:$E,PerPM!$A18,'2026'!AD:AD)/PARAMETER!$T$3,"") | AE19: =IF(AE$4<=PARAMETER!$X$2,SUMIF('2026'!$E:$E,PerPM!$A18,'2026'!AE:AE)/PARAMETER!$T$3,"") | AF19: =IF(AF$4<=PARAMETER!$X$2,SUMIF('2026'!$E:$E,PerPM!$A18,'2026'!AF:AF)/PARAMETER!$T$3,"") | AG19: =IF(AG$4<=PARAMETER!$X$2,SUMIF('2026'!$E:$E,PerPM!$A18,'2026'!AG:AG)/PARAMETER!$T$3,"") | AH19: =IF(AH$4<=PARAMETER!$X$2,SUMIF('2026'!$E:$E,PerPM!$A18,'2026'!AH:AH)/PARAMETER!$T$3,"") | AI19: =IF(AI$4<=PARAMETER!$X$2,SUMIF('2026'!$E:$E,PerPM!$A18,'2026'!AI:AI)/PARAMETER!$T$3,"") | AJ19: =IF(AJ$4<=PARAMETER!$X$2,SUMIF('2026'!$E:$E,PerPM!$A18,'2026'!AJ:AJ)/PARAMETER!$T$3,"") | AK19: =IF(AK$4<=PARAMETER!$X$2,SUMIF('2026'!$E:$E,PerPM!$A18,'2026'!AK:AK)/PARAMETER!$T$3,"") | AL19: =IF(AL$4<=PARAMETER!$X$2,SUMIF('2026'!$E:$E,PerPM!$A18,'2026'!AL:AL)/PARAMETER!$T$3,"") | AM19: =IF(AM$4<=PARAMETER!$X$2,SUMIF('2026'!$E:$E,PerPM!$A18,'2026'!AM:AM)/PARAMETER!$T$3,"") | AN19: =IF(AN$4<=PARAMETER!$X$2,SUMIF('2026'!$E:$E,PerPM!$A18,'2026'!AN:AN)/PARAMETER!$T$3,"") | AO19: =IF(AO$4<=PARAMETER!$X$2,SUMIF('2026'!$E:$E,PerPM!$A18,'2026'!AO:AO)/PARAMETER!$T$3,"") | AP19: =IF(AP$4<=PARAMETER!$X$2,SUMIF('2026'!$E:$E,PerPM!$A18,'2026'!AP:AP)/PARAMETER!$T$3,"") | AQ19: =IF(AQ$4<=PARAMETER!$X$2,SUMIF('2026'!$E:$E,PerPM!$A18,'2026'!AQ:AQ)/PARAMETER!$T$3,"") | AR19: =IF(AR$4<=PARAMETER!$X$2,SUMIF('2026'!$E:$E,PerPM!$A18,'2026'!AR:AR)/PARAMETER!$T$3,"") | AS19: =IF(AS$4<=PARAMETER!$X$2,SUMIF('2026'!$E:$E,PerPM!$A18,'2026'!AS:AS)/PARAMETER!$T$3,"") | AT19: =IF(AT$4<=PARAMETER!$X$2,SUMIF('2026'!$E:$E,PerPM!$A18,'2026'!AT:AT)/PARAMETER!$T$3,"") | AU19: =IF(AU$4<=PARAMETER!$X$2,SUMIF('2026'!$E:$E,PerPM!$A18,'2026'!AU:AU)/PARAMETER!$T$3,"") | AV19: =IF(AV$4<=PARAMETER!$X$2,SUMIF('2026'!$E:$E,PerPM!$A18,'2026'!AV:AV)/PARAMETER!$T$3,"") | AW19: =IF(AW$4<=PARAMETER!$X$2,SUMIF('2026'!$E:$E,PerPM!$A18,'2026'!AW:AW)/PARAMETER!$T$3,"") | AX19: =IF(AX$4<=PARAMETER!$X$2,SUMIF('2026'!$E:$E,PerPM!$A18,'2026'!AX:AX)/PARAMETER!$T$3,"") | AY19: =IF(AY$4<=PARAMETER!$X$2,SUMIF('2026'!$E:$E,PerPM!$A18,'2026'!AY:AY)/PARAMETER!$T$3,"") | AZ19: =IF(AZ$4<=PARAMETER!$X$2,SUMIF('2026'!$E:$E,PerPM!$A18,'2026'!AZ:AZ)/PARAMETER!$T$3,"") | BA19: =IF(BA$4<=PARAMETER!$X$2,SUMIF('2026'!$E:$E,PerPM!$A18,'2026'!BA:BA)/PARAMETER!$T$3,"") | BB19: =IF(BB$4<=PARAMETER!$X$2,SUMIF('2026'!$E:$E,PerPM!$A18,'2026'!BB:BB)/PARAMETER!$T$3,"") | BC19: =IF(BC$4<=PARAMETER!$X$2,SUMIF('2026'!$E:$E,PerPM!$A18,'2026'!BC:BC)/PARAMETER!$T$3,"") | BD19: =IF(BD$4<=PARAMETER!$X$2,SUMIF('2026'!$E:$E,PerPM!$A18,'2026'!BD:BD)/PARAMETER!$T$3,"") | BE19: =IF(BE$4<=PARAMETER!$X$2,SUMIF('2026'!$E:$E,PerPM!$A18,'2026'!BE:BE)/PARAMETER!$T$3,"") | BF19: =IF(BF$4<=PARAMETER!$X$2,SUMIF('2026'!$E:$E,PerPM!$A18,'2026'!BF:BF)/PARAMETER!$T$3,"") | BG19: =IF(BG$4<=PARAMETER!$X$2,SUMIF('2026'!$E:$E,PerPM!$A18,'2026'!BG:BG)/PARAMETER!$T$3,"") | BH19: =IF(BH$4<=PARAMETER!$X$2,SUMIF('2026'!$E:$E,PerPM!$A18,'2026'!BH:BH)/PARAMETER!$T$3,"") | BI19: =IF(BI$4<=PARAMETER!$X$2,SUMIF('2026'!$E:$E,PerPM!$A18,'2026'!BI:BI)/PARAMETER!$T$3,"")
A20: =CONCATENATE(B20,PARAMETER!T$2) -> NINAVOL | B20: =B19 -> NINA | C20: YoY (%) | D20: =H20/H21-1 -> 1.1756094 | E20: =IF(D20>300%,300%,D20) -> 1.1756094 | F20: =F16 -> 2025 | G20: =IF(G$4<=PARAMETER!$X$2,SUMIF('2025'!$E:$E,PerPM!$A19,'2025'!G:G)/PARAMETER!$T$3,"") -> 367270.03 | H20: =IF(H$4<=PARAMETER!$X$2,SUMIF('2025'!$E:$E,PerPM!$A19,'2025'!H:H)/PARAMETER!$T$3,"") -> 73355.734 | I20: =IF(I$4<=PARAMETER!$X$2,SUMIF('2025'!$E:$E,PerPM!$A19,'2025'!I:I)/PARAMETER!$T$3,"") -> 4642.1209 | J20: =IF(J$4<=PARAMETER!$X$2,SUMIF('2025'!$E:$E,PerPM!$A19,'2025'!J:J)/PARAMETER!$T$3,"") -> 3928.0331 | K20: =IF(K$4<=PARAMETER!$X$2,SUMIF('2025'!$E:$E,PerPM!$A19,'2025'!K:K)/PARAMETER!$T$3,"") -> 3908.0346 | L20: =IF(L$4<=PARAMETER!$X$2,SUMIF('2025'!$E:$E,PerPM!$A19,'2025'!L:L)/PARAMETER!$T$3,"") -> 4678.4553 | M20: =IF(M$4<=PARAMETER!$X$2,SUMIF('2025'!$E:$E,PerPM!$A19,'2025'!M:M)/PARAMETER!$T$3,"") -> 4706.7965 | N20: =IF(N$4<=PARAMETER!$X$2,SUMIF('2025'!$E:$E,PerPM!$A19,'2025'!N:N)/PARAMETER!$T$3,"") -> 4359.8524 | O20: =IF(O$4<=PARAMETER!$X$2,SUMIF('2025'!$E:$E,PerPM!$A19,'2025'!O:O)/PARAMETER!$T$3,"") -> 4230.5787 | P20: =IF(P$4<=PARAMETER!$X$2,SUMIF('2025'!$E:$E,PerPM!$A19,'2025'!P:P)/PARAMETER!$T$3,"") -> 7444.4498 | Q20: =IF(Q$4<=PARAMETER!$X$2,SUMIF('2025'!$E:$E,PerPM!$A19,'2025'!Q:Q)/PARAMETER!$T$3,"") -> 8721.5919 | R20: =IF(R$4<=PARAMETER!$X$2,SUMIF('2025'!$E:$E,PerPM!$A19,'2025'!R:R)/PARAMETER!$T$3,"") -> 7641.6606 | S20: =IF(S$4<=PARAMETER!$X$2,SUMIF('2025'!$E:$E,PerPM!$A19,'2025'!S:S)/PARAMETER!$T$3,"") -> 8603.3798 | T20: =IF(T$4<=PARAMETER!$X$2,SUMIF('2025'!$E:$E,PerPM!$A19,'2025'!T:T)/PARAMETER!$T$3,"") -> 10490.78 | U20: =IF(U$4<=PARAMETER!$X$2,SUMIF('2025'!$E:$E,PerPM!$A19,'2025'!U:U)/PARAMETER!$T$3,"") | V20: =IF(V$4<=PARAMETER!$X$2,SUMIF('2025'!$E:$E,PerPM!$A19,'2025'!V:V)/PARAMETER!$T$3,"") | W20: =IF(W$4<=PARAMETER!$X$2,SUMIF('2025'!$E:$E,PerPM!$A19,'2025'!W:W)/PARAMETER!$T$3,"") | X20: =IF(X$4<=PARAMETER!$X$2,SUMIF('2025'!$E:$E,PerPM!$A19,'2025'!X:X)/PARAMETER!$T$3,"") | Y20: =IF(Y$4<=PARAMETER!$X$2,SUMIF('2025'!$E:$E,PerPM!$A19,'2025'!Y:Y)/PARAMETER!$T$3,"") | Z20: =IF(Z$4<=PARAMETER!$X$2,SUMIF('2025'!$E:$E,PerPM!$A19,'2025'!Z:Z)/PARAMETER!$T$3,"") | AA20: =IF(AA$4<=PARAMETER!$X$2,SUMIF('2025'!$E:$E,PerPM!$A19,'2025'!AA:AA)/PARAMETER!$T$3,"") | AB20: =IF(AB$4<=PARAMETER!$X$2,SUMIF('2025'!$E:$E,PerPM!$A19,'2025'!AB:AB)/PARAMETER!$T$3,"") | AC20: =IF(AC$4<=PARAMETER!$X$2,SUMIF('2025'!$E:$E,PerPM!$A19,'2025'!AC:AC)/PARAMETER!$T$3,"") | AD20: =IF(AD$4<=PARAMETER!$X$2,SUMIF('2025'!$E:$E,PerPM!$A19,'2025'!AD:AD)/PARAMETER!$T$3,"") | AE20: =IF(AE$4<=PARAMETER!$X$2,SUMIF('2025'!$E:$E,PerPM!$A19,'2025'!AE:AE)/PARAMETER!$T$3,"") | AF20: =IF(AF$4<=PARAMETER!$X$2,SUMIF('2025'!$E:$E,PerPM!$A19,'2025'!AF:AF)/PARAMETER!$T$3,"") | AG20: =IF(AG$4<=PARAMETER!$X$2,SUMIF('2025'!$E:$E,PerPM!$A19,'2025'!AG:AG)/PARAMETER!$T$3,"") | AH20: =IF(AH$4<=PARAMETER!$X$2,SUMIF('2025'!$E:$E,PerPM!$A19,'2025'!AH:AH)/PARAMETER!$T$3,"") | AI20: =IF(AI$4<=PARAMETER!$X$2,SUMIF('2025'!$E:$E,PerPM!$A19,'2025'!AI:AI)/PARAMETER!$T$3,"") | AJ20: =IF(AJ$4<=PARAMETER!$X$2,SUMIF('2025'!$E:$E,PerPM!$A19,'2025'!AJ:AJ)/PARAMETER!$T$3,"") | AK20: =IF(AK$4<=PARAMETER!$X$2,SUMIF('2025'!$E:$E,PerPM!$A19,'2025'!AK:AK)/PARAMETER!$T$3,"") | AL20: =IF(AL$4<=PARAMETER!$X$2,SUMIF('2025'!$E:$E,PerPM!$A19,'2025'!AL:AL)/PARAMETER!$T$3,"") | AM20: =IF(AM$4<=PARAMETER!$X$2,SUMIF('2025'!$E:$E,PerPM!$A19,'2025'!AM:AM)/PARAMETER!$T$3,"") | AN20: =IF(AN$4<=PARAMETER!$X$2,SUMIF('2025'!$E:$E,PerPM!$A19,'2025'!AN:AN)/PARAMETER!$T$3,"") | AO20: =IF(AO$4<=PARAMETER!$X$2,SUMIF('2025'!$E:$E,PerPM!$A19,'2025'!AO:AO)/PARAMETER!$T$3,"") | AP20: =IF(AP$4<=PARAMETER!$X$2,SUMIF('2025'!$E:$E,PerPM!$A19,'2025'!AP:AP)/PARAMETER!$T$3,"") | AQ20: =IF(AQ$4<=PARAMETER!$X$2,SUMIF('2025'!$E:$E,PerPM!$A19,'2025'!AQ:AQ)/PARAMETER!$T$3,"") | AR20: =IF(AR$4<=PARAMETER!$X$2,SUMIF('2025'!$E:$E,PerPM!$A19,'2025'!AR:AR)/PARAMETER!$T$3,"") | AS20: =IF(AS$4<=PARAMETER!$X$2,SUMIF('2025'!$E:$E,PerPM!$A19,'2025'!AS:AS)/PARAMETER!$T$3,"") | AT20: =IF(AT$4<=PARAMETER!$X$2,SUMIF('2025'!$E:$E,PerPM!$A19,'2025'!AT:AT)/PARAMETER!$T$3,"") | AU20: =IF(AU$4<=PARAMETER!$X$2,SUMIF('2025'!$E:$E,PerPM!$A19,'2025'!AU:AU)/PARAMETER!$T$3,"") | AV20: =IF(AV$4<=PARAMETER!$X$2,SUMIF('2025'!$E:$E,PerPM!$A19,'2025'!AV:AV)/PARAMETER!$T$3,"") | AW20: =IF(AW$4<=PARAMETER!$X$2,SUMIF('2025'!$E:$E,PerPM!$A19,'2025'!AW:AW)/PARAMETER!$T$3,"") | AX20: =IF(AX$4<=PARAMETER!$X$2,SUMIF('2025'!$E:$E,PerPM!$A19,'2025'!AX:AX)/PARAMETER!$T$3,"") | AY20: =IF(AY$4<=PARAMETER!$X$2,SUMIF('2025'!$E:$E,PerPM!$A19,'2025'!AY:AY)/PARAMETER!$T$3,"") | AZ20: =IF(AZ$4<=PARAMETER!$X$2,SUMIF('2025'!$E:$E,PerPM!$A19,'2025'!AZ:AZ)/PARAMETER!$T$3,"") | BA20: =IF(BA$4<=PARAMETER!$X$2,SUMIF('2025'!$E:$E,PerPM!$A19,'2025'!BA:BA)/PARAMETER!$T$3,"") | BB20: =IF(BB$4<=PARAMETER!$X$2,SUMIF('2025'!$E:$E,PerPM!$A19,'2025'!BB:BB)/PARAMETER!$T$3,"") | BC20: =IF(BC$4<=PARAMETER!$X$2,SUMIF('2025'!$E:$E,PerPM!$A19,'2025'!BC:BC)/PARAMETER!$T$3,"") | BD20: =IF(BD$4<=PARAMETER!$X$2,SUMIF('2025'!$E:$E,PerPM!$A19,'2025'!BD:BD)/PARAMETER!$T$3,"") | BE20: =IF(BE$4<=PARAMETER!$X$2,SUMIF('2025'!$E:$E,PerPM!$A19,'2025'!BE:BE)/PARAMETER!$T$3,"") | BF20: =IF(BF$4<=PARAMETER!$X$2,SUMIF('2025'!$E:$E,PerPM!$A19,'2025'!BF:BF)/PARAMETER!$T$3,"") | BG20: =IF(BG$4<=PARAMETER!$X$2,SUMIF('2025'!$E:$E,PerPM!$A19,'2025'!BG:BG)/PARAMETER!$T$3,"") | BH20: =IF(BH$4<=PARAMETER!$X$2,SUMIF('2025'!$E:$E,PerPM!$A19,'2025'!BH:BH)/PARAMETER!$T$3,"") | BI20: =IF(BI$4<=PARAMETER!$X$2,SUMIF('2025'!$E:$E,PerPM!$A19,'2025'!BI:BI)/PARAMETER!$T$3,"")
A21: =CONCATENATE(B21,PARAMETER!T$2) -> NINAVOL | B21: =B19 -> NINA | F21: =F17 -> 2024 | G21: =IF(G$4<=PARAMETER!$X$2,SUMIF('2024'!$E:$E,PerPM!$A18,'2024'!G:G)/PARAMETER!$T$3,"") -> 177032.76 | H21: =IF(H$4<=PARAMETER!$X$2,SUMIF('2024'!$E:$E,PerPM!$A18,'2024'!H:H)/PARAMETER!$T$3,"") -> 33717.327 | I21: =IF(I$4<=PARAMETER!$X$2,SUMIF('2024'!$E:$E,PerPM!$A18,'2024'!I:I)/PARAMETER!$T$3,"") -> 2420.7037 | J21: =IF(J$4<=PARAMETER!$X$2,SUMIF('2024'!$E:$E,PerPM!$A18,'2024'!J:J)/PARAMETER!$T$3,"") -> 2254.4403 | K21: =IF(K$4<=PARAMETER!$X$2,SUMIF('2024'!$E:$E,PerPM!$A18,'2024'!K:K)/PARAMETER!$T$3,"") -> 2354.455 | L21: =IF(L$4<=PARAMETER!$X$2,SUMIF('2024'!$E:$E,PerPM!$A18,'2024'!L:L)/PARAMETER!$T$3,"") -> 2791.1607 | M21: =IF(M$4<=PARAMETER!$X$2,SUMIF('2024'!$E:$E,PerPM!$A18,'2024'!M:M)/PARAMETER!$T$3,"") -> 2779.7873 | N21: =IF(N$4<=PARAMETER!$X$2,SUMIF('2024'!$E:$E,PerPM!$A18,'2024'!N:N)/PARAMETER!$T$3,"") -> 2816.469 | O21: =IF(O$4<=PARAMETER!$X$2,SUMIF('2024'!$E:$E,PerPM!$A18,'2024'!O:O)/PARAMETER!$T$3,"") -> 2646.8318 | P21: =IF(P$4<=PARAMETER!$X$2,SUMIF('2024'!$E:$E,PerPM!$A18,'2024'!P:P)/PARAMETER!$T$3,"") -> 2772.4104 | Q21: =IF(Q$4<=PARAMETER!$X$2,SUMIF('2024'!$E:$E,PerPM!$A18,'2024'!Q:Q)/PARAMETER!$T$3,"") -> 3243.875 | R21: =IF(R$4<=PARAMETER!$X$2,SUMIF('2024'!$E:$E,PerPM!$A18,'2024'!R:R)/PARAMETER!$T$3,"") -> 3308.8299 | S21: =IF(S$4<=PARAMETER!$X$2,SUMIF('2024'!$E:$E,PerPM!$A18,'2024'!S:S)/PARAMETER!$T$3,"") -> 3203.9467 | T21: =IF(T$4<=PARAMETER!$X$2,SUMIF('2024'!$E:$E,PerPM!$A18,'2024'!T:T)/PARAMETER!$T$3,"") -> 3124.4167 | U21: =IF(U$4<=PARAMETER!$X$2,SUMIF('2024'!$E:$E,PerPM!$A18,'2024'!U:U)/PARAMETER!$T$3,"") | V21: =IF(V$4<=PARAMETER!$X$2,SUMIF('2024'!$E:$E,PerPM!$A18,'2024'!V:V)/PARAMETER!$T$3,"") | W21: =IF(W$4<=PARAMETER!$X$2,SUMIF('2024'!$E:$E,PerPM!$A18,'2024'!W:W)/PARAMETER!$T$3,"") | X21: =IF(X$4<=PARAMETER!$X$2,SUMIF('2024'!$E:$E,PerPM!$A18,'2024'!X:X)/PARAMETER!$T$3,"") | Y21: =IF(Y$4<=PARAMETER!$X$2,SUMIF('2024'!$E:$E,PerPM!$A18,'2024'!Y:Y)/PARAMETER!$T$3,"") | Z21: =IF(Z$4<=PARAMETER!$X$2,SUMIF('2024'!$E:$E,PerPM!$A18,'2024'!Z:Z)/PARAMETER!$T$3,"") | AA21: =IF(AA$4<=PARAMETER!$X$2,SUMIF('2024'!$E:$E,PerPM!$A18,'2024'!AA:AA)/PARAMETER!$T$3,"") | AB21: =IF(AB$4<=PARAMETER!$X$2,SUMIF('2024'!$E:$E,PerPM!$A18,'2024'!AB:AB)/PARAMETER!$T$3,"") | AC21: =IF(AC$4<=PARAMETER!$X$2,SUMIF('2024'!$E:$E,PerPM!$A18,'2024'!AC:AC)/PARAMETER!$T$3,"") | AD21: =IF(AD$4<=PARAMETER!$X$2,SUMIF('2024'!$E:$E,PerPM!$A18,'2024'!AD:AD)/PARAMETER!$T$3,"") | AE21: =IF(AE$4<=PARAMETER!$X$2,SUMIF('2024'!$E:$E,PerPM!$A18,'2024'!AE:AE)/PARAMETER!$T$3,"") | AF21: =IF(AF$4<=PARAMETER!$X$2,SUMIF('2024'!$E:$E,PerPM!$A18,'2024'!AF:AF)/PARAMETER!$T$3,"") | AG21: =IF(AG$4<=PARAMETER!$X$2,SUMIF('2024'!$E:$E,PerPM!$A18,'2024'!AG:AG)/PARAMETER!$T$3,"") | AH21: =IF(AH$4<=PARAMETER!$X$2,SUMIF('2024'!$E:$E,PerPM!$A18,'2024'!AH:AH)/PARAMETER!$T$3,"") | AI21: =IF(AI$4<=PARAMETER!$X$2,SUMIF('2024'!$E:$E,PerPM!$A18,'2024'!AI:AI)/PARAMETER!$T$3,"") | AJ21: =IF(AJ$4<=PARAMETER!$X$2,SUMIF('2024'!$E:$E,PerPM!$A18,'2024'!AJ:AJ)/PARAMETER!$T$3,"") | AK21: =IF(AK$4<=PARAMETER!$X$2,SUMIF('2024'!$E:$E,PerPM!$A18,'2024'!AK:AK)/PARAMETER!$T$3,"") | AL21: =IF(AL$4<=PARAMETER!$X$2,SUMIF('2024'!$E:$E,PerPM!$A18,'2024'!AL:AL)/PARAMETER!$T$3,"") | AM21: =IF(AM$4<=PARAMETER!$X$2,SUMIF('2024'!$E:$E,PerPM!$A18,'2024'!AM:AM)/PARAMETER!$T$3,"") | AN21: =IF(AN$4<=PARAMETER!$X$2,SUMIF('2024'!$E:$E,PerPM!$A18,'2024'!AN:AN)/PARAMETER!$T$3,"") | AO21: =IF(AO$4<=PARAMETER!$X$2,SUMIF('2024'!$E:$E,PerPM!$A18,'2024'!AO:AO)/PARAMETER!$T$3,"") | AP21: =IF(AP$4<=PARAMETER!$X$2,SUMIF('2024'!$E:$E,PerPM!$A18,'2024'!AP:AP)/PARAMETER!$T$3,"") | AQ21: =IF(AQ$4<=PARAMETER!$X$2,SUMIF('2024'!$E:$E,PerPM!$A18,'2024'!AQ:AQ)/PARAMETER!$T$3,"") | AR21: =IF(AR$4<=PARAMETER!$X$2,SUMIF('2024'!$E:$E,PerPM!$A18,'2024'!AR:AR)/PARAMETER!$T$3,"") | AS21: =IF(AS$4<=PARAMETER!$X$2,SUMIF('2024'!$E:$E,PerPM!$A18,'2024'!AS:AS)/PARAMETER!$T$3,"") | AT21: =IF(AT$4<=PARAMETER!$X$2,SUMIF('2024'!$E:$E,PerPM!$A18,'2024'!AT:AT)/PARAMETER!$T$3,"") | AU21: =IF(AU$4<=PARAMETER!$X$2,SUMIF('2024'!$E:$E,PerPM!$A18,'2024'!AU:AU)/PARAMETER!$T$3,"") | AV21: =IF(AV$4<=PARAMETER!$X$2,SUMIF('2024'!$E:$E,PerPM!$A18,'2024'!AV:AV)/PARAMETER!$T$3,"") | AW21: =IF(AW$4<=PARAMETER!$X$2,SUMIF('2024'!$E:$E,PerPM!$A18,'2024'!AW:AW)/PARAMETER!$T$3,"") | AX21: =IF(AX$4<=PARAMETER!$X$2,SUMIF('2024'!$E:$E,PerPM!$A18,'2024'!AX:AX)/PARAMETER!$T$3,"") | AY21: =IF(AY$4<=PARAMETER!$X$2,SUMIF('2024'!$E:$E,PerPM!$A18,'2024'!AY:AY)/PARAMETER!$T$3,"") | AZ21: =IF(AZ$4<=PARAMETER!$X$2,SUMIF('2024'!$E:$E,PerPM!$A18,'2024'!AZ:AZ)/PARAMETER!$T$3,"") | BA21: =IF(BA$4<=PARAMETER!$X$2,SUMIF('2024'!$E:$E,PerPM!$A18,'2024'!BA:BA)/PARAMETER!$T$3,"") | BB21: =IF(BB$4<=PARAMETER!$X$2,SUMIF('2024'!$E:$E,PerPM!$A18,'2024'!BB:BB)/PARAMETER!$T$3,"") | BC21: =IF(BC$4<=PARAMETER!$X$2,SUMIF('2024'!$E:$E,PerPM!$A18,'2024'!BC:BC)/PARAMETER!$T$3,"") | BD21: =IF(BD$4<=PARAMETER!$X$2,SUMIF('2024'!$E:$E,PerPM!$A18,'2024'!BD:BD)/PARAMETER!$T$3,"") | BE21: =IF(BE$4<=PARAMETER!$X$2,SUMIF('2024'!$E:$E,PerPM!$A18,'2024'!BE:BE)/PARAMETER!$T$3,"") | BF21: =IF(BF$4<=PARAMETER!$X$2,SUMIF('2024'!$E:$E,PerPM!$A18,'2024'!BF:BF)/PARAMETER!$T$3,"") | BG21: =IF(BG$4<=PARAMETER!$X$2,SUMIF('2024'!$E:$E,PerPM!$A18,'2024'!BG:BG)/PARAMETER!$T$3,"") | BH21: =IF(BH$4<=PARAMETER!$X$2,SUMIF('2024'!$E:$E,PerPM!$A18,'2024'!BH:BH)/PARAMETER!$T$3,"") | BI21: =IF(BI$4<=PARAMETER!$X$2,SUMIF('2024'!$E:$E,PerPM!$A18,'2024'!BI:BI)/PARAMETER!$T$3,"")
A22: =CONCATENATE(B22,PARAMETER!T$2) -> RIFALDIVOL | B22: =PARAMETER!H4 -> RIFALDI | C22: Ach (%) | D22: =H23/H22 -> 627.90917 | E22: =IF(D22>300%,300%,D22) -> 3 | F22: =F18 -> Target | G22: =SUMIF('2026 T'!$E:$E,PerPM!$A22,'2026 T'!G:G)/PARAMETER!$T$3 -> 487510 | H22: =SUMIF('2026 T'!$E:$E,PerPM!$A22,'2026 T'!H:H)/PARAMETER!$T$3 -> 20579.602 | I22: =IF(I$4<=PARAMETER!$X$2,SUMIF('2026 T'!$E:$E,PerPM!$A22,'2026 T'!I:I)/PARAMETER!$T$3,"") -> 2497.0901 | J22: =IF(J$4<=PARAMETER!$X$2,SUMIF('2026 T'!$E:$E,PerPM!$A22,'2026 T'!J:J)/PARAMETER!$T$3,"") -> 2469.6751 | K22: =IF(K$4<=PARAMETER!$X$2,SUMIF('2026 T'!$E:$E,PerPM!$A22,'2026 T'!K:K)/PARAMETER!$T$3,"") -> 2176.6466 | L22: =IF(L$4<=PARAMETER!$X$2,SUMIF('2026 T'!$E:$E,PerPM!$A22,'2026 T'!L:L)/PARAMETER!$T$3,"") -> 2675.7301 | M22: =IF(M$4<=PARAMETER!$X$2,SUMIF('2026 T'!$E:$E,PerPM!$A22,'2026 T'!M:M)/PARAMETER!$T$3,"") -> 2552.8935 | N22: =IF(N$4<=PARAMETER!$X$2,SUMIF('2026 T'!$E:$E,PerPM!$A22,'2026 T'!N:N)/PARAMETER!$T$3,"") -> 2146.5567 | O22: =IF(O$4<=PARAMETER!$X$2,SUMIF('2026 T'!$E:$E,PerPM!$A22,'2026 T'!O:O)/PARAMETER!$T$3,"") -> 1851.116 | P22: =IF(P$4<=PARAMETER!$X$2,SUMIF('2026 T'!$E:$E,PerPM!$A22,'2026 T'!P:P)/PARAMETER!$T$3,"") -> 1510.1886 | Q22: =IF(Q$4<=PARAMETER!$X$2,SUMIF('2026 T'!$E:$E,PerPM!$A22,'2026 T'!Q:Q)/PARAMETER!$T$3,"") -> 2699.7053 | R22: =IF(R$4<=PARAMETER!$X$2,SUMIF('2026 T'!$E:$E,PerPM!$A22,'2026 T'!R:R)/PARAMETER!$T$3,"") -> 3345.0627 | S22: =IF(S$4<=PARAMETER!$X$2,SUMIF('2026 T'!$E:$E,PerPM!$A22,'2026 T'!S:S)/PARAMETER!$T$3,"") -> 4205.4533 | T22: =IF(T$4<=PARAMETER!$X$2,SUMIF('2026 T'!$E:$E,PerPM!$A22,'2026 T'!T:T)/PARAMETER!$T$3,"") -> 1372.3241 | U22: =IF(U$4<=PARAMETER!$X$2,SUMIF('2026 T'!$E:$E,PerPM!$A22,'2026 T'!U:U)/PARAMETER!$T$3,"") | V22: =IF(V$4<=PARAMETER!$X$2,SUMIF('2026 T'!$E:$E,PerPM!$A22,'2026 T'!V:V)/PARAMETER!$T$3,"") | W22: =IF(W$4<=PARAMETER!$X$2,SUMIF('2026 T'!$E:$E,PerPM!$A22,'2026 T'!W:W)/PARAMETER!$T$3,"") | X22: =IF(X$4<=PARAMETER!$X$2,SUMIF('2026 T'!$E:$E,PerPM!$A22,'2026 T'!X:X)/PARAMETER!$T$3,"") | Y22: =IF(Y$4<=PARAMETER!$X$2,SUMIF('2026 T'!$E:$E,PerPM!$A22,'2026 T'!Y:Y)/PARAMETER!$T$3,"") | Z22: =IF(Z$4<=PARAMETER!$X$2,SUMIF('2026 T'!$E:$E,PerPM!$A22,'2026 T'!Z:Z)/PARAMETER!$T$3,"") | AA22: =IF(AA$4<=PARAMETER!$X$2,SUMIF('2026 T'!$E:$E,PerPM!$A22,'2026 T'!AA:AA)/PARAMETER!$T$3,"") | AB22: =IF(AB$4<=PARAMETER!$X$2,SUMIF('2026 T'!$E:$E,PerPM!$A22,'2026 T'!AB:AB)/PARAMETER!$T$3,"") | AC22: =IF(AC$4<=PARAMETER!$X$2,SUMIF('2026 T'!$E:$E,PerPM!$A22,'2026 T'!AC:AC)/PARAMETER!$T$3,"") | AD22: =IF(AD$4<=PARAMETER!$X$2,SUMIF('2026 T'!$E:$E,PerPM!$A22,'2026 T'!AD:AD)/PARAMETER!$T$3,"") | AE22: =IF(AE$4<=PARAMETER!$X$2,SUMIF('2026 T'!$E:$E,PerPM!$A22,'2026 T'!AE:AE)/PARAMETER!$T$3,"") | AF22: =IF(AF$4<=PARAMETER!$X$2,SUMIF('2026 T'!$E:$E,PerPM!$A22,'2026 T'!AF:AF)/PARAMETER!$T$3,"") | AG22: =IF(AG$4<=PARAMETER!$X$2,SUMIF('2026 T'!$E:$E,PerPM!$A22,'2026 T'!AG:AG)/PARAMETER!$T$3,"") | AH22: =IF(AH$4<=PARAMETER!$X$2,SUMIF('2026 T'!$E:$E,PerPM!$A22,'2026 T'!AH:AH)/PARAMETER!$T$3,"") | AI22: =IF(AI$4<=PARAMETER!$X$2,SUMIF('2026 T'!$E:$E,PerPM!$A22,'2026 T'!AI:AI)/PARAMETER!$T$3,"") | AJ22: =IF(AJ$4<=PARAMETER!$X$2,SUMIF('2026 T'!$E:$E,PerPM!$A22,'2026 T'!AJ:AJ)/PARAMETER!$T$3,"") | AK22: =IF(AK$4<=PARAMETER!$X$2,SUMIF('2026 T'!$E:$E,PerPM!$A22,'2026 T'!AK:AK)/PARAMETER!$T$3,"") | AL22: =IF(AL$4<=PARAMETER!$X$2,SUMIF('2026 T'!$E:$E,PerPM!$A22,'2026 T'!AL:AL)/PARAMETER!$T$3,"") | AM22: =IF(AM$4<=PARAMETER!$X$2,SUMIF('2026 T'!$E:$E,PerPM!$A22,'2026 T'!AM:AM)/PARAMETER!$T$3,"") | AN22: =IF(AN$4<=PARAMETER!$X$2,SUMIF('2026 T'!$E:$E,PerPM!$A22,'2026 T'!AN:AN)/PARAMETER!$T$3,"") | AO22: =IF(AO$4<=PARAMETER!$X$2,SUMIF('2026 T'!$E:$E,PerPM!$A22,'2026 T'!AO:AO)/PARAMETER!$T$3,"") | AP22: =IF(AP$4<=PARAMETER!$X$2,SUMIF('2026 T'!$E:$E,PerPM!$A22,'2026 T'!AP:AP)/PARAMETER!$T$3,"") | AQ22: =IF(AQ$4<=PARAMETER!$X$2,SUMIF('2026 T'!$E:$E,PerPM!$A22,'2026 T'!AQ:AQ)/PARAMETER!$T$3,"") | AR22: =IF(AR$4<=PARAMETER!$X$2,SUMIF('2026 T'!$E:$E,PerPM!$A22,'2026 T'!AR:AR)/PARAMETER!$T$3,"") | AS22: =IF(AS$4<=PARAMETER!$X$2,SUMIF('2026 T'!$E:$E,PerPM!$A22,'2026 T'!AS:AS)/PARAMETER!$T$3,"") | AT22: =IF(AT$4<=PARAMETER!$X$2,SUMIF('2026 T'!$E:$E,PerPM!$A22,'2026 T'!AT:AT)/PARAMETER!$T$3,"") | AU22: =IF(AU$4<=PARAMETER!$X$2,SUMIF('2026 T'!$E:$E,PerPM!$A22,'2026 T'!AU:AU)/PARAMETER!$T$3,"") | AV22: =IF(AV$4<=PARAMETER!$X$2,SUMIF('2026 T'!$E:$E,PerPM!$A22,'2026 T'!AV:AV)/PARAMETER!$T$3,"") | AW22: =IF(AW$4<=PARAMETER!$X$2,SUMIF('2026 T'!$E:$E,PerPM!$A22,'2026 T'!AW:AW)/PARAMETER!$T$3,"") | AX22: =IF(AX$4<=PARAMETER!$X$2,SUMIF('2026 T'!$E:$E,PerPM!$A22,'2026 T'!AX:AX)/PARAMETER!$T$3,"") | AY22: =IF(AY$4<=PARAMETER!$X$2,SUMIF('2026 T'!$E:$E,PerPM!$A22,'2026 T'!AY:AY)/PARAMETER!$T$3,"") | AZ22: =IF(AZ$4<=PARAMETER!$X$2,SUMIF('2026 T'!$E:$E,PerPM!$A22,'2026 T'!AZ:AZ)/PARAMETER!$T$3,"") | BA22: =IF(BA$4<=PARAMETER!$X$2,SUMIF('2026 T'!$E:$E,PerPM!$A22,'2026 T'!BA:BA)/PARAMETER!$T$3,"") | BB22: =IF(BB$4<=PARAMETER!$X$2,SUMIF('2026 T'!$E:$E,PerPM!$A22,'2026 T'!BB:BB)/PARAMETER!$T$3,"") | BC22: =IF(BC$4<=PARAMETER!$X$2,SUMIF('2026 T'!$E:$E,PerPM!$A22,'2026 T'!BC:BC)/PARAMETER!$T$3,"") | BD22: =IF(BD$4<=PARAMETER!$X$2,SUMIF('2026 T'!$E:$E,PerPM!$A22,'2026 T'!BD:BD)/PARAMETER!$T$3,"") | BE22: =IF(BE$4<=PARAMETER!$X$2,SUMIF('2026 T'!$E:$E,PerPM!$A22,'2026 T'!BE:BE)/PARAMETER!$T$3,"") | BF22: =IF(BF$4<=PARAMETER!$X$2,SUMIF('2026 T'!$E:$E,PerPM!$A22,'2026 T'!BF:BF)/PARAMETER!$T$3,"") | BG22: =IF(BG$4<=PARAMETER!$X$2,SUMIF('2026 T'!$E:$E,PerPM!$A22,'2026 T'!BG:BG)/PARAMETER!$T$3,"") | BH22: =IF(BH$4<=PARAMETER!$X$2,SUMIF('2026 T'!$E:$E,PerPM!$A22,'2026 T'!BH:BH)/PARAMETER!$T$3,"") | BI22: =IF(BI$4<=PARAMETER!$X$2,SUMIF('2026 T'!$E:$E,PerPM!$A22,'2026 T'!BI:BI)/PARAMETER!$T$3,"")
A23: =CONCATENATE(B23,PARAMETER!T$2) -> RIFALDIVOL | B23: =B22 -> RIFALDI | C23: YoY (%) | D23: =H23/H24-1 -> 730.715 | E23: =IF(D23>300%,300%,D23) -> 3 | F23: =F19 -> 2026 | G23: =IF(G$4<=PARAMETER!$X$2,SUMIF('2026'!$E:$E,PerPM!$A22,'2026'!G:G)/PARAMETER!$T$3,"") -> 12961254 | H23: =IF(H$4<=PARAMETER!$X$2,SUMIF('2026'!$E:$E,PerPM!$A22,'2026'!H:H)/PARAMETER!$T$3,"") -> 12922121 | I23: =IF(I$4<=PARAMETER!$X$2,SUMIF('2026'!$E:$E,PerPM!$A22,'2026'!I:I)/PARAMETER!$T$3,"") -> 467.26523 | J23: =IF(J$4<=PARAMETER!$X$2,SUMIF('2026'!$E:$E,PerPM!$A22,'2026'!J:J)/PARAMETER!$T$3,"") -> 387.19617 | K23: =IF(K$4<=PARAMETER!$X$2,SUMIF('2026'!$E:$E,PerPM!$A22,'2026'!K:K)/PARAMETER!$T$3,"") -> 398.58689 | L23: =IF(L$4<=PARAMETER!$X$2,SUMIF('2026'!$E:$E,PerPM!$A22,'2026'!L:L)/PARAMETER!$T$3,"") -> 447.88338 | M23: =IF(M$4<=PARAMETER!$X$2,SUMIF('2026'!$E:$E,PerPM!$A22,'2026'!M:M)/PARAMETER!$T$3,"") -> 501.59708 | N23: =IF(N$4<=PARAMETER!$X$2,SUMIF('2026'!$E:$E,PerPM!$A22,'2026'!N:N)/PARAMETER!$T$3,"") -> 488.763 | O23: =IF(O$4<=PARAMETER!$X$2,SUMIF('2026'!$E:$E,PerPM!$A22,'2026'!O:O)/PARAMETER!$T$3,"") -> 508.23222 | P23: =IF(P$4<=PARAMETER!$X$2,SUMIF('2026'!$E:$E,PerPM!$A22,'2026'!P:P)/PARAMETER!$T$3,"") -> 424.75369 | Q23: =IF(Q$4<=PARAMETER!$X$2,SUMIF('2026'!$E:$E,PerPM!$A22,'2026'!Q:Q)/PARAMETER!$T$3,"") -> 7796926.7 | R23: =IF(R$4<=PARAMETER!$X$2,SUMIF('2026'!$E:$E,PerPM!$A22,'2026'!R:R)/PARAMETER!$T$3,"") -> 2517424.4 | S23: =IF(S$4<=PARAMETER!$X$2,SUMIF('2026'!$E:$E,PerPM!$A22,'2026'!S:S)/PARAMETER!$T$3,"") -> 2603721.5 | T23: =IF(T$4<=PARAMETER!$X$2,SUMIF('2026'!$E:$E,PerPM!$A22,'2026'!T:T)/PARAMETER!$T$3,"") -> 423.93587 | U23: =IF(U$4<=PARAMETER!$X$2,SUMIF('2026'!$E:$E,PerPM!$A22,'2026'!U:U)/PARAMETER!$T$3,"") | V23: =IF(V$4<=PARAMETER!$X$2,SUMIF('2026'!$E:$E,PerPM!$A22,'2026'!V:V)/PARAMETER!$T$3,"") | W23: =IF(W$4<=PARAMETER!$X$2,SUMIF('2026'!$E:$E,PerPM!$A22,'2026'!W:W)/PARAMETER!$T$3,"") | X23: =IF(X$4<=PARAMETER!$X$2,SUMIF('2026'!$E:$E,PerPM!$A22,'2026'!X:X)/PARAMETER!$T$3,"") | Y23: =IF(Y$4<=PARAMETER!$X$2,SUMIF('2026'!$E:$E,PerPM!$A22,'2026'!Y:Y)/PARAMETER!$T$3,"") | Z23: =IF(Z$4<=PARAMETER!$X$2,SUMIF('2026'!$E:$E,PerPM!$A22,'2026'!Z:Z)/PARAMETER!$T$3,"") | AA23: =IF(AA$4<=PARAMETER!$X$2,SUMIF('2026'!$E:$E,PerPM!$A22,'2026'!AA:AA)/PARAMETER!$T$3,"") | AB23: =IF(AB$4<=PARAMETER!$X$2,SUMIF('2026'!$E:$E,PerPM!$A22,'2026'!AB:AB)/PARAMETER!$T$3,"") | AC23: =IF(AC$4<=PARAMETER!$X$2,SUMIF('2026'!$E:$E,PerPM!$A22,'2026'!AC:AC)/PARAMETER!$T$3,"") | AD23: =IF(AD$4<=PARAMETER!$X$2,SUMIF('2026'!$E:$E,PerPM!$A22,'2026'!AD:AD)/PARAMETER!$T$3,"") | AE23: =IF(AE$4<=PARAMETER!$X$2,SUMIF('2026'!$E:$E,PerPM!$A22,'2026'!AE:AE)/PARAMETER!$T$3,"") | AF23: =IF(AF$4<=PARAMETER!$X$2,SUMIF('2026'!$E:$E,PerPM!$A22,'2026'!AF:AF)/PARAMETER!$T$3,"") | AG23: =IF(AG$4<=PARAMETER!$X$2,SUMIF('2026'!$E:$E,PerPM!$A22,'2026'!AG:AG)/PARAMETER!$T$3,"") | AH23: =IF(AH$4<=PARAMETER!$X$2,SUMIF('2026'!$E:$E,PerPM!$A22,'2026'!AH:AH)/PARAMETER!$T$3,"") | AI23: =IF(AI$4<=PARAMETER!$X$2,SUMIF('2026'!$E:$E,PerPM!$A22,'2026'!AI:AI)/PARAMETER!$T$3,"") | AJ23: =IF(AJ$4<=PARAMETER!$X$2,SUMIF('2026'!$E:$E,PerPM!$A22,'2026'!AJ:AJ)/PARAMETER!$T$3,"") | AK23: =IF(AK$4<=PARAMETER!$X$2,SUMIF('2026'!$E:$E,PerPM!$A22,'2026'!AK:AK)/PARAMETER!$T$3,"") | AL23: =IF(AL$4<=PARAMETER!$X$2,SUMIF('2026'!$E:$E,PerPM!$A22,'2026'!AL:AL)/PARAMETER!$T$3,"") | AM23: =IF(AM$4<=PARAMETER!$X$2,SUMIF('2026'!$E:$E,PerPM!$A22,'2026'!AM:AM)/PARAMETER!$T$3,"") | AN23: =IF(AN$4<=PARAMETER!$X$2,SUMIF('2026'!$E:$E,PerPM!$A22,'2026'!AN:AN)/PARAMETER!$T$3,"") | AO23: =IF(AO$4<=PARAMETER!$X$2,SUMIF('2026'!$E:$E,PerPM!$A22,'2026'!AO:AO)/PARAMETER!$T$3,"") | AP23: =IF(AP$4<=PARAMETER!$X$2,SUMIF('2026'!$E:$E,PerPM!$A22,'2026'!AP:AP)/PARAMETER!$T$3,"") | AQ23: =IF(AQ$4<=PARAMETER!$X$2,SUMIF('2026'!$E:$E,PerPM!$A22,'2026'!AQ:AQ)/PARAMETER!$T$3,"") | AR23: =IF(AR$4<=PARAMETER!$X$2,SUMIF('2026'!$E:$E,PerPM!$A22,'2026'!AR:AR)/PARAMETER!$T$3,"") | AS23: =IF(AS$4<=PARAMETER!$X$2,SUMIF('2026'!$E:$E,PerPM!$A22,'2026'!AS:AS)/PARAMETER!$T$3,"") | AT23: =IF(AT$4<=PARAMETER!$X$2,SUMIF('2026'!$E:$E,PerPM!$A22,'2026'!AT:AT)/PARAMETER!$T$3,"") | AU23: =IF(AU$4<=PARAMETER!$X$2,SUMIF('2026'!$E:$E,PerPM!$A22,'2026'!AU:AU)/PARAMETER!$T$3,"") | AV23: =IF(AV$4<=PARAMETER!$X$2,SUMIF('2026'!$E:$E,PerPM!$A22,'2026'!AV:AV)/PARAMETER!$T$3,"") | AW23: =IF(AW$4<=PARAMETER!$X$2,SUMIF('2026'!$E:$E,PerPM!$A22,'2026'!AW:AW)/PARAMETER!$T$3,"") | AX23: =IF(AX$4<=PARAMETER!$X$2,SUMIF('2026'!$E:$E,PerPM!$A22,'2026'!AX:AX)/PARAMETER!$T$3,"") | AY23: =IF(AY$4<=PARAMETER!$X$2,SUMIF('2026'!$E:$E,PerPM!$A22,'2026'!AY:AY)/PARAMETER!$T$3,"") | AZ23: =IF(AZ$4<=PARAMETER!$X$2,SUMIF('2026'!$E:$E,PerPM!$A22,'2026'!AZ:AZ)/PARAMETER!$T$3,"") | BA23: =IF(BA$4<=PARAMETER!$X$2,SUMIF('2026'!$E:$E,PerPM!$A22,'2026'!BA:BA)/PARAMETER!$T$3,"") | BB23: =IF(BB$4<=PARAMETER!$X$2,SUMIF('2026'!$E:$E,PerPM!$A22,'2026'!BB:BB)/PARAMETER!$T$3,"") | BC23: =IF(BC$4<=PARAMETER!$X$2,SUMIF('2026'!$E:$E,PerPM!$A22,'2026'!BC:BC)/PARAMETER!$T$3,"") | BD23: =IF(BD$4<=PARAMETER!$X$2,SUMIF('2026'!$E:$E,PerPM!$A22,'2026'!BD:BD)/PARAMETER!$T$3,"") | BE23: =IF(BE$4<=PARAMETER!$X$2,SUMIF('2026'!$E:$E,PerPM!$A22,'2026'!BE:BE)/PARAMETER!$T$3,"") | BF23: =IF(BF$4<=PARAMETER!$X$2,SUMIF('2026'!$E:$E,PerPM!$A22,'2026'!BF:BF)/PARAMETER!$T$3,"") | BG23: =IF(BG$4<=PARAMETER!$X$2,SUMIF('2026'!$E:$E,PerPM!$A22,'2026'!BG:BG)/PARAMETER!$T$3,"") | BH23: =IF(BH$4<=PARAMETER!$X$2,SUMIF('2026'!$E:$E,PerPM!$A22,'2026'!BH:BH)/PARAMETER!$T$3,"") | BI23: =IF(BI$4<=PARAMETER!$X$2,SUMIF('2026'!$E:$E,PerPM!$A22,'2026'!BI:BI)/PARAMETER!$T$3,"")
